[2019-02-07 16:29:32 +0000] [15] [INFO] Starting gunicorn 19.9.0
[2019-02-07 16:29:32 +0000] [15] [INFO] Listening at: http://127.0.0.1:8000 (15)
[2019-02-07 16:29:32 +0000] [15] [INFO] Using worker: sync
[2019-02-07 16:29:32 +0000] [32] [INFO] Booting worker with pid: 32
[2019-02-07 16:29:32 +0000] [34] [INFO] Booting worker with pid: 34
[2019-02-07 16:29:32 +0000] [35] [INFO] Booting worker with pid: 35
[2019-02-07 16:29:32 +0000] [36] [INFO] Booting worker with pid: 36
/opt/graphite/webapp/graphite/local_settings.py:334: UserWarning: SECRET_KEY is set to an unsafe default. This should be set in local_settings.py for better security
[2019-02-07 16:29:32 +0000] [32] [ERROR] Exception in worker process
Traceback (most recent call last):
  File "/usr/lib/python2.7/site-packages/gunicorn/arbiter.py", line 583, in spawn_worker
    worker.init_process()
  File "/usr/lib/python2.7/site-packages/gunicorn/workers/base.py", line 129, in init_process
    self.load_wsgi()
  File "/usr/lib/python2.7/site-packages/gunicorn/workers/base.py", line 138, in load_wsgi
    self.wsgi = self.app.wsgi()
  File "/usr/lib/python2.7/site-packages/gunicorn/app/base.py", line 67, in wsgi
    self.callable = self.load()
  File "/usr/lib/python2.7/site-packages/gunicorn/app/wsgiapp.py", line 52, in load
    return self.load_wsgiapp()
  File "/usr/lib/python2.7/site-packages/gunicorn/app/wsgiapp.py", line 41, in load_wsgiapp
    return util.import_app(self.app_uri)
  File "/usr/lib/python2.7/site-packages/gunicorn/util.py", line 350, in import_app
    __import__(module)
  File "/opt/graphite/webapp/graphite/wsgi.py", line 15, in <module>
    application = get_wsgi_application()
  File "/usr/lib/python2.7/site-packages/django/core/wsgi.py", line 13, in get_wsgi_application
    django.setup(set_prefix=False)
  File "/usr/lib/python2.7/site-packages/django/__init__.py", line 27, in setup
    apps.populate(settings.INSTALLED_APPS)
  File "/usr/lib/python2.7/site-packages/django/apps/registry.py", line 85, in populate
    app_config = AppConfig.create(entry)
  File "/usr/lib/python2.7/site-packages/django/apps/config.py", line 94, in create
    module = import_module(entry)
  File "/usr/lib/python2.7/importlib/__init__.py", line 37, in import_module
    __import__(name)
  File "/opt/graphite/webapp/graphite/functions/__init__.py", line 10, in <module>
    from graphite.logger import log
  File "/opt/graphite/webapp/graphite/logger.py", line 106, in <module>
    log = GraphiteLogger() # import-shared logger instance
  File "/opt/graphite/webapp/graphite/logger.py", line 39, in __init__
    level = logging.DEBUG if settings.DEBUG else logging.INFO,
  File "/opt/graphite/webapp/graphite/logger.py", line 78, in _config_logger
    handler = Rotater(log_file, when=when, backupCount=backupCount)
  File "/usr/lib/python2.7/logging/handlers.py", line 171, in __init__
    BaseRotatingHandler.__init__(self, filename, 'a', encoding, delay)
  File "/usr/lib/python2.7/logging/handlers.py", line 64, in __init__
    logging.FileHandler.__init__(self, filename, mode, encoding, delay)
  File "/usr/lib/python2.7/logging/__init__.py", line 920, in __init__
    StreamHandler.__init__(self, self._open())
  File "/usr/lib/python2.7/logging/__init__.py", line 950, in _open
    stream = open(self.baseFilename, self.mode)
IOError: [Errno 2] No such file or directory: '/opt/graphite/storage/log/webapp/info.log'
[2019-02-07 16:29:32 +0000] [32] [INFO] Worker exiting (pid: 32)
/opt/graphite/webapp/graphite/local_settings.py:334: UserWarning: SECRET_KEY is set to an unsafe default. This should be set in local_settings.py for better security
[2019-02-07 16:29:32 +0000] [34] [ERROR] Exception in worker process
Traceback (most recent call last):
  File "/usr/lib/python2.7/site-packages/gunicorn/arbiter.py", line 583, in spawn_worker
    worker.init_process()
  File "/usr/lib/python2.7/site-packages/gunicorn/workers/base.py", line 129, in init_process
    self.load_wsgi()
  File "/usr/lib/python2.7/site-packages/gunicorn/workers/base.py", line 138, in load_wsgi
    self.wsgi = self.app.wsgi()
  File "/usr/lib/python2.7/site-packages/gunicorn/app/base.py", line 67, in wsgi
    self.callable = self.load()
  File "/usr/lib/python2.7/site-packages/gunicorn/app/wsgiapp.py", line 52, in load
    return self.load_wsgiapp()
  File "/usr/lib/python2.7/site-packages/gunicorn/app/wsgiapp.py", line 41, in load_wsgiapp
    return util.import_app(self.app_uri)
  File "/usr/lib/python2.7/site-packages/gunicorn/util.py", line 350, in import_app
    __import__(module)
  File "/opt/graphite/webapp/graphite/wsgi.py", line 15, in <module>
    application = get_wsgi_application()
  File "/usr/lib/python2.7/site-packages/django/core/wsgi.py", line 13, in get_wsgi_application
    django.setup(set_prefix=False)
  File "/usr/lib/python2.7/site-packages/django/__init__.py", line 27, in setup
    apps.populate(settings.INSTALLED_APPS)
  File "/usr/lib/python2.7/site-packages/django/apps/registry.py", line 85, in populate
    app_config = AppConfig.create(entry)
  File "/usr/lib/python2.7/site-packages/django/apps/config.py", line 94, in create
    module = import_module(entry)
  File "/usr/lib/python2.7/importlib/__init__.py", line 37, in import_module
    __import__(name)
  File "/opt/graphite/webapp/graphite/functions/__init__.py", line 10, in <module>
    from graphite.logger import log
  File "/opt/graphite/webapp/graphite/logger.py", line 106, in <module>
    log = GraphiteLogger() # import-shared logger instance
  File "/opt/graphite/webapp/graphite/logger.py", line 39, in __init__
    level = logging.DEBUG if settings.DEBUG else logging.INFO,
  File "/opt/graphite/webapp/graphite/logger.py", line 78, in _config_logger
    handler = Rotater(log_file, when=when, backupCount=backupCount)
  File "/usr/lib/python2.7/logging/handlers.py", line 171, in __init__
    BaseRotatingHandler.__init__(self, filename, 'a', encoding, delay)
  File "/usr/lib/python2.7/logging/handlers.py", line 64, in __init__
    logging.FileHandler.__init__(self, filename, mode, encoding, delay)
  File "/usr/lib/python2.7/logging/__init__.py", line 920, in __init__
    StreamHandler.__init__(self, self._open())
  File "/usr/lib/python2.7/logging/__init__.py", line 950, in _open
    stream = open(self.baseFilename, self.mode)
IOError: [Errno 2] No such file or directory: '/opt/graphite/storage/log/webapp/info.log'
[2019-02-07 16:29:32 +0000] [34] [INFO] Worker exiting (pid: 34)
Traceback (most recent call last):
  File "/usr/bin/gunicorn", line 11, in <module>
    sys.exit(run())
  File "/usr/lib/python2.7/site-packages/gunicorn/app/wsgiapp.py", line 61, in run
    WSGIApplication("%(prog)s [OPTIONS] [APP_MODULE]").run()
  File "/usr/lib/python2.7/site-packages/gunicorn/app/base.py", line 223, in run
    super(Application, self).run()
  File "/usr/lib/python2.7/site-packages/gunicorn/app/base.py", line 72, in run
    Arbiter(self).run()
  File "/usr/lib/python2.7/site-packages/gunicorn/arbiter.py", line 232, in run
    self.halt(reason=inst.reason, exit_status=inst.exit_status)
  File "/usr/lib/python2.7/site-packages/gunicorn/arbiter.py", line 345, in halt
    self.stop()
  File "/usr/lib/python2.7/site-packages/gunicorn/arbiter.py", line 393, in stop
    time.sleep(0.1)
  File "/usr/lib/python2.7/site-packages/gunicorn/arbiter.py", line 245, in handle_chld
    self.reap_workers()
  File "/usr/lib/python2.7/site-packages/gunicorn/arbiter.py", line 525, in reap_workers
    raise HaltServer(reason, self.WORKER_BOOT_ERROR)
gunicorn.errors.HaltServer: <HaltServer 'Worker failed to boot.' 3>
[2019-02-07 16:29:33 +0000] [39] [INFO] Starting gunicorn 19.9.0
[2019-02-07 16:29:33 +0000] [39] [INFO] Listening at: http://127.0.0.1:8000 (39)
[2019-02-07 16:29:33 +0000] [39] [INFO] Using worker: sync
[2019-02-07 16:29:33 +0000] [41] [INFO] Booting worker with pid: 41
[2019-02-07 16:29:33 +0000] [42] [INFO] Booting worker with pid: 42
[2019-02-07 16:29:33 +0000] [43] [INFO] Booting worker with pid: 43
[2019-02-07 16:29:33 +0000] [44] [INFO] Booting worker with pid: 44
/opt/graphite/webapp/graphite/local_settings.py:334: UserWarning: SECRET_KEY is set to an unsafe default. This should be set in local_settings.py for better security
/opt/graphite/webapp/graphite/local_settings.py:334: UserWarning: SECRET_KEY is set to an unsafe default. This should be set in local_settings.py for better security
[2019-02-07 16:29:34 +0000] [41] [ERROR] Exception in worker process
Traceback (most recent call last):
  File "/usr/lib/python2.7/site-packages/gunicorn/arbiter.py", line 583, in spawn_worker
    worker.init_process()
  File "/usr/lib/python2.7/site-packages/gunicorn/workers/base.py", line 129, in init_process
    self.load_wsgi()
  File "/usr/lib/python2.7/site-packages/gunicorn/workers/base.py", line 138, in load_wsgi
    self.wsgi = self.app.wsgi()
  File "/usr/lib/python2.7/site-packages/gunicorn/app/base.py", line 67, in wsgi
    self.callable = self.load()
  File "/usr/lib/python2.7/site-packages/gunicorn/app/wsgiapp.py", line 52, in load
    return self.load_wsgiapp()
  File "/usr/lib/python2.7/site-packages/gunicorn/app/wsgiapp.py", line 41, in load_wsgiapp
    return util.import_app(self.app_uri)
  File "/usr/lib/python2.7/site-packages/gunicorn/util.py", line 350, in import_app
    __import__(module)
  File "/opt/graphite/webapp/graphite/wsgi.py", line 15, in <module>
    application = get_wsgi_application()
  File "/usr/lib/python2.7/site-packages/django/core/wsgi.py", line 13, in get_wsgi_application
    django.setup(set_prefix=False)
  File "/usr/lib/python2.7/site-packages/django/__init__.py", line 27, in setup
    apps.populate(settings.INSTALLED_APPS)
  File "/usr/lib/python2.7/site-packages/django/apps/registry.py", line 85, in populate
    app_config = AppConfig.create(entry)
  File "/usr/lib/python2.7/site-packages/django/apps/config.py", line 94, in create
    module = import_module(entry)
  File "/usr/lib/python2.7/importlib/__init__.py", line 37, in import_module
    __import__(name)
  File "/opt/graphite/webapp/graphite/functions/__init__.py", line 10, in <module>
    from graphite.logger import log
  File "/opt/graphite/webapp/graphite/logger.py", line 106, in <module>
    log = GraphiteLogger() # import-shared logger instance
  File "/opt/graphite/webapp/graphite/logger.py", line 39, in __init__
    level = logging.DEBUG if settings.DEBUG else logging.INFO,
  File "/opt/graphite/webapp/graphite/logger.py", line 78, in _config_logger
    handler = Rotater(log_file, when=when, backupCount=backupCount)
  File "/usr/lib/python2.7/logging/handlers.py", line 171, in __init__
    BaseRotatingHandler.__init__(self, filename, 'a', encoding, delay)
  File "/usr/lib/python2.7/logging/handlers.py", line 64, in __init__
    logging.FileHandler.__init__(self, filename, mode, encoding, delay)
  File "/usr/lib/python2.7/logging/__init__.py", line 920, in __init__
    StreamHandler.__init__(self, self._open())
  File "/usr/lib/python2.7/logging/__init__.py", line 950, in _open
    stream = open(self.baseFilename, self.mode)
IOError: [Errno 2] No such file or directory: '/opt/graphite/storage/log/webapp/info.log'
[2019-02-07 16:29:34 +0000] [41] [INFO] Worker exiting (pid: 41)
[2019-02-07 16:29:34 +0000] [42] [ERROR] Exception in worker process
Traceback (most recent call last):
  File "/usr/lib/python2.7/site-packages/gunicorn/arbiter.py", line 583, in spawn_worker
    worker.init_process()
  File "/usr/lib/python2.7/site-packages/gunicorn/workers/base.py", line 129, in init_process
    self.load_wsgi()
  File "/usr/lib/python2.7/site-packages/gunicorn/workers/base.py", line 138, in load_wsgi
    self.wsgi = self.app.wsgi()
  File "/usr/lib/python2.7/site-packages/gunicorn/app/base.py", line 67, in wsgi
    self.callable = self.load()
  File "/usr/lib/python2.7/site-packages/gunicorn/app/wsgiapp.py", line 52, in load
    return self.load_wsgiapp()
  File "/usr/lib/python2.7/site-packages/gunicorn/app/wsgiapp.py", line 41, in load_wsgiapp
    return util.import_app(self.app_uri)
  File "/usr/lib/python2.7/site-packages/gunicorn/util.py", line 350, in import_app
    __import__(module)
  File "/opt/graphite/webapp/graphite/wsgi.py", line 15, in <module>
    application = get_wsgi_application()
  File "/usr/lib/python2.7/site-packages/django/core/wsgi.py", line 13, in get_wsgi_application
    django.setup(set_prefix=False)
  File "/usr/lib/python2.7/site-packages/django/__init__.py", line 27, in setup
    apps.populate(settings.INSTALLED_APPS)
  File "/usr/lib/python2.7/site-packages/django/apps/registry.py", line 85, in populate
    app_config = AppConfig.create(entry)
  File "/usr/lib/python2.7/site-packages/django/apps/config.py", line 94, in create
    module = import_module(entry)
  File "/usr/lib/python2.7/importlib/__init__.py", line 37, in import_module
    __import__(name)
  File "/opt/graphite/webapp/graphite/functions/__init__.py", line 10, in <module>
    from graphite.logger import log
  File "/opt/graphite/webapp/graphite/logger.py", line 106, in <module>
    log = GraphiteLogger() # import-shared logger instance
  File "/opt/graphite/webapp/graphite/logger.py", line 39, in __init__
    level = logging.DEBUG if settings.DEBUG else logging.INFO,
  File "/opt/graphite/webapp/graphite/logger.py", line 78, in _config_logger
    handler = Rotater(log_file, when=when, backupCount=backupCount)
  File "/usr/lib/python2.7/logging/handlers.py", line 171, in __init__
    BaseRotatingHandler.__init__(self, filename, 'a', encoding, delay)
  File "/usr/lib/python2.7/logging/handlers.py", line 64, in __init__
    logging.FileHandler.__init__(self, filename, mode, encoding, delay)
  File "/usr/lib/python2.7/logging/__init__.py", line 920, in __init__
    StreamHandler.__init__(self, self._open())
  File "/usr/lib/python2.7/logging/__init__.py", line 950, in _open
    stream = open(self.baseFilename, self.mode)
IOError: [Errno 2] No such file or directory: '/opt/graphite/storage/log/webapp/info.log'
[2019-02-07 16:29:34 +0000] [42] [INFO] Worker exiting (pid: 42)
/opt/graphite/webapp/graphite/local_settings.py:334: UserWarning: SECRET_KEY is set to an unsafe default. This should be set in local_settings.py for better security
[2019-02-07 16:29:34 +0000] [43] [ERROR] Exception in worker process
Traceback (most recent call last):
  File "/usr/lib/python2.7/site-packages/gunicorn/arbiter.py", line 583, in spawn_worker
    worker.init_process()
  File "/usr/lib/python2.7/site-packages/gunicorn/workers/base.py", line 129, in init_process
    self.load_wsgi()
  File "/usr/lib/python2.7/site-packages/gunicorn/workers/base.py", line 138, in load_wsgi
    self.wsgi = self.app.wsgi()
  File "/usr/lib/python2.7/site-packages/gunicorn/app/base.py", line 67, in wsgi
    self.callable = self.load()
  File "/usr/lib/python2.7/site-packages/gunicorn/app/wsgiapp.py", line 52, in load
    return self.load_wsgiapp()
  File "/usr/lib/python2.7/site-packages/gunicorn/app/wsgiapp.py", line 41, in load_wsgiapp
    return util.import_app(self.app_uri)
  File "/usr/lib/python2.7/site-packages/gunicorn/util.py", line 350, in import_app
    __import__(module)
  File "/opt/graphite/webapp/graphite/wsgi.py", line 15, in <module>
    application = get_wsgi_application()
  File "/usr/lib/python2.7/site-packages/django/core/wsgi.py", line 13, in get_wsgi_application
    django.setup(set_prefix=False)
  File "/usr/lib/python2.7/site-packages/django/__init__.py", line 27, in setup
    apps.populate(settings.INSTALLED_APPS)
  File "/usr/lib/python2.7/site-packages/django/apps/registry.py", line 85, in populate
    app_config = AppConfig.create(entry)
  File "/usr/lib/python2.7/site-packages/django/apps/config.py", line 94, in create
    module = import_module(entry)
  File "/usr/lib/python2.7/importlib/__init__.py", line 37, in import_module
    __import__(name)
  File "/opt/graphite/webapp/graphite/functions/__init__.py", line 10, in <module>
    from graphite.logger import log
  File "/opt/graphite/webapp/graphite/logger.py", line 106, in <module>
    log = GraphiteLogger() # import-shared logger instance
  File "/opt/graphite/webapp/graphite/logger.py", line 39, in __init__
    level = logging.DEBUG if settings.DEBUG else logging.INFO,
  File "/opt/graphite/webapp/graphite/logger.py", line 78, in _config_logger
    handler = Rotater(log_file, when=when, backupCount=backupCount)
  File "/usr/lib/python2.7/logging/handlers.py", line 171, in __init__
    BaseRotatingHandler.__init__(self, filename, 'a', encoding, delay)
  File "/usr/lib/python2.7/logging/handlers.py", line 64, in __init__
    logging.FileHandler.__init__(self, filename, mode, encoding, delay)
  File "/usr/lib/python2.7/logging/__init__.py", line 920, in __init__
    StreamHandler.__init__(self, self._open())
  File "/usr/lib/python2.7/logging/__init__.py", line 950, in _open
    stream = open(self.baseFilename, self.mode)
IOError: [Errno 2] No such file or directory: '/opt/graphite/storage/log/webapp/info.log'
[2019-02-07 16:29:34 +0000] [43] [INFO] Worker exiting (pid: 43)
Traceback (most recent call last):
  File "/usr/bin/gunicorn", line 11, in <module>
    sys.exit(run())
  File "/usr/lib/python2.7/site-packages/gunicorn/app/wsgiapp.py", line 61, in run
    WSGIApplication("%(prog)s [OPTIONS] [APP_MODULE]").run()
  File "/usr/lib/python2.7/site-packages/gunicorn/app/base.py", line 223, in run
    super(Application, self).run()
  File "/usr/lib/python2.7/site-packages/gunicorn/app/base.py", line 72, in run
    Arbiter(self).run()
  File "/usr/lib/python2.7/site-packages/gunicorn/arbiter.py", line 232, in run
    self.halt(reason=inst.reason, exit_status=inst.exit_status)
  File "/usr/lib/python2.7/site-packages/gunicorn/arbiter.py", line 345, in halt
    self.stop()
  File "/usr/lib/python2.7/site-packages/gunicorn/arbiter.py", line 393, in stop
    time.sleep(0.1)
  File "/usr/lib/python2.7/site-packages/gunicorn/arbiter.py", line 245, in handle_chld
    self.reap_workers()
  File "/usr/lib/python2.7/site-packages/gunicorn/arbiter.py", line 525, in reap_workers
    raise HaltServer(reason, self.WORKER_BOOT_ERROR)
gunicorn.errors.HaltServer: <HaltServer 'Worker failed to boot.' 3>
/opt/graphite/webapp/graphite/local_settings.py:334: UserWarning: SECRET_KEY is set to an unsafe default. This should be set in local_settings.py for better security
[2019-02-07 16:29:34 +0000] [44] [ERROR] Exception in worker process
Traceback (most recent call last):
  File "/usr/lib/python2.7/site-packages/gunicorn/arbiter.py", line 583, in spawn_worker
    worker.init_process()
  File "/usr/lib/python2.7/site-packages/gunicorn/workers/base.py", line 129, in init_process
    self.load_wsgi()
  File "/usr/lib/python2.7/site-packages/gunicorn/workers/base.py", line 138, in load_wsgi
    self.wsgi = self.app.wsgi()
  File "/usr/lib/python2.7/site-packages/gunicorn/app/base.py", line 67, in wsgi
    self.callable = self.load()
  File "/usr/lib/python2.7/site-packages/gunicorn/app/wsgiapp.py", line 52, in load
    return self.load_wsgiapp()
  File "/usr/lib/python2.7/site-packages/gunicorn/app/wsgiapp.py", line 41, in load_wsgiapp
    return util.import_app(self.app_uri)
  File "/usr/lib/python2.7/site-packages/gunicorn/util.py", line 350, in import_app
    __import__(module)
  File "/opt/graphite/webapp/graphite/wsgi.py", line 15, in <module>
    application = get_wsgi_application()
  File "/usr/lib/python2.7/site-packages/django/core/wsgi.py", line 13, in get_wsgi_application
    django.setup(set_prefix=False)
  File "/usr/lib/python2.7/site-packages/django/__init__.py", line 27, in setup
    apps.populate(settings.INSTALLED_APPS)
  File "/usr/lib/python2.7/site-packages/django/apps/registry.py", line 85, in populate
    app_config = AppConfig.create(entry)
  File "/usr/lib/python2.7/site-packages/django/apps/config.py", line 94, in create
    module = import_module(entry)
  File "/usr/lib/python2.7/importlib/__init__.py", line 37, in import_module
    __import__(name)
  File "/opt/graphite/webapp/graphite/functions/__init__.py", line 10, in <module>
    from graphite.logger import log
  File "/opt/graphite/webapp/graphite/logger.py", line 106, in <module>
    log = GraphiteLogger() # import-shared logger instance
  File "/opt/graphite/webapp/graphite/logger.py", line 39, in __init__
    level = logging.DEBUG if settings.DEBUG else logging.INFO,
  File "/opt/graphite/webapp/graphite/logger.py", line 78, in _config_logger
    handler = Rotater(log_file, when=when, backupCount=backupCount)
  File "/usr/lib/python2.7/logging/handlers.py", line 171, in __init__
    BaseRotatingHandler.__init__(self, filename, 'a', encoding, delay)
  File "/usr/lib/python2.7/logging/handlers.py", line 64, in __init__
    logging.FileHandler.__init__(self, filename, mode, encoding, delay)
  File "/usr/lib/python2.7/logging/__init__.py", line 920, in __init__
    StreamHandler.__init__(self, self._open())
  File "/usr/lib/python2.7/logging/__init__.py", line 950, in _open
    stream = open(self.baseFilename, self.mode)
IOError: [Errno 2] No such file or directory: '/opt/graphite/storage/log/webapp/info.log'
[2019-02-07 16:29:34 +0000] [44] [INFO] Worker exiting (pid: 44)
[2019-02-07 16:29:34 +0000] [45] [INFO] Starting gunicorn 19.9.0
[2019-02-07 16:29:34 +0000] [45] [INFO] Listening at: http://127.0.0.1:8000 (45)
[2019-02-07 16:29:34 +0000] [45] [INFO] Using worker: sync
[2019-02-07 16:29:34 +0000] [49] [INFO] Booting worker with pid: 49
[2019-02-07 16:29:34 +0000] [50] [INFO] Booting worker with pid: 50
/opt/graphite/webapp/graphite/local_settings.py:334: UserWarning: SECRET_KEY is set to an unsafe default. This should be set in local_settings.py for better security
[2019-02-07 16:29:34 +0000] [49] [ERROR] Exception in worker process
Traceback (most recent call last):
  File "/usr/lib/python2.7/site-packages/gunicorn/arbiter.py", line 583, in spawn_worker
    worker.init_process()
  File "/usr/lib/python2.7/site-packages/gunicorn/workers/base.py", line 129, in init_process
    self.load_wsgi()
  File "/usr/lib/python2.7/site-packages/gunicorn/workers/base.py", line 138, in load_wsgi
    self.wsgi = self.app.wsgi()
  File "/usr/lib/python2.7/site-packages/gunicorn/app/base.py", line 67, in wsgi
    self.callable = self.load()
  File "/usr/lib/python2.7/site-packages/gunicorn/app/wsgiapp.py", line 52, in load
    return self.load_wsgiapp()
  File "/usr/lib/python2.7/site-packages/gunicorn/app/wsgiapp.py", line 41, in load_wsgiapp
    return util.import_app(self.app_uri)
  File "/usr/lib/python2.7/site-packages/gunicorn/util.py", line 350, in import_app
    __import__(module)
  File "/opt/graphite/webapp/graphite/wsgi.py", line 15, in <module>
    application = get_wsgi_application()
  File "/usr/lib/python2.7/site-packages/django/core/wsgi.py", line 13, in get_wsgi_application
    django.setup(set_prefix=False)
  File "/usr/lib/python2.7/site-packages/django/__init__.py", line 27, in setup
    apps.populate(settings.INSTALLED_APPS)
  File "/usr/lib/python2.7/site-packages/django/apps/registry.py", line 85, in populate
    app_config = AppConfig.create(entry)
  File "/usr/lib/python2.7/site-packages/django/apps/config.py", line 94, in create
    module = import_module(entry)
  File "/usr/lib/python2.7/importlib/__init__.py", line 37, in import_module
    __import__(name)
  File "/opt/graphite/webapp/graphite/functions/__init__.py", line 10, in <module>
    from graphite.logger import log
  File "/opt/graphite/webapp/graphite/logger.py", line 106, in <module>
    log = GraphiteLogger() # import-shared logger instance
  File "/opt/graphite/webapp/graphite/logger.py", line 39, in __init__
    level = logging.DEBUG if settings.DEBUG else logging.INFO,
  File "/opt/graphite/webapp/graphite/logger.py", line 78, in _config_logger
    handler = Rotater(log_file, when=when, backupCount=backupCount)
  File "/usr/lib/python2.7/logging/handlers.py", line 171, in __init__
    BaseRotatingHandler.__init__(self, filename, 'a', encoding, delay)
  File "/usr/lib/python2.7/logging/handlers.py", line 64, in __init__
    logging.FileHandler.__init__(self, filename, mode, encoding, delay)
  File "/usr/lib/python2.7/logging/__init__.py", line 920, in __init__
    StreamHandler.__init__(self, self._open())
  File "/usr/lib/python2.7/logging/__init__.py", line 950, in _open
    stream = open(self.baseFilename, self.mode)
IOError: [Errno 2] No such file or directory: '/opt/graphite/storage/log/webapp/info.log'
[2019-02-07 16:29:34 +0000] [49] [INFO] Worker exiting (pid: 49)
[2019-02-07 16:29:35 +0000] [51] [INFO] Booting worker with pid: 51
[2019-02-07 16:29:35 +0000] [52] [INFO] Booting worker with pid: 52
/opt/graphite/webapp/graphite/local_settings.py:334: UserWarning: SECRET_KEY is set to an unsafe default. This should be set in local_settings.py for better security
/opt/graphite/webapp/graphite/local_settings.py:334: UserWarning: SECRET_KEY is set to an unsafe default. This should be set in local_settings.py for better security
/opt/graphite/webapp/graphite/local_settings.py:334: UserWarning: SECRET_KEY is set to an unsafe default. This should be set in local_settings.py for better security
[2019-02-07 16:29:35 +0000] [50] [ERROR] Exception in worker process
Traceback (most recent call last):
  File "/usr/lib/python2.7/site-packages/gunicorn/arbiter.py", line 583, in spawn_worker
    worker.init_process()
  File "/usr/lib/python2.7/site-packages/gunicorn/workers/base.py", line 129, in init_process
    self.load_wsgi()
  File "/usr/lib/python2.7/site-packages/gunicorn/workers/base.py", line 138, in load_wsgi
    self.wsgi = self.app.wsgi()
  File "/usr/lib/python2.7/site-packages/gunicorn/app/base.py", line 67, in wsgi
    self.callable = self.load()
  File "/usr/lib/python2.7/site-packages/gunicorn/app/wsgiapp.py", line 52, in load
    return self.load_wsgiapp()
  File "/usr/lib/python2.7/site-packages/gunicorn/app/wsgiapp.py", line 41, in load_wsgiapp
    return util.import_app(self.app_uri)
  File "/usr/lib/python2.7/site-packages/gunicorn/util.py", line 350, in import_app
    __import__(module)
  File "/opt/graphite/webapp/graphite/wsgi.py", line 15, in <module>
    application = get_wsgi_application()
  File "/usr/lib/python2.7/site-packages/django/core/wsgi.py", line 13, in get_wsgi_application
    django.setup(set_prefix=False)
  File "/usr/lib/python2.7/site-packages/django/__init__.py", line 27, in setup
    apps.populate(settings.INSTALLED_APPS)
  File "/usr/lib/python2.7/site-packages/django/apps/registry.py", line 85, in populate
    app_config = AppConfig.create(entry)
  File "/usr/lib/python2.7/site-packages/django/apps/config.py", line 94, in create
    module = import_module(entry)
  File "/usr/lib/python2.7/importlib/__init__.py", line 37, in import_module
    __import__(name)
  File "/opt/graphite/webapp/graphite/functions/__init__.py", line 10, in <module>
    from graphite.logger import log
  File "/opt/graphite/webapp/graphite/logger.py", line 106, in <module>
    log = GraphiteLogger() # import-shared logger instance
  File "/opt/graphite/webapp/graphite/logger.py", line 39, in __init__
    level = logging.DEBUG if settings.DEBUG else logging.INFO,
  File "/opt/graphite/webapp/graphite/logger.py", line 78, in _config_logger
    handler = Rotater(log_file, when=when, backupCount=backupCount)
  File "/usr/lib/python2.7/logging/handlers.py", line 171, in __init__
    BaseRotatingHandler.__init__(self, filename, 'a', encoding, delay)
  File "/usr/lib/python2.7/logging/handlers.py", line 64, in __init__
    logging.FileHandler.__init__(self, filename, mode, encoding, delay)
  File "/usr/lib/python2.7/logging/__init__.py", line 920, in __init__
    StreamHandler.__init__(self, self._open())
  File "/usr/lib/python2.7/logging/__init__.py", line 950, in _open
    stream = open(self.baseFilename, self.mode)
IOError: [Errno 2] No such file or directory: '/opt/graphite/storage/log/webapp/info.log'
[2019-02-07 16:29:35 +0000] [50] [INFO] Worker exiting (pid: 50)
[2019-02-07 16:29:35 +0000] [52] [ERROR] Exception in worker process
Traceback (most recent call last):
  File "/usr/lib/python2.7/site-packages/gunicorn/arbiter.py", line 583, in spawn_worker
    worker.init_process()
  File "/usr/lib/python2.7/site-packages/gunicorn/workers/base.py", line 129, in init_process
    self.load_wsgi()
  File "/usr/lib/python2.7/site-packages/gunicorn/workers/base.py", line 138, in load_wsgi
    self.wsgi = self.app.wsgi()
  File "/usr/lib/python2.7/site-packages/gunicorn/app/base.py", line 67, in wsgi
    self.callable = self.load()
  File "/usr/lib/python2.7/site-packages/gunicorn/app/wsgiapp.py", line 52, in load
    return self.load_wsgiapp()
  File "/usr/lib/python2.7/site-packages/gunicorn/app/wsgiapp.py", line 41, in load_wsgiapp
    return util.import_app(self.app_uri)
  File "/usr/lib/python2.7/site-packages/gunicorn/util.py", line 350, in import_app
    __import__(module)
  File "/opt/graphite/webapp/graphite/wsgi.py", line 15, in <module>
    application = get_wsgi_application()
  File "/usr/lib/python2.7/site-packages/django/core/wsgi.py", line 13, in get_wsgi_application
    django.setup(set_prefix=False)
  File "/usr/lib/python2.7/site-packages/django/__init__.py", line 27, in setup
    apps.populate(settings.INSTALLED_APPS)
  File "/usr/lib/python2.7/site-packages/django/apps/registry.py", line 85, in populate
    app_config = AppConfig.create(entry)
  File "/usr/lib/python2.7/site-packages/django/apps/config.py", line 94, in create
    module = import_module(entry)
  File "/usr/lib/python2.7/importlib/__init__.py", line 37, in import_module
    __import__(name)
  File "/opt/graphite/webapp/graphite/functions/__init__.py", line 10, in <module>
    from graphite.logger import log
  File "/opt/graphite/webapp/graphite/logger.py", line 106, in <module>
    log = GraphiteLogger() # import-shared logger instance
  File "/opt/graphite/webapp/graphite/logger.py", line 39, in __init__
    level = logging.DEBUG if settings.DEBUG else logging.INFO,
  File "/opt/graphite/webapp/graphite/logger.py", line 78, in _config_logger
    handler = Rotater(log_file, when=when, backupCount=backupCount)
  File "/usr/lib/python2.7/logging/handlers.py", line 171, in __init__
    BaseRotatingHandler.__init__(self, filename, 'a', encoding, delay)
  File "/usr/lib/python2.7/logging/handlers.py", line 64, in __init__
    logging.FileHandler.__init__(self, filename, mode, encoding, delay)
  File "/usr/lib/python2.7/logging/__init__.py", line 920, in __init__
    StreamHandler.__init__(self, self._open())
  File "/usr/lib/python2.7/logging/__init__.py", line 950, in _open
    stream = open(self.baseFilename, self.mode)
IOError: [Errno 2] No such file or directory: '/opt/graphite/storage/log/webapp/info.log'
[2019-02-07 16:29:35 +0000] [52] [INFO] Worker exiting (pid: 52)
[2019-02-07 16:29:35 +0000] [51] [ERROR] Exception in worker process
Traceback (most recent call last):
  File "/usr/lib/python2.7/site-packages/gunicorn/arbiter.py", line 583, in spawn_worker
    worker.init_process()
  File "/usr/lib/python2.7/site-packages/gunicorn/workers/base.py", line 129, in init_process
    self.load_wsgi()
  File "/usr/lib/python2.7/site-packages/gunicorn/workers/base.py", line 138, in load_wsgi
    self.wsgi = self.app.wsgi()
  File "/usr/lib/python2.7/site-packages/gunicorn/app/base.py", line 67, in wsgi
    self.callable = self.load()
  File "/usr/lib/python2.7/site-packages/gunicorn/app/wsgiapp.py", line 52, in load
    return self.load_wsgiapp()
  File "/usr/lib/python2.7/site-packages/gunicorn/app/wsgiapp.py", line 41, in load_wsgiapp
    return util.import_app(self.app_uri)
  File "/usr/lib/python2.7/site-packages/gunicorn/util.py", line 350, in import_app
    __import__(module)
  File "/opt/graphite/webapp/graphite/wsgi.py", line 15, in <module>
    application = get_wsgi_application()
  File "/usr/lib/python2.7/site-packages/django/core/wsgi.py", line 13, in get_wsgi_application
    django.setup(set_prefix=False)
  File "/usr/lib/python2.7/site-packages/django/__init__.py", line 27, in setup
    apps.populate(settings.INSTALLED_APPS)
  File "/usr/lib/python2.7/site-packages/django/apps/registry.py", line 85, in populate
    app_config = AppConfig.create(entry)
  File "/usr/lib/python2.7/site-packages/django/apps/config.py", line 94, in create
    module = import_module(entry)
  File "/usr/lib/python2.7/importlib/__init__.py", line 37, in import_module
    __import__(name)
  File "/opt/graphite/webapp/graphite/functions/__init__.py", line 10, in <module>
    from graphite.logger import log
  File "/opt/graphite/webapp/graphite/logger.py", line 106, in <module>
    log = GraphiteLogger() # import-shared logger instance
  File "/opt/graphite/webapp/graphite/logger.py", line 39, in __init__
    level = logging.DEBUG if settings.DEBUG else logging.INFO,
  File "/opt/graphite/webapp/graphite/logger.py", line 78, in _config_logger
    handler = Rotater(log_file, when=when, backupCount=backupCount)
  File "/usr/lib/python2.7/logging/handlers.py", line 171, in __init__
    BaseRotatingHandler.__init__(self, filename, 'a', encoding, delay)
  File "/usr/lib/python2.7/logging/handlers.py", line 64, in __init__
    logging.FileHandler.__init__(self, filename, mode, encoding, delay)
  File "/usr/lib/python2.7/logging/__init__.py", line 920, in __init__
    StreamHandler.__init__(self, self._open())
  File "/usr/lib/python2.7/logging/__init__.py", line 950, in _open
    stream = open(self.baseFilename, self.mode)
IOError: [Errno 2] No such file or directory: '/opt/graphite/storage/log/webapp/info.log'
[2019-02-07 16:29:35 +0000] [51] [INFO] Worker exiting (pid: 51)
Traceback (most recent call last):
  File "/usr/bin/gunicorn", line 11, in <module>
    sys.exit(run())
  File "/usr/lib/python2.7/site-packages/gunicorn/app/wsgiapp.py", line 61, in run
    WSGIApplication("%(prog)s [OPTIONS] [APP_MODULE]").run()
  File "/usr/lib/python2.7/site-packages/gunicorn/app/base.py", line 223, in run
    super(Application, self).run()
  File "/usr/lib/python2.7/site-packages/gunicorn/app/base.py", line 72, in run
    Arbiter(self).run()
  File "/usr/lib/python2.7/site-packages/gunicorn/arbiter.py", line 232, in run
    self.halt(reason=inst.reason, exit_status=inst.exit_status)
  File "/usr/lib/python2.7/site-packages/gunicorn/arbiter.py", line 345, in halt
    self.stop()
  File "/usr/lib/python2.7/site-packages/gunicorn/arbiter.py", line 393, in stop
    time.sleep(0.1)
  File "/usr/lib/python2.7/site-packages/gunicorn/arbiter.py", line 245, in handle_chld
    self.reap_workers()
  File "/usr/lib/python2.7/site-packages/gunicorn/arbiter.py", line 525, in reap_workers
    raise HaltServer(reason, self.WORKER_BOOT_ERROR)
gunicorn.errors.HaltServer: <HaltServer 'Worker failed to boot.' 3>
[2019-02-07 16:29:36 +0000] [53] [INFO] Starting gunicorn 19.9.0
[2019-02-07 16:29:36 +0000] [53] [INFO] Listening at: http://127.0.0.1:8000 (53)
[2019-02-07 16:29:36 +0000] [53] [INFO] Using worker: sync
[2019-02-07 16:29:36 +0000] [55] [INFO] Booting worker with pid: 55
[2019-02-07 16:29:36 +0000] [56] [INFO] Booting worker with pid: 56
[2019-02-07 16:29:36 +0000] [57] [INFO] Booting worker with pid: 57
[2019-02-07 16:29:36 +0000] [58] [INFO] Booting worker with pid: 58
/opt/graphite/webapp/graphite/local_settings.py:334: UserWarning: SECRET_KEY is set to an unsafe default. This should be set in local_settings.py for better security
[2019-02-07 16:29:36 +0000] [55] [ERROR] Exception in worker process
Traceback (most recent call last):
  File "/usr/lib/python2.7/site-packages/gunicorn/arbiter.py", line 583, in spawn_worker
    worker.init_process()
  File "/usr/lib/python2.7/site-packages/gunicorn/workers/base.py", line 129, in init_process
    self.load_wsgi()
  File "/usr/lib/python2.7/site-packages/gunicorn/workers/base.py", line 138, in load_wsgi
    self.wsgi = self.app.wsgi()
  File "/usr/lib/python2.7/site-packages/gunicorn/app/base.py", line 67, in wsgi
    self.callable = self.load()
  File "/usr/lib/python2.7/site-packages/gunicorn/app/wsgiapp.py", line 52, in load
    return self.load_wsgiapp()
  File "/usr/lib/python2.7/site-packages/gunicorn/app/wsgiapp.py", line 41, in load_wsgiapp
    return util.import_app(self.app_uri)
  File "/usr/lib/python2.7/site-packages/gunicorn/util.py", line 350, in import_app
    __import__(module)
  File "/opt/graphite/webapp/graphite/wsgi.py", line 15, in <module>
    application = get_wsgi_application()
  File "/usr/lib/python2.7/site-packages/django/core/wsgi.py", line 13, in get_wsgi_application
    django.setup(set_prefix=False)
  File "/usr/lib/python2.7/site-packages/django/__init__.py", line 27, in setup
    apps.populate(settings.INSTALLED_APPS)
  File "/usr/lib/python2.7/site-packages/django/apps/registry.py", line 85, in populate
    app_config = AppConfig.create(entry)
  File "/usr/lib/python2.7/site-packages/django/apps/config.py", line 94, in create
    module = import_module(entry)
  File "/usr/lib/python2.7/importlib/__init__.py", line 37, in import_module
    __import__(name)
  File "/opt/graphite/webapp/graphite/functions/__init__.py", line 10, in <module>
    from graphite.logger import log
  File "/opt/graphite/webapp/graphite/logger.py", line 106, in <module>
    log = GraphiteLogger() # import-shared logger instance
  File "/opt/graphite/webapp/graphite/logger.py", line 39, in __init__
    level = logging.DEBUG if settings.DEBUG else logging.INFO,
  File "/opt/graphite/webapp/graphite/logger.py", line 78, in _config_logger
    handler = Rotater(log_file, when=when, backupCount=backupCount)
  File "/usr/lib/python2.7/logging/handlers.py", line 171, in __init__
    BaseRotatingHandler.__init__(self, filename, 'a', encoding, delay)
  File "/usr/lib/python2.7/logging/handlers.py", line 64, in __init__
    logging.FileHandler.__init__(self, filename, mode, encoding, delay)
  File "/usr/lib/python2.7/logging/__init__.py", line 920, in __init__
    StreamHandler.__init__(self, self._open())
  File "/usr/lib/python2.7/logging/__init__.py", line 950, in _open
    stream = open(self.baseFilename, self.mode)
IOError: [Errno 2] No such file or directory: '/opt/graphite/storage/log/webapp/info.log'
[2019-02-07 16:29:36 +0000] [55] [INFO] Worker exiting (pid: 55)
/opt/graphite/webapp/graphite/local_settings.py:334: UserWarning: SECRET_KEY is set to an unsafe default. This should be set in local_settings.py for better security
[2019-02-07 16:29:36 +0000] [56] [ERROR] Exception in worker process
Traceback (most recent call last):
  File "/usr/lib/python2.7/site-packages/gunicorn/arbiter.py", line 583, in spawn_worker
    worker.init_process()
  File "/usr/lib/python2.7/site-packages/gunicorn/workers/base.py", line 129, in init_process
    self.load_wsgi()
  File "/usr/lib/python2.7/site-packages/gunicorn/workers/base.py", line 138, in load_wsgi
    self.wsgi = self.app.wsgi()
  File "/usr/lib/python2.7/site-packages/gunicorn/app/base.py", line 67, in wsgi
    self.callable = self.load()
  File "/usr/lib/python2.7/site-packages/gunicorn/app/wsgiapp.py", line 52, in load
    return self.load_wsgiapp()
  File "/usr/lib/python2.7/site-packages/gunicorn/app/wsgiapp.py", line 41, in load_wsgiapp
    return util.import_app(self.app_uri)
  File "/usr/lib/python2.7/site-packages/gunicorn/util.py", line 350, in import_app
    __import__(module)
  File "/opt/graphite/webapp/graphite/wsgi.py", line 15, in <module>
    application = get_wsgi_application()
  File "/usr/lib/python2.7/site-packages/django/core/wsgi.py", line 13, in get_wsgi_application
    django.setup(set_prefix=False)
  File "/usr/lib/python2.7/site-packages/django/__init__.py", line 27, in setup
    apps.populate(settings.INSTALLED_APPS)
  File "/usr/lib/python2.7/site-packages/django/apps/registry.py", line 85, in populate
    app_config = AppConfig.create(entry)
  File "/usr/lib/python2.7/site-packages/django/apps/config.py", line 94, in create
    module = import_module(entry)
  File "/usr/lib/python2.7/importlib/__init__.py", line 37, in import_module
    __import__(name)
  File "/opt/graphite/webapp/graphite/functions/__init__.py", line 10, in <module>
    from graphite.logger import log
  File "/opt/graphite/webapp/graphite/logger.py", line 106, in <module>
    log = GraphiteLogger() # import-shared logger instance
  File "/opt/graphite/webapp/graphite/logger.py", line 39, in __init__
    level = logging.DEBUG if settings.DEBUG else logging.INFO,
  File "/opt/graphite/webapp/graphite/logger.py", line 78, in _config_logger
    handler = Rotater(log_file, when=when, backupCount=backupCount)
  File "/usr/lib/python2.7/logging/handlers.py", line 171, in __init__
    BaseRotatingHandler.__init__(self, filename, 'a', encoding, delay)
  File "/usr/lib/python2.7/logging/handlers.py", line 64, in __init__
    logging.FileHandler.__init__(self, filename, mode, encoding, delay)
  File "/usr/lib/python2.7/logging/__init__.py", line 920, in __init__
    StreamHandler.__init__(self, self._open())
  File "/usr/lib/python2.7/logging/__init__.py", line 950, in _open
    stream = open(self.baseFilename, self.mode)
IOError: [Errno 2] No such file or directory: '/opt/graphite/storage/log/webapp/info.log'
[2019-02-07 16:29:36 +0000] [56] [INFO] Worker exiting (pid: 56)
/opt/graphite/webapp/graphite/local_settings.py:334: UserWarning: SECRET_KEY is set to an unsafe default. This should be set in local_settings.py for better security
[2019-02-07 16:29:36 +0000] [57] [ERROR] Exception in worker process
Traceback (most recent call last):
  File "/usr/lib/python2.7/site-packages/gunicorn/arbiter.py", line 583, in spawn_worker
    worker.init_process()
  File "/usr/lib/python2.7/site-packages/gunicorn/workers/base.py", line 129, in init_process
    self.load_wsgi()
  File "/usr/lib/python2.7/site-packages/gunicorn/workers/base.py", line 138, in load_wsgi
    self.wsgi = self.app.wsgi()
  File "/usr/lib/python2.7/site-packages/gunicorn/app/base.py", line 67, in wsgi
    self.callable = self.load()
  File "/usr/lib/python2.7/site-packages/gunicorn/app/wsgiapp.py", line 52, in load
    return self.load_wsgiapp()
  File "/usr/lib/python2.7/site-packages/gunicorn/app/wsgiapp.py", line 41, in load_wsgiapp
    return util.import_app(self.app_uri)
  File "/usr/lib/python2.7/site-packages/gunicorn/util.py", line 350, in import_app
    __import__(module)
  File "/opt/graphite/webapp/graphite/wsgi.py", line 15, in <module>
    application = get_wsgi_application()
  File "/usr/lib/python2.7/site-packages/django/core/wsgi.py", line 13, in get_wsgi_application
    django.setup(set_prefix=False)
  File "/usr/lib/python2.7/site-packages/django/__init__.py", line 27, in setup
    apps.populate(settings.INSTALLED_APPS)
  File "/usr/lib/python2.7/site-packages/django/apps/registry.py", line 85, in populate
    app_config = AppConfig.create(entry)
  File "/usr/lib/python2.7/site-packages/django/apps/config.py", line 94, in create
    module = import_module(entry)
  File "/usr/lib/python2.7/importlib/__init__.py", line 37, in import_module
    __import__(name)
  File "/opt/graphite/webapp/graphite/functions/__init__.py", line 10, in <module>
    from graphite.logger import log
  File "/opt/graphite/webapp/graphite/logger.py", line 106, in <module>
    log = GraphiteLogger() # import-shared logger instance
  File "/opt/graphite/webapp/graphite/logger.py", line 39, in __init__
    level = logging.DEBUG if settings.DEBUG else logging.INFO,
  File "/opt/graphite/webapp/graphite/logger.py", line 78, in _config_logger
    handler = Rotater(log_file, when=when, backupCount=backupCount)
  File "/usr/lib/python2.7/logging/handlers.py", line 171, in __init__
    BaseRotatingHandler.__init__(self, filename, 'a', encoding, delay)
  File "/usr/lib/python2.7/logging/handlers.py", line 64, in __init__
    logging.FileHandler.__init__(self, filename, mode, encoding, delay)
  File "/usr/lib/python2.7/logging/__init__.py", line 920, in __init__
    StreamHandler.__init__(self, self._open())
  File "/usr/lib/python2.7/logging/__init__.py", line 950, in _open
    stream = open(self.baseFilename, self.mode)
IOError: [Errno 2] No such file or directory: '/opt/graphite/storage/log/webapp/info.log'
[2019-02-07 16:29:36 +0000] [57] [INFO] Worker exiting (pid: 57)
/opt/graphite/webapp/graphite/local_settings.py:334: UserWarning: SECRET_KEY is set to an unsafe default. This should be set in local_settings.py for better security
[2019-02-07 16:29:36 +0000] [58] [ERROR] Exception in worker process
Traceback (most recent call last):
  File "/usr/lib/python2.7/site-packages/gunicorn/arbiter.py", line 583, in spawn_worker
    worker.init_process()
  File "/usr/lib/python2.7/site-packages/gunicorn/workers/base.py", line 129, in init_process
    self.load_wsgi()
  File "/usr/lib/python2.7/site-packages/gunicorn/workers/base.py", line 138, in load_wsgi
    self.wsgi = self.app.wsgi()
  File "/usr/lib/python2.7/site-packages/gunicorn/app/base.py", line 67, in wsgi
    self.callable = self.load()
  File "/usr/lib/python2.7/site-packages/gunicorn/app/wsgiapp.py", line 52, in load
    return self.load_wsgiapp()
  File "/usr/lib/python2.7/site-packages/gunicorn/app/wsgiapp.py", line 41, in load_wsgiapp
    return util.import_app(self.app_uri)
  File "/usr/lib/python2.7/site-packages/gunicorn/util.py", line 350, in import_app
    __import__(module)
  File "/opt/graphite/webapp/graphite/wsgi.py", line 15, in <module>
    application = get_wsgi_application()
  File "/usr/lib/python2.7/site-packages/django/core/wsgi.py", line 13, in get_wsgi_application
    django.setup(set_prefix=False)
  File "/usr/lib/python2.7/site-packages/django/__init__.py", line 27, in setup
    apps.populate(settings.INSTALLED_APPS)
  File "/usr/lib/python2.7/site-packages/django/apps/registry.py", line 85, in populate
    app_config = AppConfig.create(entry)
  File "/usr/lib/python2.7/site-packages/django/apps/config.py", line 94, in create
    module = import_module(entry)
  File "/usr/lib/python2.7/importlib/__init__.py", line 37, in import_module
    __import__(name)
  File "/opt/graphite/webapp/graphite/functions/__init__.py", line 10, in <module>
    from graphite.logger import log
  File "/opt/graphite/webapp/graphite/logger.py", line 106, in <module>
    log = GraphiteLogger() # import-shared logger instance
  File "/opt/graphite/webapp/graphite/logger.py", line 39, in __init__
    level = logging.DEBUG if settings.DEBUG else logging.INFO,
  File "/opt/graphite/webapp/graphite/logger.py", line 78, in _config_logger
    handler = Rotater(log_file, when=when, backupCount=backupCount)
  File "/usr/lib/python2.7/logging/handlers.py", line 171, in __init__
    BaseRotatingHandler.__init__(self, filename, 'a', encoding, delay)
  File "/usr/lib/python2.7/logging/handlers.py", line 64, in __init__
    logging.FileHandler.__init__(self, filename, mode, encoding, delay)
  File "/usr/lib/python2.7/logging/__init__.py", line 920, in __init__
    StreamHandler.__init__(self, self._open())
  File "/usr/lib/python2.7/logging/__init__.py", line 950, in _open
    stream = open(self.baseFilename, self.mode)
IOError: [Errno 2] No such file or directory: '/opt/graphite/storage/log/webapp/info.log'
[2019-02-07 16:29:36 +0000] [58] [INFO] Worker exiting (pid: 58)
Traceback (most recent call last):
  File "/usr/bin/gunicorn", line 11, in <module>
    sys.exit(run())
  File "/usr/lib/python2.7/site-packages/gunicorn/app/wsgiapp.py", line 61, in run
    WSGIApplication("%(prog)s [OPTIONS] [APP_MODULE]").run()
  File "/usr/lib/python2.7/site-packages/gunicorn/app/base.py", line 223, in run
    super(Application, self).run()
  File "/usr/lib/python2.7/site-packages/gunicorn/app/base.py", line 72, in run
    Arbiter(self).run()
  File "/usr/lib/python2.7/site-packages/gunicorn/arbiter.py", line 232, in run
    self.halt(reason=inst.reason, exit_status=inst.exit_status)
  File "/usr/lib/python2.7/site-packages/gunicorn/arbiter.py", line 345, in halt
    self.stop()
  File "/usr/lib/python2.7/site-packages/gunicorn/arbiter.py", line 393, in stop
    time.sleep(0.1)
  File "/usr/lib/python2.7/site-packages/gunicorn/arbiter.py", line 245, in handle_chld
    self.reap_workers()
  File "/usr/lib/python2.7/site-packages/gunicorn/arbiter.py", line 525, in reap_workers
    raise HaltServer(reason, self.WORKER_BOOT_ERROR)
gunicorn.errors.HaltServer: <HaltServer 'Worker failed to boot.' 3>
[2019-02-07 16:29:39 +0000] [59] [INFO] Starting gunicorn 19.9.0
[2019-02-07 16:29:39 +0000] [59] [INFO] Listening at: http://127.0.0.1:8000 (59)
[2019-02-07 16:29:39 +0000] [59] [INFO] Using worker: sync
[2019-02-07 16:29:39 +0000] [61] [INFO] Booting worker with pid: 61
[2019-02-07 16:29:39 +0000] [62] [INFO] Booting worker with pid: 62
/opt/graphite/webapp/graphite/local_settings.py:334: UserWarning: SECRET_KEY is set to an unsafe default. This should be set in local_settings.py for better security
[2019-02-07 16:29:39 +0000] [61] [ERROR] Exception in worker process
Traceback (most recent call last):
  File "/usr/lib/python2.7/site-packages/gunicorn/arbiter.py", line 583, in spawn_worker
    worker.init_process()
  File "/usr/lib/python2.7/site-packages/gunicorn/workers/base.py", line 129, in init_process
    self.load_wsgi()
  File "/usr/lib/python2.7/site-packages/gunicorn/workers/base.py", line 138, in load_wsgi
    self.wsgi = self.app.wsgi()
  File "/usr/lib/python2.7/site-packages/gunicorn/app/base.py", line 67, in wsgi
    self.callable = self.load()
  File "/usr/lib/python2.7/site-packages/gunicorn/app/wsgiapp.py", line 52, in load
    return self.load_wsgiapp()
  File "/usr/lib/python2.7/site-packages/gunicorn/app/wsgiapp.py", line 41, in load_wsgiapp
    return util.import_app(self.app_uri)
  File "/usr/lib/python2.7/site-packages/gunicorn/util.py", line 350, in import_app
    __import__(module)
  File "/opt/graphite/webapp/graphite/wsgi.py", line 15, in <module>
    application = get_wsgi_application()
  File "/usr/lib/python2.7/site-packages/django/core/wsgi.py", line 13, in get_wsgi_application
    django.setup(set_prefix=False)
  File "/usr/lib/python2.7/site-packages/django/__init__.py", line 27, in setup
    apps.populate(settings.INSTALLED_APPS)
  File "/usr/lib/python2.7/site-packages/django/apps/registry.py", line 85, in populate
    app_config = AppConfig.create(entry)
  File "/usr/lib/python2.7/site-packages/django/apps/config.py", line 94, in create
    module = import_module(entry)
  File "/usr/lib/python2.7/importlib/__init__.py", line 37, in import_module
    __import__(name)
  File "/opt/graphite/webapp/graphite/functions/__init__.py", line 10, in <module>
    from graphite.logger import log
  File "/opt/graphite/webapp/graphite/logger.py", line 106, in <module>
    log = GraphiteLogger() # import-shared logger instance
  File "/opt/graphite/webapp/graphite/logger.py", line 39, in __init__
    level = logging.DEBUG if settings.DEBUG else logging.INFO,
  File "/opt/graphite/webapp/graphite/logger.py", line 78, in _config_logger
    handler = Rotater(log_file, when=when, backupCount=backupCount)
  File "/usr/lib/python2.7/logging/handlers.py", line 171, in __init__
    BaseRotatingHandler.__init__(self, filename, 'a', encoding, delay)
  File "/usr/lib/python2.7/logging/handlers.py", line 64, in __init__
    logging.FileHandler.__init__(self, filename, mode, encoding, delay)
  File "/usr/lib/python2.7/logging/__init__.py", line 920, in __init__
    StreamHandler.__init__(self, self._open())
  File "/usr/lib/python2.7/logging/__init__.py", line 950, in _open
    stream = open(self.baseFilename, self.mode)
IOError: [Errno 2] No such file or directory: '/opt/graphite/storage/log/webapp/info.log'
[2019-02-07 16:29:39 +0000] [61] [INFO] Worker exiting (pid: 61)
[2019-02-07 16:29:39 +0000] [63] [INFO] Booting worker with pid: 63
[2019-02-07 16:29:39 +0000] [64] [INFO] Booting worker with pid: 64
/opt/graphite/webapp/graphite/local_settings.py:334: UserWarning: SECRET_KEY is set to an unsafe default. This should be set in local_settings.py for better security
[2019-02-07 16:29:39 +0000] [62] [ERROR] Exception in worker process
Traceback (most recent call last):
  File "/usr/lib/python2.7/site-packages/gunicorn/arbiter.py", line 583, in spawn_worker
    worker.init_process()
  File "/usr/lib/python2.7/site-packages/gunicorn/workers/base.py", line 129, in init_process
    self.load_wsgi()
  File "/usr/lib/python2.7/site-packages/gunicorn/workers/base.py", line 138, in load_wsgi
    self.wsgi = self.app.wsgi()
  File "/usr/lib/python2.7/site-packages/gunicorn/app/base.py", line 67, in wsgi
    self.callable = self.load()
  File "/usr/lib/python2.7/site-packages/gunicorn/app/wsgiapp.py", line 52, in load
    return self.load_wsgiapp()
  File "/usr/lib/python2.7/site-packages/gunicorn/app/wsgiapp.py", line 41, in load_wsgiapp
    return util.import_app(self.app_uri)
  File "/usr/lib/python2.7/site-packages/gunicorn/util.py", line 350, in import_app
    __import__(module)
  File "/opt/graphite/webapp/graphite/wsgi.py", line 15, in <module>
    application = get_wsgi_application()
  File "/usr/lib/python2.7/site-packages/django/core/wsgi.py", line 13, in get_wsgi_application
    django.setup(set_prefix=False)
  File "/usr/lib/python2.7/site-packages/django/__init__.py", line 27, in setup
    apps.populate(settings.INSTALLED_APPS)
  File "/usr/lib/python2.7/site-packages/django/apps/registry.py", line 85, in populate
    app_config = AppConfig.create(entry)
  File "/usr/lib/python2.7/site-packages/django/apps/config.py", line 94, in create
    module = import_module(entry)
  File "/usr/lib/python2.7/importlib/__init__.py", line 37, in import_module
    __import__(name)
  File "/opt/graphite/webapp/graphite/functions/__init__.py", line 10, in <module>
    from graphite.logger import log
  File "/opt/graphite/webapp/graphite/logger.py", line 106, in <module>
    log = GraphiteLogger() # import-shared logger instance
  File "/opt/graphite/webapp/graphite/logger.py", line 39, in __init__
    level = logging.DEBUG if settings.DEBUG else logging.INFO,
  File "/opt/graphite/webapp/graphite/logger.py", line 78, in _config_logger
    handler = Rotater(log_file, when=when, backupCount=backupCount)
  File "/usr/lib/python2.7/logging/handlers.py", line 171, in __init__
    BaseRotatingHandler.__init__(self, filename, 'a', encoding, delay)
  File "/usr/lib/python2.7/logging/handlers.py", line 64, in __init__
    logging.FileHandler.__init__(self, filename, mode, encoding, delay)
  File "/usr/lib/python2.7/logging/__init__.py", line 920, in __init__
    StreamHandler.__init__(self, self._open())
  File "/usr/lib/python2.7/logging/__init__.py", line 950, in _open
    stream = open(self.baseFilename, self.mode)
IOError: [Errno 2] No such file or directory: '/opt/graphite/storage/log/webapp/info.log'
[2019-02-07 16:29:39 +0000] [62] [INFO] Worker exiting (pid: 62)
Traceback (most recent call last):
  File "/usr/bin/gunicorn", line 11, in <module>
    sys.exit(run())
  File "/usr/lib/python2.7/site-packages/gunicorn/app/wsgiapp.py", line 61, in run
    WSGIApplication("%(prog)s [OPTIONS] [APP_MODULE]").run()
  File "/usr/lib/python2.7/site-packages/gunicorn/app/base.py", line 223, in run
    super(Application, self).run()
  File "/usr/lib/python2.7/site-packages/gunicorn/app/base.py", line 72, in run
    Arbiter(self).run()
  File "/usr/lib/python2.7/site-packages/gunicorn/arbiter.py", line 232, in run
    self.halt(reason=inst.reason, exit_status=inst.exit_status)
  File "/usr/lib/python2.7/site-packages/gunicorn/arbiter.py", line 345, in halt
    self.stop()
  File "/usr/lib/python2.7/site-packages/gunicorn/arbiter.py", line 393, in stop
    time.sleep(0.1)
  File "/usr/lib/python2.7/site-packages/gunicorn/arbiter.py", line 245, in handle_chld
    self.reap_workers()
  File "/usr/lib/python2.7/site-packages/gunicorn/arbiter.py", line 525, in reap_workers
    raise HaltServer(reason, self.WORKER_BOOT_ERROR)
gunicorn.errors.HaltServer: <HaltServer 'Worker failed to boot.' 3>
/opt/graphite/webapp/graphite/local_settings.py:334: UserWarning: SECRET_KEY is set to an unsafe default. This should be set in local_settings.py for better security
[2019-02-07 16:29:39 +0000] [63] [ERROR] Exception in worker process
Traceback (most recent call last):
  File "/usr/lib/python2.7/site-packages/gunicorn/arbiter.py", line 583, in spawn_worker
    worker.init_process()
  File "/usr/lib/python2.7/site-packages/gunicorn/workers/base.py", line 129, in init_process
    self.load_wsgi()
  File "/usr/lib/python2.7/site-packages/gunicorn/workers/base.py", line 138, in load_wsgi
    self.wsgi = self.app.wsgi()
  File "/usr/lib/python2.7/site-packages/gunicorn/app/base.py", line 67, in wsgi
    self.callable = self.load()
  File "/usr/lib/python2.7/site-packages/gunicorn/app/wsgiapp.py", line 52, in load
    return self.load_wsgiapp()
  File "/usr/lib/python2.7/site-packages/gunicorn/app/wsgiapp.py", line 41, in load_wsgiapp
    return util.import_app(self.app_uri)
  File "/usr/lib/python2.7/site-packages/gunicorn/util.py", line 350, in import_app
    __import__(module)
  File "/opt/graphite/webapp/graphite/wsgi.py", line 15, in <module>
    application = get_wsgi_application()
  File "/usr/lib/python2.7/site-packages/django/core/wsgi.py", line 13, in get_wsgi_application
    django.setup(set_prefix=False)
  File "/usr/lib/python2.7/site-packages/django/__init__.py", line 27, in setup
    apps.populate(settings.INSTALLED_APPS)
  File "/usr/lib/python2.7/site-packages/django/apps/registry.py", line 85, in populate
    app_config = AppConfig.create(entry)
  File "/usr/lib/python2.7/site-packages/django/apps/config.py", line 94, in create
    module = import_module(entry)
  File "/usr/lib/python2.7/importlib/__init__.py", line 37, in import_module
    __import__(name)
  File "/opt/graphite/webapp/graphite/functions/__init__.py", line 10, in <module>
    from graphite.logger import log
  File "/opt/graphite/webapp/graphite/logger.py", line 106, in <module>
    log = GraphiteLogger() # import-shared logger instance
  File "/opt/graphite/webapp/graphite/logger.py", line 39, in __init__
    level = logging.DEBUG if settings.DEBUG else logging.INFO,
  File "/opt/graphite/webapp/graphite/logger.py", line 78, in _config_logger
    handler = Rotater(log_file, when=when, backupCount=backupCount)
  File "/usr/lib/python2.7/logging/handlers.py", line 171, in __init__
    BaseRotatingHandler.__init__(self, filename, 'a', encoding, delay)
  File "/usr/lib/python2.7/logging/handlers.py", line 64, in __init__
    logging.FileHandler.__init__(self, filename, mode, encoding, delay)
  File "/usr/lib/python2.7/logging/__init__.py", line 920, in __init__
    StreamHandler.__init__(self, self._open())
  File "/usr/lib/python2.7/logging/__init__.py", line 950, in _open
    stream = open(self.baseFilename, self.mode)
IOError: [Errno 2] No such file or directory: '/opt/graphite/storage/log/webapp/info.log'
[2019-02-07 16:29:39 +0000] [63] [INFO] Worker exiting (pid: 63)
[2019-02-07 16:29:43 +0000] [173] [INFO] Starting gunicorn 19.9.0
[2019-02-07 16:29:43 +0000] [173] [INFO] Listening at: http://127.0.0.1:8000 (173)
[2019-02-07 16:29:43 +0000] [173] [INFO] Using worker: sync
[2019-02-07 16:29:43 +0000] [181] [INFO] Booting worker with pid: 181
[2019-02-07 16:29:43 +0000] [182] [INFO] Booting worker with pid: 182
/opt/graphite/webapp/graphite/local_settings.py:334: UserWarning: SECRET_KEY is set to an unsafe default. This should be set in local_settings.py for better security
[2019-02-07 16:29:43 +0000] [183] [INFO] Booting worker with pid: 183
[2019-02-07 16:29:43 +0000] [181] [ERROR] Exception in worker process
Traceback (most recent call last):
  File "/usr/lib/python2.7/site-packages/gunicorn/arbiter.py", line 583, in spawn_worker
    worker.init_process()
  File "/usr/lib/python2.7/site-packages/gunicorn/workers/base.py", line 129, in init_process
    self.load_wsgi()
  File "/usr/lib/python2.7/site-packages/gunicorn/workers/base.py", line 138, in load_wsgi
    self.wsgi = self.app.wsgi()
  File "/usr/lib/python2.7/site-packages/gunicorn/app/base.py", line 67, in wsgi
    self.callable = self.load()
  File "/usr/lib/python2.7/site-packages/gunicorn/app/wsgiapp.py", line 52, in load
    return self.load_wsgiapp()
  File "/usr/lib/python2.7/site-packages/gunicorn/app/wsgiapp.py", line 41, in load_wsgiapp
    return util.import_app(self.app_uri)
  File "/usr/lib/python2.7/site-packages/gunicorn/util.py", line 350, in import_app
    __import__(module)
  File "/opt/graphite/webapp/graphite/wsgi.py", line 15, in <module>
    application = get_wsgi_application()
  File "/usr/lib/python2.7/site-packages/django/core/wsgi.py", line 13, in get_wsgi_application
    django.setup(set_prefix=False)
  File "/usr/lib/python2.7/site-packages/django/__init__.py", line 27, in setup
    apps.populate(settings.INSTALLED_APPS)
  File "/usr/lib/python2.7/site-packages/django/apps/registry.py", line 85, in populate
    app_config = AppConfig.create(entry)
  File "/usr/lib/python2.7/site-packages/django/apps/config.py", line 94, in create
    module = import_module(entry)
  File "/usr/lib/python2.7/importlib/__init__.py", line 37, in import_module
    __import__(name)
  File "/opt/graphite/webapp/graphite/functions/__init__.py", line 10, in <module>
    from graphite.logger import log
  File "/opt/graphite/webapp/graphite/logger.py", line 106, in <module>
    log = GraphiteLogger() # import-shared logger instance
  File "/opt/graphite/webapp/graphite/logger.py", line 39, in __init__
    level = logging.DEBUG if settings.DEBUG else logging.INFO,
  File "/opt/graphite/webapp/graphite/logger.py", line 78, in _config_logger
    handler = Rotater(log_file, when=when, backupCount=backupCount)
  File "/usr/lib/python2.7/logging/handlers.py", line 171, in __init__
    BaseRotatingHandler.__init__(self, filename, 'a', encoding, delay)
  File "/usr/lib/python2.7/logging/handlers.py", line 64, in __init__
    logging.FileHandler.__init__(self, filename, mode, encoding, delay)
  File "/usr/lib/python2.7/logging/__init__.py", line 920, in __init__
    StreamHandler.__init__(self, self._open())
  File "/usr/lib/python2.7/logging/__init__.py", line 950, in _open
    stream = open(self.baseFilename, self.mode)
IOError: [Errno 2] No such file or directory: '/opt/graphite/storage/log/webapp/info.log'
[2019-02-07 16:29:43 +0000] [181] [INFO] Worker exiting (pid: 181)
[2019-02-07 16:29:43 +0000] [184] [INFO] Booting worker with pid: 184
/opt/graphite/webapp/graphite/local_settings.py:334: UserWarning: SECRET_KEY is set to an unsafe default. This should be set in local_settings.py for better security
[2019-02-07 16:29:43 +0000] [182] [ERROR] Exception in worker process
Traceback (most recent call last):
  File "/usr/lib/python2.7/site-packages/gunicorn/arbiter.py", line 583, in spawn_worker
    worker.init_process()
  File "/usr/lib/python2.7/site-packages/gunicorn/workers/base.py", line 129, in init_process
    self.load_wsgi()
  File "/usr/lib/python2.7/site-packages/gunicorn/workers/base.py", line 138, in load_wsgi
    self.wsgi = self.app.wsgi()
  File "/usr/lib/python2.7/site-packages/gunicorn/app/base.py", line 67, in wsgi
    self.callable = self.load()
  File "/usr/lib/python2.7/site-packages/gunicorn/app/wsgiapp.py", line 52, in load
    return self.load_wsgiapp()
  File "/usr/lib/python2.7/site-packages/gunicorn/app/wsgiapp.py", line 41, in load_wsgiapp
    return util.import_app(self.app_uri)
  File "/usr/lib/python2.7/site-packages/gunicorn/util.py", line 350, in import_app
    __import__(module)
  File "/opt/graphite/webapp/graphite/wsgi.py", line 15, in <module>
    application = get_wsgi_application()
  File "/usr/lib/python2.7/site-packages/django/core/wsgi.py", line 13, in get_wsgi_application
    django.setup(set_prefix=False)
  File "/usr/lib/python2.7/site-packages/django/__init__.py", line 27, in setup
    apps.populate(settings.INSTALLED_APPS)
  File "/usr/lib/python2.7/site-packages/django/apps/registry.py", line 85, in populate
    app_config = AppConfig.create(entry)
  File "/usr/lib/python2.7/site-packages/django/apps/config.py", line 94, in create
    module = import_module(entry)
  File "/usr/lib/python2.7/importlib/__init__.py", line 37, in import_module
    __import__(name)
  File "/opt/graphite/webapp/graphite/functions/__init__.py", line 10, in <module>
    from graphite.logger import log
  File "/opt/graphite/webapp/graphite/logger.py", line 106, in <module>
    log = GraphiteLogger() # import-shared logger instance
  File "/opt/graphite/webapp/graphite/logger.py", line 39, in __init__
    level = logging.DEBUG if settings.DEBUG else logging.INFO,
  File "/opt/graphite/webapp/graphite/logger.py", line 78, in _config_logger
    handler = Rotater(log_file, when=when, backupCount=backupCount)
  File "/usr/lib/python2.7/logging/handlers.py", line 171, in __init__
    BaseRotatingHandler.__init__(self, filename, 'a', encoding, delay)
  File "/usr/lib/python2.7/logging/handlers.py", line 64, in __init__
    logging.FileHandler.__init__(self, filename, mode, encoding, delay)
  File "/usr/lib/python2.7/logging/__init__.py", line 920, in __init__
    StreamHandler.__init__(self, self._open())
  File "/usr/lib/python2.7/logging/__init__.py", line 950, in _open
    stream = open(self.baseFilename, self.mode)
IOError: [Errno 2] No such file or directory: '/opt/graphite/storage/log/webapp/info.log'
[2019-02-07 16:29:43 +0000] [182] [INFO] Worker exiting (pid: 182)
/opt/graphite/webapp/graphite/local_settings.py:334: UserWarning: SECRET_KEY is set to an unsafe default. This should be set in local_settings.py for better security
Traceback (most recent call last):
  File "/usr/bin/gunicorn", line 11, in <module>
    sys.exit(run())
  File "/usr/lib/python2.7/site-packages/gunicorn/app/wsgiapp.py", line 61, in run
    WSGIApplication("%(prog)s [OPTIONS] [APP_MODULE]").run()
  File "/usr/lib/python2.7/site-packages/gunicorn/app/base.py", line 223, in run
    super(Application, self).run()
  File "/usr/lib/python2.7/site-packages/gunicorn/app/base.py", line 72, in run
    Arbiter(self).run()
  File "/usr/lib/python2.7/site-packages/gunicorn/arbiter.py", line 232, in run
    self.halt(reason=inst.reason, exit_status=inst.exit_status)
  File "/usr/lib/python2.7/site-packages/gunicorn/arbiter.py", line 345, in halt
    self.stop()
  File "/usr/lib/python2.7/site-packages/gunicorn/arbiter.py", line 393, in stop
    time.sleep(0.1)
  File "/usr/lib/python2.7/site-packages/gunicorn/arbiter.py", line 245, in handle_chld
    self.reap_workers()
  File "/usr/lib/python2.7/site-packages/gunicorn/arbiter.py", line 525, in reap_workers
    raise HaltServer(reason, self.WORKER_BOOT_ERROR)
gunicorn.errors.HaltServer: <HaltServer 'Worker failed to boot.' 3>
[2019-02-07 16:29:43 +0000] [184] [ERROR] Exception in worker process
Traceback (most recent call last):
  File "/usr/lib/python2.7/site-packages/gunicorn/arbiter.py", line 583, in spawn_worker
    worker.init_process()
  File "/usr/lib/python2.7/site-packages/gunicorn/workers/base.py", line 129, in init_process
    self.load_wsgi()
  File "/usr/lib/python2.7/site-packages/gunicorn/workers/base.py", line 138, in load_wsgi
    self.wsgi = self.app.wsgi()
  File "/usr/lib/python2.7/site-packages/gunicorn/app/base.py", line 67, in wsgi
    self.callable = self.load()
  File "/usr/lib/python2.7/site-packages/gunicorn/app/wsgiapp.py", line 52, in load
    return self.load_wsgiapp()
  File "/usr/lib/python2.7/site-packages/gunicorn/app/wsgiapp.py", line 41, in load_wsgiapp
    return util.import_app(self.app_uri)
  File "/usr/lib/python2.7/site-packages/gunicorn/util.py", line 350, in import_app
    __import__(module)
  File "/opt/graphite/webapp/graphite/wsgi.py", line 15, in <module>
    application = get_wsgi_application()
  File "/usr/lib/python2.7/site-packages/django/core/wsgi.py", line 13, in get_wsgi_application
    django.setup(set_prefix=False)
  File "/usr/lib/python2.7/site-packages/django/__init__.py", line 27, in setup
    apps.populate(settings.INSTALLED_APPS)
  File "/usr/lib/python2.7/site-packages/django/apps/registry.py", line 85, in populate
    app_config = AppConfig.create(entry)
  File "/usr/lib/python2.7/site-packages/django/apps/config.py", line 94, in create
    module = import_module(entry)
  File "/usr/lib/python2.7/importlib/__init__.py", line 37, in import_module
    __import__(name)
  File "/opt/graphite/webapp/graphite/functions/__init__.py", line 10, in <module>
    from graphite.logger import log
  File "/opt/graphite/webapp/graphite/logger.py", line 106, in <module>
    log = GraphiteLogger() # import-shared logger instance
  File "/opt/graphite/webapp/graphite/logger.py", line 39, in __init__
    level = logging.DEBUG if settings.DEBUG else logging.INFO,
  File "/opt/graphite/webapp/graphite/logger.py", line 78, in _config_logger
    handler = Rotater(log_file, when=when, backupCount=backupCount)
  File "/usr/lib/python2.7/logging/handlers.py", line 171, in __init__
    BaseRotatingHandler.__init__(self, filename, 'a', encoding, delay)
  File "/usr/lib/python2.7/logging/handlers.py", line 64, in __init__
    logging.FileHandler.__init__(self, filename, mode, encoding, delay)
  File "/usr/lib/python2.7/logging/__init__.py", line 920, in __init__
    StreamHandler.__init__(self, self._open())
  File "/usr/lib/python2.7/logging/__init__.py", line 950, in _open
    stream = open(self.baseFilename, self.mode)
IOError: [Errno 2] No such file or directory: '/opt/graphite/storage/log/webapp/info.log'
[2019-02-07 16:29:43 +0000] [184] [INFO] Worker exiting (pid: 184)
[2019-02-07 16:33:21 +0000] [19] [INFO] Starting gunicorn 19.9.0
[2019-02-07 16:33:21 +0000] [19] [INFO] Listening at: http://127.0.0.1:8000 (19)
[2019-02-07 16:33:21 +0000] [19] [INFO] Using worker: sync
[2019-02-07 16:33:21 +0000] [38] [INFO] Booting worker with pid: 38
[2019-02-07 16:33:21 +0000] [39] [INFO] Booting worker with pid: 39
[2019-02-07 16:33:21 +0000] [40] [INFO] Booting worker with pid: 40
[2019-02-07 16:33:21 +0000] [41] [INFO] Booting worker with pid: 41
/opt/graphite/webapp/graphite/local_settings.py:334: UserWarning: SECRET_KEY is set to an unsafe default. This should be set in local_settings.py for better security
/opt/graphite/webapp/graphite/local_settings.py:334: UserWarning: SECRET_KEY is set to an unsafe default. This should be set in local_settings.py for better security
[2019-02-07 16:33:22 +0000] [38] [ERROR] Exception in worker process
Traceback (most recent call last):
  File "/usr/lib/python2.7/site-packages/gunicorn/arbiter.py", line 583, in spawn_worker
    worker.init_process()
  File "/usr/lib/python2.7/site-packages/gunicorn/workers/base.py", line 129, in init_process
    self.load_wsgi()
  File "/usr/lib/python2.7/site-packages/gunicorn/workers/base.py", line 138, in load_wsgi
    self.wsgi = self.app.wsgi()
  File "/usr/lib/python2.7/site-packages/gunicorn/app/base.py", line 67, in wsgi
    self.callable = self.load()
  File "/usr/lib/python2.7/site-packages/gunicorn/app/wsgiapp.py", line 52, in load
    return self.load_wsgiapp()
  File "/usr/lib/python2.7/site-packages/gunicorn/app/wsgiapp.py", line 41, in load_wsgiapp
    return util.import_app(self.app_uri)
  File "/usr/lib/python2.7/site-packages/gunicorn/util.py", line 350, in import_app
    __import__(module)
  File "/opt/graphite/webapp/graphite/wsgi.py", line 15, in <module>
    application = get_wsgi_application()
  File "/usr/lib/python2.7/site-packages/django/core/wsgi.py", line 13, in get_wsgi_application
    django.setup(set_prefix=False)
  File "/usr/lib/python2.7/site-packages/django/__init__.py", line 27, in setup
    apps.populate(settings.INSTALLED_APPS)
  File "/usr/lib/python2.7/site-packages/django/apps/registry.py", line 85, in populate
    app_config = AppConfig.create(entry)
  File "/usr/lib/python2.7/site-packages/django/apps/config.py", line 94, in create
    module = import_module(entry)
  File "/usr/lib/python2.7/importlib/__init__.py", line 37, in import_module
    __import__(name)
  File "/opt/graphite/webapp/graphite/functions/__init__.py", line 10, in <module>
    from graphite.logger import log
  File "/opt/graphite/webapp/graphite/logger.py", line 106, in <module>
    log = GraphiteLogger() # import-shared logger instance
  File "/opt/graphite/webapp/graphite/logger.py", line 39, in __init__
    level = logging.DEBUG if settings.DEBUG else logging.INFO,
  File "/opt/graphite/webapp/graphite/logger.py", line 78, in _config_logger
    handler = Rotater(log_file, when=when, backupCount=backupCount)
  File "/usr/lib/python2.7/logging/handlers.py", line 171, in __init__
    BaseRotatingHandler.__init__(self, filename, 'a', encoding, delay)
  File "/usr/lib/python2.7/logging/handlers.py", line 64, in __init__
    logging.FileHandler.__init__(self, filename, mode, encoding, delay)
  File "/usr/lib/python2.7/logging/__init__.py", line 920, in __init__
    StreamHandler.__init__(self, self._open())
  File "/usr/lib/python2.7/logging/__init__.py", line 950, in _open
    stream = open(self.baseFilename, self.mode)
IOError: [Errno 2] No such file or directory: '/opt/graphite/storage/log/webapp/info.log'
[2019-02-07 16:33:22 +0000] [38] [INFO] Worker exiting (pid: 38)
[2019-02-07 16:33:22 +0000] [39] [ERROR] Exception in worker process
Traceback (most recent call last):
  File "/usr/lib/python2.7/site-packages/gunicorn/arbiter.py", line 583, in spawn_worker
    worker.init_process()
  File "/usr/lib/python2.7/site-packages/gunicorn/workers/base.py", line 129, in init_process
    self.load_wsgi()
  File "/usr/lib/python2.7/site-packages/gunicorn/workers/base.py", line 138, in load_wsgi
    self.wsgi = self.app.wsgi()
  File "/usr/lib/python2.7/site-packages/gunicorn/app/base.py", line 67, in wsgi
    self.callable = self.load()
  File "/usr/lib/python2.7/site-packages/gunicorn/app/wsgiapp.py", line 52, in load
    return self.load_wsgiapp()
  File "/usr/lib/python2.7/site-packages/gunicorn/app/wsgiapp.py", line 41, in load_wsgiapp
    return util.import_app(self.app_uri)
  File "/usr/lib/python2.7/site-packages/gunicorn/util.py", line 350, in import_app
    __import__(module)
  File "/opt/graphite/webapp/graphite/wsgi.py", line 15, in <module>
    application = get_wsgi_application()
  File "/usr/lib/python2.7/site-packages/django/core/wsgi.py", line 13, in get_wsgi_application
    django.setup(set_prefix=False)
  File "/usr/lib/python2.7/site-packages/django/__init__.py", line 27, in setup
    apps.populate(settings.INSTALLED_APPS)
  File "/usr/lib/python2.7/site-packages/django/apps/registry.py", line 85, in populate
    app_config = AppConfig.create(entry)
  File "/usr/lib/python2.7/site-packages/django/apps/config.py", line 94, in create
    module = import_module(entry)
  File "/usr/lib/python2.7/importlib/__init__.py", line 37, in import_module
    __import__(name)
  File "/opt/graphite/webapp/graphite/functions/__init__.py", line 10, in <module>
    from graphite.logger import log
  File "/opt/graphite/webapp/graphite/logger.py", line 106, in <module>
    log = GraphiteLogger() # import-shared logger instance
  File "/opt/graphite/webapp/graphite/logger.py", line 39, in __init__
    level = logging.DEBUG if settings.DEBUG else logging.INFO,
  File "/opt/graphite/webapp/graphite/logger.py", line 78, in _config_logger
    handler = Rotater(log_file, when=when, backupCount=backupCount)
  File "/usr/lib/python2.7/logging/handlers.py", line 171, in __init__
    BaseRotatingHandler.__init__(self, filename, 'a', encoding, delay)
  File "/usr/lib/python2.7/logging/handlers.py", line 64, in __init__
    logging.FileHandler.__init__(self, filename, mode, encoding, delay)
  File "/usr/lib/python2.7/logging/__init__.py", line 920, in __init__
    StreamHandler.__init__(self, self._open())
  File "/usr/lib/python2.7/logging/__init__.py", line 950, in _open
    stream = open(self.baseFilename, self.mode)
IOError: [Errno 2] No such file or directory: '/opt/graphite/storage/log/webapp/info.log'
[2019-02-07 16:33:22 +0000] [39] [INFO] Worker exiting (pid: 39)
/opt/graphite/webapp/graphite/local_settings.py:334: UserWarning: SECRET_KEY is set to an unsafe default. This should be set in local_settings.py for better security
[2019-02-07 16:33:22 +0000] [40] [ERROR] Exception in worker process
Traceback (most recent call last):
  File "/usr/lib/python2.7/site-packages/gunicorn/arbiter.py", line 583, in spawn_worker
    worker.init_process()
  File "/usr/lib/python2.7/site-packages/gunicorn/workers/base.py", line 129, in init_process
    self.load_wsgi()
  File "/usr/lib/python2.7/site-packages/gunicorn/workers/base.py", line 138, in load_wsgi
    self.wsgi = self.app.wsgi()
  File "/usr/lib/python2.7/site-packages/gunicorn/app/base.py", line 67, in wsgi
    self.callable = self.load()
  File "/usr/lib/python2.7/site-packages/gunicorn/app/wsgiapp.py", line 52, in load
    return self.load_wsgiapp()
  File "/usr/lib/python2.7/site-packages/gunicorn/app/wsgiapp.py", line 41, in load_wsgiapp
    return util.import_app(self.app_uri)
  File "/usr/lib/python2.7/site-packages/gunicorn/util.py", line 350, in import_app
    __import__(module)
  File "/opt/graphite/webapp/graphite/wsgi.py", line 15, in <module>
    application = get_wsgi_application()
  File "/usr/lib/python2.7/site-packages/django/core/wsgi.py", line 13, in get_wsgi_application
    django.setup(set_prefix=False)
  File "/usr/lib/python2.7/site-packages/django/__init__.py", line 27, in setup
    apps.populate(settings.INSTALLED_APPS)
  File "/usr/lib/python2.7/site-packages/django/apps/registry.py", line 85, in populate
    app_config = AppConfig.create(entry)
  File "/usr/lib/python2.7/site-packages/django/apps/config.py", line 94, in create
    module = import_module(entry)
  File "/usr/lib/python2.7/importlib/__init__.py", line 37, in import_module
    __import__(name)
  File "/opt/graphite/webapp/graphite/functions/__init__.py", line 10, in <module>
    from graphite.logger import log
  File "/opt/graphite/webapp/graphite/logger.py", line 106, in <module>
    log = GraphiteLogger() # import-shared logger instance
  File "/opt/graphite/webapp/graphite/logger.py", line 39, in __init__
    level = logging.DEBUG if settings.DEBUG else logging.INFO,
  File "/opt/graphite/webapp/graphite/logger.py", line 78, in _config_logger
    handler = Rotater(log_file, when=when, backupCount=backupCount)
  File "/usr/lib/python2.7/logging/handlers.py", line 171, in __init__
    BaseRotatingHandler.__init__(self, filename, 'a', encoding, delay)
  File "/usr/lib/python2.7/logging/handlers.py", line 64, in __init__
    logging.FileHandler.__init__(self, filename, mode, encoding, delay)
  File "/usr/lib/python2.7/logging/__init__.py", line 920, in __init__
    StreamHandler.__init__(self, self._open())
  File "/usr/lib/python2.7/logging/__init__.py", line 950, in _open
    stream = open(self.baseFilename, self.mode)
IOError: [Errno 2] No such file or directory: '/opt/graphite/storage/log/webapp/info.log'
[2019-02-07 16:33:22 +0000] [40] [INFO] Worker exiting (pid: 40)
/opt/graphite/webapp/graphite/local_settings.py:334: UserWarning: SECRET_KEY is set to an unsafe default. This should be set in local_settings.py for better security
[2019-02-07 16:33:22 +0000] [41] [ERROR] Exception in worker process
Traceback (most recent call last):
  File "/usr/lib/python2.7/site-packages/gunicorn/arbiter.py", line 583, in spawn_worker
    worker.init_process()
  File "/usr/lib/python2.7/site-packages/gunicorn/workers/base.py", line 129, in init_process
    self.load_wsgi()
  File "/usr/lib/python2.7/site-packages/gunicorn/workers/base.py", line 138, in load_wsgi
    self.wsgi = self.app.wsgi()
  File "/usr/lib/python2.7/site-packages/gunicorn/app/base.py", line 67, in wsgi
    self.callable = self.load()
  File "/usr/lib/python2.7/site-packages/gunicorn/app/wsgiapp.py", line 52, in load
    return self.load_wsgiapp()
  File "/usr/lib/python2.7/site-packages/gunicorn/app/wsgiapp.py", line 41, in load_wsgiapp
    return util.import_app(self.app_uri)
  File "/usr/lib/python2.7/site-packages/gunicorn/util.py", line 350, in import_app
    __import__(module)
  File "/opt/graphite/webapp/graphite/wsgi.py", line 15, in <module>
    application = get_wsgi_application()
  File "/usr/lib/python2.7/site-packages/django/core/wsgi.py", line 13, in get_wsgi_application
    django.setup(set_prefix=False)
  File "/usr/lib/python2.7/site-packages/django/__init__.py", line 27, in setup
    apps.populate(settings.INSTALLED_APPS)
  File "/usr/lib/python2.7/site-packages/django/apps/registry.py", line 85, in populate
    app_config = AppConfig.create(entry)
  File "/usr/lib/python2.7/site-packages/django/apps/config.py", line 94, in create
    module = import_module(entry)
  File "/usr/lib/python2.7/importlib/__init__.py", line 37, in import_module
    __import__(name)
  File "/opt/graphite/webapp/graphite/functions/__init__.py", line 10, in <module>
    from graphite.logger import log
  File "/opt/graphite/webapp/graphite/logger.py", line 106, in <module>
    log = GraphiteLogger() # import-shared logger instance
  File "/opt/graphite/webapp/graphite/logger.py", line 39, in __init__
    level = logging.DEBUG if settings.DEBUG else logging.INFO,
  File "/opt/graphite/webapp/graphite/logger.py", line 78, in _config_logger
    handler = Rotater(log_file, when=when, backupCount=backupCount)
  File "/usr/lib/python2.7/logging/handlers.py", line 171, in __init__
    BaseRotatingHandler.__init__(self, filename, 'a', encoding, delay)
  File "/usr/lib/python2.7/logging/handlers.py", line 64, in __init__
    logging.FileHandler.__init__(self, filename, mode, encoding, delay)
  File "/usr/lib/python2.7/logging/__init__.py", line 920, in __init__
    StreamHandler.__init__(self, self._open())
  File "/usr/lib/python2.7/logging/__init__.py", line 950, in _open
    stream = open(self.baseFilename, self.mode)
IOError: [Errno 2] No such file or directory: '/opt/graphite/storage/log/webapp/info.log'
[2019-02-07 16:33:22 +0000] [41] [INFO] Worker exiting (pid: 41)
Traceback (most recent call last):
  File "/usr/bin/gunicorn", line 11, in <module>
    sys.exit(run())
  File "/usr/lib/python2.7/site-packages/gunicorn/app/wsgiapp.py", line 61, in run
    WSGIApplication("%(prog)s [OPTIONS] [APP_MODULE]").run()
  File "/usr/lib/python2.7/site-packages/gunicorn/app/base.py", line 223, in run
    super(Application, self).run()
  File "/usr/lib/python2.7/site-packages/gunicorn/app/base.py", line 72, in run
    Arbiter(self).run()
  File "/usr/lib/python2.7/site-packages/gunicorn/arbiter.py", line 232, in run
    self.halt(reason=inst.reason, exit_status=inst.exit_status)
  File "/usr/lib/python2.7/site-packages/gunicorn/arbiter.py", line 345, in halt
    self.stop()
  File "/usr/lib/python2.7/site-packages/gunicorn/arbiter.py", line 393, in stop
    time.sleep(0.1)
  File "/usr/lib/python2.7/site-packages/gunicorn/arbiter.py", line 245, in handle_chld
    self.reap_workers()
  File "/usr/lib/python2.7/site-packages/gunicorn/arbiter.py", line 525, in reap_workers
    raise HaltServer(reason, self.WORKER_BOOT_ERROR)
gunicorn.errors.HaltServer: <HaltServer 'Worker failed to boot.' 3>
[2019-02-07 16:33:23 +0000] [42] [INFO] Starting gunicorn 19.9.0
[2019-02-07 16:33:23 +0000] [42] [INFO] Listening at: http://127.0.0.1:8000 (42)
[2019-02-07 16:33:23 +0000] [42] [INFO] Using worker: sync
[2019-02-07 16:33:23 +0000] [44] [INFO] Booting worker with pid: 44
[2019-02-07 16:33:23 +0000] [45] [INFO] Booting worker with pid: 45
[2019-02-07 16:33:23 +0000] [46] [INFO] Booting worker with pid: 46
[2019-02-07 16:33:23 +0000] [47] [INFO] Booting worker with pid: 47
/opt/graphite/webapp/graphite/local_settings.py:334: UserWarning: SECRET_KEY is set to an unsafe default. This should be set in local_settings.py for better security
[2019-02-07 16:33:23 +0000] [44] [ERROR] Exception in worker process
Traceback (most recent call last):
  File "/usr/lib/python2.7/site-packages/gunicorn/arbiter.py", line 583, in spawn_worker
    worker.init_process()
  File "/usr/lib/python2.7/site-packages/gunicorn/workers/base.py", line 129, in init_process
    self.load_wsgi()
  File "/usr/lib/python2.7/site-packages/gunicorn/workers/base.py", line 138, in load_wsgi
    self.wsgi = self.app.wsgi()
  File "/usr/lib/python2.7/site-packages/gunicorn/app/base.py", line 67, in wsgi
    self.callable = self.load()
  File "/usr/lib/python2.7/site-packages/gunicorn/app/wsgiapp.py", line 52, in load
    return self.load_wsgiapp()
  File "/usr/lib/python2.7/site-packages/gunicorn/app/wsgiapp.py", line 41, in load_wsgiapp
    return util.import_app(self.app_uri)
  File "/usr/lib/python2.7/site-packages/gunicorn/util.py", line 350, in import_app
    __import__(module)
  File "/opt/graphite/webapp/graphite/wsgi.py", line 15, in <module>
    application = get_wsgi_application()
  File "/usr/lib/python2.7/site-packages/django/core/wsgi.py", line 13, in get_wsgi_application
    django.setup(set_prefix=False)
  File "/usr/lib/python2.7/site-packages/django/__init__.py", line 27, in setup
    apps.populate(settings.INSTALLED_APPS)
  File "/usr/lib/python2.7/site-packages/django/apps/registry.py", line 85, in populate
    app_config = AppConfig.create(entry)
  File "/usr/lib/python2.7/site-packages/django/apps/config.py", line 94, in create
    module = import_module(entry)
  File "/usr/lib/python2.7/importlib/__init__.py", line 37, in import_module
    __import__(name)
  File "/opt/graphite/webapp/graphite/functions/__init__.py", line 10, in <module>
    from graphite.logger import log
  File "/opt/graphite/webapp/graphite/logger.py", line 106, in <module>
    log = GraphiteLogger() # import-shared logger instance
  File "/opt/graphite/webapp/graphite/logger.py", line 39, in __init__
    level = logging.DEBUG if settings.DEBUG else logging.INFO,
  File "/opt/graphite/webapp/graphite/logger.py", line 78, in _config_logger
    handler = Rotater(log_file, when=when, backupCount=backupCount)
  File "/usr/lib/python2.7/logging/handlers.py", line 171, in __init__
    BaseRotatingHandler.__init__(self, filename, 'a', encoding, delay)
  File "/usr/lib/python2.7/logging/handlers.py", line 64, in __init__
    logging.FileHandler.__init__(self, filename, mode, encoding, delay)
  File "/usr/lib/python2.7/logging/__init__.py", line 920, in __init__
    StreamHandler.__init__(self, self._open())
  File "/usr/lib/python2.7/logging/__init__.py", line 950, in _open
    stream = open(self.baseFilename, self.mode)
IOError: [Errno 2] No such file or directory: '/opt/graphite/storage/log/webapp/info.log'
[2019-02-07 16:33:23 +0000] [44] [INFO] Worker exiting (pid: 44)
/opt/graphite/webapp/graphite/local_settings.py:334: UserWarning: SECRET_KEY is set to an unsafe default. This should be set in local_settings.py for better security
[2019-02-07 16:33:23 +0000] [45] [ERROR] Exception in worker process
Traceback (most recent call last):
  File "/usr/lib/python2.7/site-packages/gunicorn/arbiter.py", line 583, in spawn_worker
    worker.init_process()
  File "/usr/lib/python2.7/site-packages/gunicorn/workers/base.py", line 129, in init_process
    self.load_wsgi()
  File "/usr/lib/python2.7/site-packages/gunicorn/workers/base.py", line 138, in load_wsgi
    self.wsgi = self.app.wsgi()
  File "/usr/lib/python2.7/site-packages/gunicorn/app/base.py", line 67, in wsgi
    self.callable = self.load()
  File "/usr/lib/python2.7/site-packages/gunicorn/app/wsgiapp.py", line 52, in load
    return self.load_wsgiapp()
  File "/usr/lib/python2.7/site-packages/gunicorn/app/wsgiapp.py", line 41, in load_wsgiapp
    return util.import_app(self.app_uri)
  File "/usr/lib/python2.7/site-packages/gunicorn/util.py", line 350, in import_app
    __import__(module)
  File "/opt/graphite/webapp/graphite/wsgi.py", line 15, in <module>
    application = get_wsgi_application()
  File "/usr/lib/python2.7/site-packages/django/core/wsgi.py", line 13, in get_wsgi_application
    django.setup(set_prefix=False)
  File "/usr/lib/python2.7/site-packages/django/__init__.py", line 27, in setup
    apps.populate(settings.INSTALLED_APPS)
  File "/usr/lib/python2.7/site-packages/django/apps/registry.py", line 85, in populate
    app_config = AppConfig.create(entry)
  File "/usr/lib/python2.7/site-packages/django/apps/config.py", line 94, in create
    module = import_module(entry)
  File "/usr/lib/python2.7/importlib/__init__.py", line 37, in import_module
    __import__(name)
  File "/opt/graphite/webapp/graphite/functions/__init__.py", line 10, in <module>
    from graphite.logger import log
  File "/opt/graphite/webapp/graphite/logger.py", line 106, in <module>
    log = GraphiteLogger() # import-shared logger instance
  File "/opt/graphite/webapp/graphite/logger.py", line 39, in __init__
    level = logging.DEBUG if settings.DEBUG else logging.INFO,
  File "/opt/graphite/webapp/graphite/logger.py", line 78, in _config_logger
    handler = Rotater(log_file, when=when, backupCount=backupCount)
  File "/usr/lib/python2.7/logging/handlers.py", line 171, in __init__
    BaseRotatingHandler.__init__(self, filename, 'a', encoding, delay)
  File "/usr/lib/python2.7/logging/handlers.py", line 64, in __init__
    logging.FileHandler.__init__(self, filename, mode, encoding, delay)
  File "/usr/lib/python2.7/logging/__init__.py", line 920, in __init__
    StreamHandler.__init__(self, self._open())
  File "/usr/lib/python2.7/logging/__init__.py", line 950, in _open
    stream = open(self.baseFilename, self.mode)
IOError: [Errno 2] No such file or directory: '/opt/graphite/storage/log/webapp/info.log'
[2019-02-07 16:33:23 +0000] [45] [INFO] Worker exiting (pid: 45)
/opt/graphite/webapp/graphite/local_settings.py:334: UserWarning: SECRET_KEY is set to an unsafe default. This should be set in local_settings.py for better security
[2019-02-07 16:33:23 +0000] [46] [ERROR] Exception in worker process
Traceback (most recent call last):
  File "/usr/lib/python2.7/site-packages/gunicorn/arbiter.py", line 583, in spawn_worker
    worker.init_process()
  File "/usr/lib/python2.7/site-packages/gunicorn/workers/base.py", line 129, in init_process
    self.load_wsgi()
  File "/usr/lib/python2.7/site-packages/gunicorn/workers/base.py", line 138, in load_wsgi
    self.wsgi = self.app.wsgi()
  File "/usr/lib/python2.7/site-packages/gunicorn/app/base.py", line 67, in wsgi
    self.callable = self.load()
  File "/usr/lib/python2.7/site-packages/gunicorn/app/wsgiapp.py", line 52, in load
    return self.load_wsgiapp()
  File "/usr/lib/python2.7/site-packages/gunicorn/app/wsgiapp.py", line 41, in load_wsgiapp
    return util.import_app(self.app_uri)
  File "/usr/lib/python2.7/site-packages/gunicorn/util.py", line 350, in import_app
    __import__(module)
  File "/opt/graphite/webapp/graphite/wsgi.py", line 15, in <module>
    application = get_wsgi_application()
  File "/usr/lib/python2.7/site-packages/django/core/wsgi.py", line 13, in get_wsgi_application
    django.setup(set_prefix=False)
  File "/usr/lib/python2.7/site-packages/django/__init__.py", line 27, in setup
    apps.populate(settings.INSTALLED_APPS)
  File "/usr/lib/python2.7/site-packages/django/apps/registry.py", line 85, in populate
    app_config = AppConfig.create(entry)
  File "/usr/lib/python2.7/site-packages/django/apps/config.py", line 94, in create
    module = import_module(entry)
  File "/usr/lib/python2.7/importlib/__init__.py", line 37, in import_module
    __import__(name)
  File "/opt/graphite/webapp/graphite/functions/__init__.py", line 10, in <module>
    from graphite.logger import log
  File "/opt/graphite/webapp/graphite/logger.py", line 106, in <module>
    log = GraphiteLogger() # import-shared logger instance
  File "/opt/graphite/webapp/graphite/logger.py", line 39, in __init__
    level = logging.DEBUG if settings.DEBUG else logging.INFO,
  File "/opt/graphite/webapp/graphite/logger.py", line 78, in _config_logger
    handler = Rotater(log_file, when=when, backupCount=backupCount)
  File "/usr/lib/python2.7/logging/handlers.py", line 171, in __init__
    BaseRotatingHandler.__init__(self, filename, 'a', encoding, delay)
  File "/usr/lib/python2.7/logging/handlers.py", line 64, in __init__
    logging.FileHandler.__init__(self, filename, mode, encoding, delay)
  File "/usr/lib/python2.7/logging/__init__.py", line 920, in __init__
    StreamHandler.__init__(self, self._open())
  File "/usr/lib/python2.7/logging/__init__.py", line 950, in _open
    stream = open(self.baseFilename, self.mode)
IOError: [Errno 2] No such file or directory: '/opt/graphite/storage/log/webapp/info.log'
[2019-02-07 16:33:23 +0000] [46] [INFO] Worker exiting (pid: 46)
Traceback (most recent call last):
  File "/usr/bin/gunicorn", line 11, in <module>
    sys.exit(run())
  File "/usr/lib/python2.7/site-packages/gunicorn/app/wsgiapp.py", line 61, in run
    WSGIApplication("%(prog)s [OPTIONS] [APP_MODULE]").run()
  File "/usr/lib/python2.7/site-packages/gunicorn/app/base.py", line 223, in run
    super(Application, self).run()
  File "/usr/lib/python2.7/site-packages/gunicorn/app/base.py", line 72, in run
    Arbiter(self).run()
  File "/usr/lib/python2.7/site-packages/gunicorn/arbiter.py", line 232, in run
    self.halt(reason=inst.reason, exit_status=inst.exit_status)
  File "/usr/lib/python2.7/site-packages/gunicorn/arbiter.py", line 345, in halt
    self.stop()
  File "/usr/lib/python2.7/site-packages/gunicorn/arbiter.py", line 393, in stop
    time.sleep(0.1)
  File "/usr/lib/python2.7/site-packages/gunicorn/arbiter.py", line 245, in handle_chld
    self.reap_workers()
  File "/usr/lib/python2.7/site-packages/gunicorn/arbiter.py", line 525, in reap_workers
    raise HaltServer(reason, self.WORKER_BOOT_ERROR)
gunicorn.errors.HaltServer: <HaltServer 'Worker failed to boot.' 3>
/opt/graphite/webapp/graphite/local_settings.py:334: UserWarning: SECRET_KEY is set to an unsafe default. This should be set in local_settings.py for better security
[2019-02-07 16:33:24 +0000] [47] [ERROR] Exception in worker process
Traceback (most recent call last):
  File "/usr/lib/python2.7/site-packages/gunicorn/arbiter.py", line 583, in spawn_worker
    worker.init_process()
  File "/usr/lib/python2.7/site-packages/gunicorn/workers/base.py", line 129, in init_process
    self.load_wsgi()
  File "/usr/lib/python2.7/site-packages/gunicorn/workers/base.py", line 138, in load_wsgi
    self.wsgi = self.app.wsgi()
  File "/usr/lib/python2.7/site-packages/gunicorn/app/base.py", line 67, in wsgi
    self.callable = self.load()
  File "/usr/lib/python2.7/site-packages/gunicorn/app/wsgiapp.py", line 52, in load
    return self.load_wsgiapp()
  File "/usr/lib/python2.7/site-packages/gunicorn/app/wsgiapp.py", line 41, in load_wsgiapp
    return util.import_app(self.app_uri)
  File "/usr/lib/python2.7/site-packages/gunicorn/util.py", line 350, in import_app
    __import__(module)
  File "/opt/graphite/webapp/graphite/wsgi.py", line 15, in <module>
    application = get_wsgi_application()
  File "/usr/lib/python2.7/site-packages/django/core/wsgi.py", line 13, in get_wsgi_application
    django.setup(set_prefix=False)
  File "/usr/lib/python2.7/site-packages/django/__init__.py", line 27, in setup
    apps.populate(settings.INSTALLED_APPS)
  File "/usr/lib/python2.7/site-packages/django/apps/registry.py", line 85, in populate
    app_config = AppConfig.create(entry)
  File "/usr/lib/python2.7/site-packages/django/apps/config.py", line 94, in create
    module = import_module(entry)
  File "/usr/lib/python2.7/importlib/__init__.py", line 37, in import_module
    __import__(name)
  File "/opt/graphite/webapp/graphite/functions/__init__.py", line 10, in <module>
    from graphite.logger import log
  File "/opt/graphite/webapp/graphite/logger.py", line 106, in <module>
    log = GraphiteLogger() # import-shared logger instance
  File "/opt/graphite/webapp/graphite/logger.py", line 39, in __init__
    level = logging.DEBUG if settings.DEBUG else logging.INFO,
  File "/opt/graphite/webapp/graphite/logger.py", line 78, in _config_logger
    handler = Rotater(log_file, when=when, backupCount=backupCount)
  File "/usr/lib/python2.7/logging/handlers.py", line 171, in __init__
    BaseRotatingHandler.__init__(self, filename, 'a', encoding, delay)
  File "/usr/lib/python2.7/logging/handlers.py", line 64, in __init__
    logging.FileHandler.__init__(self, filename, mode, encoding, delay)
  File "/usr/lib/python2.7/logging/__init__.py", line 920, in __init__
    StreamHandler.__init__(self, self._open())
  File "/usr/lib/python2.7/logging/__init__.py", line 950, in _open
    stream = open(self.baseFilename, self.mode)
IOError: [Errno 2] No such file or directory: '/opt/graphite/storage/log/webapp/info.log'
[2019-02-07 16:33:24 +0000] [47] [INFO] Worker exiting (pid: 47)
[2019-02-07 16:33:25 +0000] [48] [INFO] Starting gunicorn 19.9.0
[2019-02-07 16:33:25 +0000] [48] [INFO] Listening at: http://127.0.0.1:8000 (48)
[2019-02-07 16:33:25 +0000] [48] [INFO] Using worker: sync
[2019-02-07 16:33:25 +0000] [50] [INFO] Booting worker with pid: 50
[2019-02-07 16:33:25 +0000] [51] [INFO] Booting worker with pid: 51
/opt/graphite/webapp/graphite/local_settings.py:334: UserWarning: SECRET_KEY is set to an unsafe default. This should be set in local_settings.py for better security
[2019-02-07 16:33:25 +0000] [52] [INFO] Booting worker with pid: 52
[2019-02-07 16:33:25 +0000] [50] [ERROR] Exception in worker process
Traceback (most recent call last):
  File "/usr/lib/python2.7/site-packages/gunicorn/arbiter.py", line 583, in spawn_worker
    worker.init_process()
  File "/usr/lib/python2.7/site-packages/gunicorn/workers/base.py", line 129, in init_process
    self.load_wsgi()
  File "/usr/lib/python2.7/site-packages/gunicorn/workers/base.py", line 138, in load_wsgi
    self.wsgi = self.app.wsgi()
  File "/usr/lib/python2.7/site-packages/gunicorn/app/base.py", line 67, in wsgi
    self.callable = self.load()
  File "/usr/lib/python2.7/site-packages/gunicorn/app/wsgiapp.py", line 52, in load
    return self.load_wsgiapp()
  File "/usr/lib/python2.7/site-packages/gunicorn/app/wsgiapp.py", line 41, in load_wsgiapp
    return util.import_app(self.app_uri)
  File "/usr/lib/python2.7/site-packages/gunicorn/util.py", line 350, in import_app
    __import__(module)
  File "/opt/graphite/webapp/graphite/wsgi.py", line 15, in <module>
    application = get_wsgi_application()
  File "/usr/lib/python2.7/site-packages/django/core/wsgi.py", line 13, in get_wsgi_application
    django.setup(set_prefix=False)
  File "/usr/lib/python2.7/site-packages/django/__init__.py", line 27, in setup
    apps.populate(settings.INSTALLED_APPS)
  File "/usr/lib/python2.7/site-packages/django/apps/registry.py", line 85, in populate
    app_config = AppConfig.create(entry)
  File "/usr/lib/python2.7/site-packages/django/apps/config.py", line 94, in create
    module = import_module(entry)
  File "/usr/lib/python2.7/importlib/__init__.py", line 37, in import_module
    __import__(name)
  File "/opt/graphite/webapp/graphite/functions/__init__.py", line 10, in <module>
    from graphite.logger import log
  File "/opt/graphite/webapp/graphite/logger.py", line 106, in <module>
    log = GraphiteLogger() # import-shared logger instance
  File "/opt/graphite/webapp/graphite/logger.py", line 39, in __init__
    level = logging.DEBUG if settings.DEBUG else logging.INFO,
  File "/opt/graphite/webapp/graphite/logger.py", line 78, in _config_logger
    handler = Rotater(log_file, when=when, backupCount=backupCount)
  File "/usr/lib/python2.7/logging/handlers.py", line 171, in __init__
    BaseRotatingHandler.__init__(self, filename, 'a', encoding, delay)
  File "/usr/lib/python2.7/logging/handlers.py", line 64, in __init__
    logging.FileHandler.__init__(self, filename, mode, encoding, delay)
  File "/usr/lib/python2.7/logging/__init__.py", line 920, in __init__
    StreamHandler.__init__(self, self._open())
  File "/usr/lib/python2.7/logging/__init__.py", line 950, in _open
    stream = open(self.baseFilename, self.mode)
IOError: [Errno 2] No such file or directory: '/opt/graphite/storage/log/webapp/info.log'
[2019-02-07 16:33:25 +0000] [50] [INFO] Worker exiting (pid: 50)
[2019-02-07 16:33:25 +0000] [53] [INFO] Booting worker with pid: 53
/opt/graphite/webapp/graphite/local_settings.py:334: UserWarning: SECRET_KEY is set to an unsafe default. This should be set in local_settings.py for better security
/opt/graphite/webapp/graphite/local_settings.py:334: UserWarning: SECRET_KEY is set to an unsafe default. This should be set in local_settings.py for better security
[2019-02-07 16:33:25 +0000] [53] [ERROR] Exception in worker process
Traceback (most recent call last):
  File "/usr/lib/python2.7/site-packages/gunicorn/arbiter.py", line 583, in spawn_worker
    worker.init_process()
  File "/usr/lib/python2.7/site-packages/gunicorn/workers/base.py", line 129, in init_process
    self.load_wsgi()
  File "/usr/lib/python2.7/site-packages/gunicorn/workers/base.py", line 138, in load_wsgi
    self.wsgi = self.app.wsgi()
  File "/usr/lib/python2.7/site-packages/gunicorn/app/base.py", line 67, in wsgi
    self.callable = self.load()
  File "/usr/lib/python2.7/site-packages/gunicorn/app/wsgiapp.py", line 52, in load
    return self.load_wsgiapp()
  File "/usr/lib/python2.7/site-packages/gunicorn/app/wsgiapp.py", line 41, in load_wsgiapp
    return util.import_app(self.app_uri)
  File "/usr/lib/python2.7/site-packages/gunicorn/util.py", line 350, in import_app
    __import__(module)
  File "/opt/graphite/webapp/graphite/wsgi.py", line 15, in <module>
    application = get_wsgi_application()
  File "/usr/lib/python2.7/site-packages/django/core/wsgi.py", line 13, in get_wsgi_application
    django.setup(set_prefix=False)
  File "/usr/lib/python2.7/site-packages/django/__init__.py", line 27, in setup
    apps.populate(settings.INSTALLED_APPS)
  File "/usr/lib/python2.7/site-packages/django/apps/registry.py", line 85, in populate
    app_config = AppConfig.create(entry)
  File "/usr/lib/python2.7/site-packages/django/apps/config.py", line 94, in create
    module = import_module(entry)
  File "/usr/lib/python2.7/importlib/__init__.py", line 37, in import_module
    __import__(name)
  File "/opt/graphite/webapp/graphite/functions/__init__.py", line 10, in <module>
    from graphite.logger import log
  File "/opt/graphite/webapp/graphite/logger.py", line 106, in <module>
    log = GraphiteLogger() # import-shared logger instance
  File "/opt/graphite/webapp/graphite/logger.py", line 39, in __init__
    level = logging.DEBUG if settings.DEBUG else logging.INFO,
  File "/opt/graphite/webapp/graphite/logger.py", line 78, in _config_logger
    handler = Rotater(log_file, when=when, backupCount=backupCount)
  File "/usr/lib/python2.7/logging/handlers.py", line 171, in __init__
    BaseRotatingHandler.__init__(self, filename, 'a', encoding, delay)
  File "/usr/lib/python2.7/logging/handlers.py", line 64, in __init__
    logging.FileHandler.__init__(self, filename, mode, encoding, delay)
  File "/usr/lib/python2.7/logging/__init__.py", line 920, in __init__
    StreamHandler.__init__(self, self._open())
  File "/usr/lib/python2.7/logging/__init__.py", line 950, in _open
    stream = open(self.baseFilename, self.mode)
IOError: [Errno 2] No such file or directory: '/opt/graphite/storage/log/webapp/info.log'
[2019-02-07 16:33:25 +0000] [53] [INFO] Worker exiting (pid: 53)
[2019-02-07 16:33:25 +0000] [51] [ERROR] Exception in worker process
Traceback (most recent call last):
  File "/usr/lib/python2.7/site-packages/gunicorn/arbiter.py", line 583, in spawn_worker
    worker.init_process()
  File "/usr/lib/python2.7/site-packages/gunicorn/workers/base.py", line 129, in init_process
    self.load_wsgi()
  File "/usr/lib/python2.7/site-packages/gunicorn/workers/base.py", line 138, in load_wsgi
    self.wsgi = self.app.wsgi()
  File "/usr/lib/python2.7/site-packages/gunicorn/app/base.py", line 67, in wsgi
    self.callable = self.load()
  File "/usr/lib/python2.7/site-packages/gunicorn/app/wsgiapp.py", line 52, in load
    return self.load_wsgiapp()
  File "/usr/lib/python2.7/site-packages/gunicorn/app/wsgiapp.py", line 41, in load_wsgiapp
    return util.import_app(self.app_uri)
  File "/usr/lib/python2.7/site-packages/gunicorn/util.py", line 350, in import_app
    __import__(module)
  File "/opt/graphite/webapp/graphite/wsgi.py", line 15, in <module>
    application = get_wsgi_application()
  File "/usr/lib/python2.7/site-packages/django/core/wsgi.py", line 13, in get_wsgi_application
    django.setup(set_prefix=False)
  File "/usr/lib/python2.7/site-packages/django/__init__.py", line 27, in setup
    apps.populate(settings.INSTALLED_APPS)
  File "/usr/lib/python2.7/site-packages/django/apps/registry.py", line 85, in populate
    app_config = AppConfig.create(entry)
  File "/usr/lib/python2.7/site-packages/django/apps/config.py", line 94, in create
    module = import_module(entry)
  File "/usr/lib/python2.7/importlib/__init__.py", line 37, in import_module
    __import__(name)
  File "/opt/graphite/webapp/graphite/functions/__init__.py", line 10, in <module>
    from graphite.logger import log
  File "/opt/graphite/webapp/graphite/logger.py", line 106, in <module>
    log = GraphiteLogger() # import-shared logger instance
  File "/opt/graphite/webapp/graphite/logger.py", line 39, in __init__
    level = logging.DEBUG if settings.DEBUG else logging.INFO,
  File "/opt/graphite/webapp/graphite/logger.py", line 78, in _config_logger
    handler = Rotater(log_file, when=when, backupCount=backupCount)
  File "/usr/lib/python2.7/logging/handlers.py", line 171, in __init__
    BaseRotatingHandler.__init__(self, filename, 'a', encoding, delay)
  File "/usr/lib/python2.7/logging/handlers.py", line 64, in __init__
    logging.FileHandler.__init__(self, filename, mode, encoding, delay)
  File "/usr/lib/python2.7/logging/__init__.py", line 920, in __init__
    StreamHandler.__init__(self, self._open())
  File "/usr/lib/python2.7/logging/__init__.py", line 950, in _open
    stream = open(self.baseFilename, self.mode)
IOError: [Errno 2] No such file or directory: '/opt/graphite/storage/log/webapp/info.log'
[2019-02-07 16:33:25 +0000] [51] [INFO] Worker exiting (pid: 51)
Traceback (most recent call last):
  File "/usr/bin/gunicorn", line 11, in <module>
    sys.exit(run())
  File "/usr/lib/python2.7/site-packages/gunicorn/app/wsgiapp.py", line 61, in run
    WSGIApplication("%(prog)s [OPTIONS] [APP_MODULE]").run()
  File "/usr/lib/python2.7/site-packages/gunicorn/app/base.py", line 223, in run
    super(Application, self).run()
  File "/usr/lib/python2.7/site-packages/gunicorn/app/base.py", line 72, in run
    Arbiter(self).run()
  File "/usr/lib/python2.7/site-packages/gunicorn/arbiter.py", line 232, in run
    self.halt(reason=inst.reason, exit_status=inst.exit_status)
  File "/usr/lib/python2.7/site-packages/gunicorn/arbiter.py", line 345, in halt
    self.stop()
  File "/usr/lib/python2.7/site-packages/gunicorn/arbiter.py", line 393, in stop
    time.sleep(0.1)
  File "/usr/lib/python2.7/site-packages/gunicorn/arbiter.py", line 245, in handle_chld
    self.reap_workers()
  File "/usr/lib/python2.7/site-packages/gunicorn/arbiter.py", line 525, in reap_workers
    raise HaltServer(reason, self.WORKER_BOOT_ERROR)
gunicorn.errors.HaltServer: <HaltServer 'Worker failed to boot.' 3>
[2019-02-07 16:33:28 +0000] [54] [INFO] Starting gunicorn 19.9.0
[2019-02-07 16:33:28 +0000] [54] [INFO] Listening at: http://127.0.0.1:8000 (54)
[2019-02-07 16:33:28 +0000] [54] [INFO] Using worker: sync
[2019-02-07 16:33:28 +0000] [56] [INFO] Booting worker with pid: 56
[2019-02-07 16:33:28 +0000] [57] [INFO] Booting worker with pid: 57
[2019-02-07 16:33:28 +0000] [58] [INFO] Booting worker with pid: 58
[2019-02-07 16:33:28 +0000] [59] [INFO] Booting worker with pid: 59
/opt/graphite/webapp/graphite/local_settings.py:334: UserWarning: SECRET_KEY is set to an unsafe default. This should be set in local_settings.py for better security
[2019-02-07 16:33:28 +0000] [56] [ERROR] Exception in worker process
Traceback (most recent call last):
  File "/usr/lib/python2.7/site-packages/gunicorn/arbiter.py", line 583, in spawn_worker
    worker.init_process()
  File "/usr/lib/python2.7/site-packages/gunicorn/workers/base.py", line 129, in init_process
    self.load_wsgi()
  File "/usr/lib/python2.7/site-packages/gunicorn/workers/base.py", line 138, in load_wsgi
    self.wsgi = self.app.wsgi()
  File "/usr/lib/python2.7/site-packages/gunicorn/app/base.py", line 67, in wsgi
    self.callable = self.load()
  File "/usr/lib/python2.7/site-packages/gunicorn/app/wsgiapp.py", line 52, in load
    return self.load_wsgiapp()
  File "/usr/lib/python2.7/site-packages/gunicorn/app/wsgiapp.py", line 41, in load_wsgiapp
    return util.import_app(self.app_uri)
  File "/usr/lib/python2.7/site-packages/gunicorn/util.py", line 350, in import_app
    __import__(module)
  File "/opt/graphite/webapp/graphite/wsgi.py", line 15, in <module>
    application = get_wsgi_application()
  File "/usr/lib/python2.7/site-packages/django/core/wsgi.py", line 13, in get_wsgi_application
    django.setup(set_prefix=False)
  File "/usr/lib/python2.7/site-packages/django/__init__.py", line 27, in setup
    apps.populate(settings.INSTALLED_APPS)
  File "/usr/lib/python2.7/site-packages/django/apps/registry.py", line 85, in populate
    app_config = AppConfig.create(entry)
  File "/usr/lib/python2.7/site-packages/django/apps/config.py", line 94, in create
    module = import_module(entry)
  File "/usr/lib/python2.7/importlib/__init__.py", line 37, in import_module
    __import__(name)
  File "/opt/graphite/webapp/graphite/functions/__init__.py", line 10, in <module>
    from graphite.logger import log
  File "/opt/graphite/webapp/graphite/logger.py", line 106, in <module>
    log = GraphiteLogger() # import-shared logger instance
  File "/opt/graphite/webapp/graphite/logger.py", line 39, in __init__
    level = logging.DEBUG if settings.DEBUG else logging.INFO,
  File "/opt/graphite/webapp/graphite/logger.py", line 78, in _config_logger
    handler = Rotater(log_file, when=when, backupCount=backupCount)
  File "/usr/lib/python2.7/logging/handlers.py", line 171, in __init__
    BaseRotatingHandler.__init__(self, filename, 'a', encoding, delay)
  File "/usr/lib/python2.7/logging/handlers.py", line 64, in __init__
    logging.FileHandler.__init__(self, filename, mode, encoding, delay)
  File "/usr/lib/python2.7/logging/__init__.py", line 920, in __init__
    StreamHandler.__init__(self, self._open())
  File "/usr/lib/python2.7/logging/__init__.py", line 950, in _open
    stream = open(self.baseFilename, self.mode)
IOError: [Errno 2] No such file or directory: '/opt/graphite/storage/log/webapp/info.log'
[2019-02-07 16:33:28 +0000] [56] [INFO] Worker exiting (pid: 56)
/opt/graphite/webapp/graphite/local_settings.py:334: UserWarning: SECRET_KEY is set to an unsafe default. This should be set in local_settings.py for better security
[2019-02-07 16:33:28 +0000] [58] [ERROR] Exception in worker process
Traceback (most recent call last):
  File "/usr/lib/python2.7/site-packages/gunicorn/arbiter.py", line 583, in spawn_worker
    worker.init_process()
  File "/usr/lib/python2.7/site-packages/gunicorn/workers/base.py", line 129, in init_process
    self.load_wsgi()
  File "/usr/lib/python2.7/site-packages/gunicorn/workers/base.py", line 138, in load_wsgi
    self.wsgi = self.app.wsgi()
  File "/usr/lib/python2.7/site-packages/gunicorn/app/base.py", line 67, in wsgi
    self.callable = self.load()
  File "/usr/lib/python2.7/site-packages/gunicorn/app/wsgiapp.py", line 52, in load
    return self.load_wsgiapp()
  File "/usr/lib/python2.7/site-packages/gunicorn/app/wsgiapp.py", line 41, in load_wsgiapp
    return util.import_app(self.app_uri)
  File "/usr/lib/python2.7/site-packages/gunicorn/util.py", line 350, in import_app
    __import__(module)
  File "/opt/graphite/webapp/graphite/wsgi.py", line 15, in <module>
    application = get_wsgi_application()
  File "/usr/lib/python2.7/site-packages/django/core/wsgi.py", line 13, in get_wsgi_application
    django.setup(set_prefix=False)
  File "/usr/lib/python2.7/site-packages/django/__init__.py", line 27, in setup
    apps.populate(settings.INSTALLED_APPS)
  File "/usr/lib/python2.7/site-packages/django/apps/registry.py", line 85, in populate
    app_config = AppConfig.create(entry)
  File "/usr/lib/python2.7/site-packages/django/apps/config.py", line 94, in create
    module = import_module(entry)
  File "/usr/lib/python2.7/importlib/__init__.py", line 37, in import_module
    __import__(name)
  File "/opt/graphite/webapp/graphite/functions/__init__.py", line 10, in <module>
    from graphite.logger import log
  File "/opt/graphite/webapp/graphite/logger.py", line 106, in <module>
    log = GraphiteLogger() # import-shared logger instance
  File "/opt/graphite/webapp/graphite/logger.py", line 39, in __init__
    level = logging.DEBUG if settings.DEBUG else logging.INFO,
  File "/opt/graphite/webapp/graphite/logger.py", line 78, in _config_logger
    handler = Rotater(log_file, when=when, backupCount=backupCount)
  File "/usr/lib/python2.7/logging/handlers.py", line 171, in __init__
    BaseRotatingHandler.__init__(self, filename, 'a', encoding, delay)
  File "/usr/lib/python2.7/logging/handlers.py", line 64, in __init__
    logging.FileHandler.__init__(self, filename, mode, encoding, delay)
  File "/usr/lib/python2.7/logging/__init__.py", line 920, in __init__
    StreamHandler.__init__(self, self._open())
  File "/usr/lib/python2.7/logging/__init__.py", line 950, in _open
    stream = open(self.baseFilename, self.mode)
IOError: [Errno 2] No such file or directory: '/opt/graphite/storage/log/webapp/info.log'
[2019-02-07 16:33:28 +0000] [58] [INFO] Worker exiting (pid: 58)
/opt/graphite/webapp/graphite/local_settings.py:334: UserWarning: SECRET_KEY is set to an unsafe default. This should be set in local_settings.py for better security
[2019-02-07 16:33:28 +0000] [57] [ERROR] Exception in worker process
Traceback (most recent call last):
  File "/usr/lib/python2.7/site-packages/gunicorn/arbiter.py", line 583, in spawn_worker
    worker.init_process()
  File "/usr/lib/python2.7/site-packages/gunicorn/workers/base.py", line 129, in init_process
    self.load_wsgi()
  File "/usr/lib/python2.7/site-packages/gunicorn/workers/base.py", line 138, in load_wsgi
    self.wsgi = self.app.wsgi()
  File "/usr/lib/python2.7/site-packages/gunicorn/app/base.py", line 67, in wsgi
    self.callable = self.load()
  File "/usr/lib/python2.7/site-packages/gunicorn/app/wsgiapp.py", line 52, in load
    return self.load_wsgiapp()
  File "/usr/lib/python2.7/site-packages/gunicorn/app/wsgiapp.py", line 41, in load_wsgiapp
    return util.import_app(self.app_uri)
  File "/usr/lib/python2.7/site-packages/gunicorn/util.py", line 350, in import_app
    __import__(module)
  File "/opt/graphite/webapp/graphite/wsgi.py", line 15, in <module>
    application = get_wsgi_application()
  File "/usr/lib/python2.7/site-packages/django/core/wsgi.py", line 13, in get_wsgi_application
    django.setup(set_prefix=False)
  File "/usr/lib/python2.7/site-packages/django/__init__.py", line 27, in setup
    apps.populate(settings.INSTALLED_APPS)
  File "/usr/lib/python2.7/site-packages/django/apps/registry.py", line 85, in populate
    app_config = AppConfig.create(entry)
  File "/usr/lib/python2.7/site-packages/django/apps/config.py", line 94, in create
    module = import_module(entry)
  File "/usr/lib/python2.7/importlib/__init__.py", line 37, in import_module
    __import__(name)
  File "/opt/graphite/webapp/graphite/functions/__init__.py", line 10, in <module>
    from graphite.logger import log
  File "/opt/graphite/webapp/graphite/logger.py", line 106, in <module>
    log = GraphiteLogger() # import-shared logger instance
  File "/opt/graphite/webapp/graphite/logger.py", line 39, in __init__
    level = logging.DEBUG if settings.DEBUG else logging.INFO,
  File "/opt/graphite/webapp/graphite/logger.py", line 78, in _config_logger
    handler = Rotater(log_file, when=when, backupCount=backupCount)
  File "/usr/lib/python2.7/logging/handlers.py", line 171, in __init__
    BaseRotatingHandler.__init__(self, filename, 'a', encoding, delay)
  File "/usr/lib/python2.7/logging/handlers.py", line 64, in __init__
    logging.FileHandler.__init__(self, filename, mode, encoding, delay)
  File "/usr/lib/python2.7/logging/__init__.py", line 920, in __init__
    StreamHandler.__init__(self, self._open())
  File "/usr/lib/python2.7/logging/__init__.py", line 950, in _open
    stream = open(self.baseFilename, self.mode)
IOError: [Errno 2] No such file or directory: '/opt/graphite/storage/log/webapp/info.log'
[2019-02-07 16:33:28 +0000] [57] [INFO] Worker exiting (pid: 57)
/opt/graphite/webapp/graphite/local_settings.py:334: UserWarning: SECRET_KEY is set to an unsafe default. This should be set in local_settings.py for better security
[2019-02-07 16:33:28 +0000] [59] [ERROR] Exception in worker process
Traceback (most recent call last):
  File "/usr/lib/python2.7/site-packages/gunicorn/arbiter.py", line 583, in spawn_worker
    worker.init_process()
  File "/usr/lib/python2.7/site-packages/gunicorn/workers/base.py", line 129, in init_process
    self.load_wsgi()
  File "/usr/lib/python2.7/site-packages/gunicorn/workers/base.py", line 138, in load_wsgi
    self.wsgi = self.app.wsgi()
  File "/usr/lib/python2.7/site-packages/gunicorn/app/base.py", line 67, in wsgi
    self.callable = self.load()
  File "/usr/lib/python2.7/site-packages/gunicorn/app/wsgiapp.py", line 52, in load
    return self.load_wsgiapp()
  File "/usr/lib/python2.7/site-packages/gunicorn/app/wsgiapp.py", line 41, in load_wsgiapp
    return util.import_app(self.app_uri)
  File "/usr/lib/python2.7/site-packages/gunicorn/util.py", line 350, in import_app
    __import__(module)
  File "/opt/graphite/webapp/graphite/wsgi.py", line 15, in <module>
    application = get_wsgi_application()
  File "/usr/lib/python2.7/site-packages/django/core/wsgi.py", line 13, in get_wsgi_application
    django.setup(set_prefix=False)
  File "/usr/lib/python2.7/site-packages/django/__init__.py", line 27, in setup
    apps.populate(settings.INSTALLED_APPS)
  File "/usr/lib/python2.7/site-packages/django/apps/registry.py", line 85, in populate
    app_config = AppConfig.create(entry)
  File "/usr/lib/python2.7/site-packages/django/apps/config.py", line 94, in create
    module = import_module(entry)
  File "/usr/lib/python2.7/importlib/__init__.py", line 37, in import_module
    __import__(name)
  File "/opt/graphite/webapp/graphite/functions/__init__.py", line 10, in <module>
    from graphite.logger import log
  File "/opt/graphite/webapp/graphite/logger.py", line 106, in <module>
    log = GraphiteLogger() # import-shared logger instance
  File "/opt/graphite/webapp/graphite/logger.py", line 39, in __init__
    level = logging.DEBUG if settings.DEBUG else logging.INFO,
  File "/opt/graphite/webapp/graphite/logger.py", line 78, in _config_logger
    handler = Rotater(log_file, when=when, backupCount=backupCount)
  File "/usr/lib/python2.7/logging/handlers.py", line 171, in __init__
    BaseRotatingHandler.__init__(self, filename, 'a', encoding, delay)
  File "/usr/lib/python2.7/logging/handlers.py", line 64, in __init__
    logging.FileHandler.__init__(self, filename, mode, encoding, delay)
  File "/usr/lib/python2.7/logging/__init__.py", line 920, in __init__
    StreamHandler.__init__(self, self._open())
  File "/usr/lib/python2.7/logging/__init__.py", line 950, in _open
    stream = open(self.baseFilename, self.mode)
IOError: [Errno 2] No such file or directory: '/opt/graphite/storage/log/webapp/info.log'
[2019-02-07 16:33:28 +0000] [59] [INFO] Worker exiting (pid: 59)
Traceback (most recent call last):
  File "/usr/bin/gunicorn", line 11, in <module>
    sys.exit(run())
  File "/usr/lib/python2.7/site-packages/gunicorn/app/wsgiapp.py", line 61, in run
    WSGIApplication("%(prog)s [OPTIONS] [APP_MODULE]").run()
  File "/usr/lib/python2.7/site-packages/gunicorn/app/base.py", line 223, in run
    super(Application, self).run()
  File "/usr/lib/python2.7/site-packages/gunicorn/app/base.py", line 72, in run
    Arbiter(self).run()
  File "/usr/lib/python2.7/site-packages/gunicorn/arbiter.py", line 232, in run
    self.halt(reason=inst.reason, exit_status=inst.exit_status)
  File "/usr/lib/python2.7/site-packages/gunicorn/arbiter.py", line 345, in halt
    self.stop()
  File "/usr/lib/python2.7/site-packages/gunicorn/arbiter.py", line 393, in stop
    time.sleep(0.1)
  File "/usr/lib/python2.7/site-packages/gunicorn/arbiter.py", line 245, in handle_chld
    self.reap_workers()
  File "/usr/lib/python2.7/site-packages/gunicorn/arbiter.py", line 525, in reap_workers
    raise HaltServer(reason, self.WORKER_BOOT_ERROR)
gunicorn.errors.HaltServer: <HaltServer 'Worker failed to boot.' 3>
[2019-02-07 16:33:33 +0000] [159] [INFO] Starting gunicorn 19.9.0
[2019-02-07 16:33:33 +0000] [159] [INFO] Listening at: http://127.0.0.1:8000 (159)
[2019-02-07 16:33:33 +0000] [159] [INFO] Using worker: sync
[2019-02-07 16:33:33 +0000] [166] [INFO] Booting worker with pid: 166
[2019-02-07 16:33:33 +0000] [167] [INFO] Booting worker with pid: 167
[2019-02-07 16:33:33 +0000] [168] [INFO] Booting worker with pid: 168
/opt/graphite/webapp/graphite/local_settings.py:334: UserWarning: SECRET_KEY is set to an unsafe default. This should be set in local_settings.py for better security
[2019-02-07 16:33:33 +0000] [166] [ERROR] Exception in worker process
Traceback (most recent call last):
  File "/usr/lib/python2.7/site-packages/gunicorn/arbiter.py", line 583, in spawn_worker
    worker.init_process()
  File "/usr/lib/python2.7/site-packages/gunicorn/workers/base.py", line 129, in init_process
    self.load_wsgi()
  File "/usr/lib/python2.7/site-packages/gunicorn/workers/base.py", line 138, in load_wsgi
    self.wsgi = self.app.wsgi()
  File "/usr/lib/python2.7/site-packages/gunicorn/app/base.py", line 67, in wsgi
    self.callable = self.load()
  File "/usr/lib/python2.7/site-packages/gunicorn/app/wsgiapp.py", line 52, in load
    return self.load_wsgiapp()
  File "/usr/lib/python2.7/site-packages/gunicorn/app/wsgiapp.py", line 41, in load_wsgiapp
    return util.import_app(self.app_uri)
  File "/usr/lib/python2.7/site-packages/gunicorn/util.py", line 350, in import_app
    __import__(module)
  File "/opt/graphite/webapp/graphite/wsgi.py", line 15, in <module>
    application = get_wsgi_application()
  File "/usr/lib/python2.7/site-packages/django/core/wsgi.py", line 13, in get_wsgi_application
    django.setup(set_prefix=False)
  File "/usr/lib/python2.7/site-packages/django/__init__.py", line 27, in setup
    apps.populate(settings.INSTALLED_APPS)
  File "/usr/lib/python2.7/site-packages/django/apps/registry.py", line 85, in populate
    app_config = AppConfig.create(entry)
  File "/usr/lib/python2.7/site-packages/django/apps/config.py", line 94, in create
    module = import_module(entry)
  File "/usr/lib/python2.7/importlib/__init__.py", line 37, in import_module
    __import__(name)
  File "/opt/graphite/webapp/graphite/functions/__init__.py", line 10, in <module>
    from graphite.logger import log
  File "/opt/graphite/webapp/graphite/logger.py", line 106, in <module>
    log = GraphiteLogger() # import-shared logger instance
  File "/opt/graphite/webapp/graphite/logger.py", line 39, in __init__
    level = logging.DEBUG if settings.DEBUG else logging.INFO,
  File "/opt/graphite/webapp/graphite/logger.py", line 78, in _config_logger
    handler = Rotater(log_file, when=when, backupCount=backupCount)
  File "/usr/lib/python2.7/logging/handlers.py", line 171, in __init__
    BaseRotatingHandler.__init__(self, filename, 'a', encoding, delay)
  File "/usr/lib/python2.7/logging/handlers.py", line 64, in __init__
    logging.FileHandler.__init__(self, filename, mode, encoding, delay)
  File "/usr/lib/python2.7/logging/__init__.py", line 920, in __init__
    StreamHandler.__init__(self, self._open())
  File "/usr/lib/python2.7/logging/__init__.py", line 950, in _open
    stream = open(self.baseFilename, self.mode)
IOError: [Errno 2] No such file or directory: '/opt/graphite/storage/log/webapp/info.log'
[2019-02-07 16:33:33 +0000] [166] [INFO] Worker exiting (pid: 166)
[2019-02-07 16:33:33 +0000] [169] [INFO] Booting worker with pid: 169
/opt/graphite/webapp/graphite/local_settings.py:334: UserWarning: SECRET_KEY is set to an unsafe default. This should be set in local_settings.py for better security
[2019-02-07 16:33:33 +0000] [169] [ERROR] Exception in worker process
Traceback (most recent call last):
  File "/usr/lib/python2.7/site-packages/gunicorn/arbiter.py", line 583, in spawn_worker
    worker.init_process()
  File "/usr/lib/python2.7/site-packages/gunicorn/workers/base.py", line 129, in init_process
    self.load_wsgi()
  File "/usr/lib/python2.7/site-packages/gunicorn/workers/base.py", line 138, in load_wsgi
    self.wsgi = self.app.wsgi()
  File "/usr/lib/python2.7/site-packages/gunicorn/app/base.py", line 67, in wsgi
    self.callable = self.load()
  File "/usr/lib/python2.7/site-packages/gunicorn/app/wsgiapp.py", line 52, in load
    return self.load_wsgiapp()
  File "/usr/lib/python2.7/site-packages/gunicorn/app/wsgiapp.py", line 41, in load_wsgiapp
    return util.import_app(self.app_uri)
  File "/usr/lib/python2.7/site-packages/gunicorn/util.py", line 350, in import_app
    __import__(module)
  File "/opt/graphite/webapp/graphite/wsgi.py", line 15, in <module>
    application = get_wsgi_application()
  File "/usr/lib/python2.7/site-packages/django/core/wsgi.py", line 13, in get_wsgi_application
    django.setup(set_prefix=False)
  File "/usr/lib/python2.7/site-packages/django/__init__.py", line 27, in setup
    apps.populate(settings.INSTALLED_APPS)
  File "/usr/lib/python2.7/site-packages/django/apps/registry.py", line 85, in populate
    app_config = AppConfig.create(entry)
  File "/usr/lib/python2.7/site-packages/django/apps/config.py", line 94, in create
    module = import_module(entry)
  File "/usr/lib/python2.7/importlib/__init__.py", line 37, in import_module
    __import__(name)
  File "/opt/graphite/webapp/graphite/functions/__init__.py", line 10, in <module>
    from graphite.logger import log
  File "/opt/graphite/webapp/graphite/logger.py", line 106, in <module>
    log = GraphiteLogger() # import-shared logger instance
  File "/opt/graphite/webapp/graphite/logger.py", line 39, in __init__
    level = logging.DEBUG if settings.DEBUG else logging.INFO,
  File "/opt/graphite/webapp/graphite/logger.py", line 78, in _config_logger
    handler = Rotater(log_file, when=when, backupCount=backupCount)
  File "/usr/lib/python2.7/logging/handlers.py", line 171, in __init__
    BaseRotatingHandler.__init__(self, filename, 'a', encoding, delay)
  File "/usr/lib/python2.7/logging/handlers.py", line 64, in __init__
    logging.FileHandler.__init__(self, filename, mode, encoding, delay)
  File "/usr/lib/python2.7/logging/__init__.py", line 920, in __init__
    StreamHandler.__init__(self, self._open())
  File "/usr/lib/python2.7/logging/__init__.py", line 950, in _open
    stream = open(self.baseFilename, self.mode)
IOError: [Errno 2] No such file or directory: '/opt/graphite/storage/log/webapp/info.log'
[2019-02-07 16:33:33 +0000] [169] [INFO] Worker exiting (pid: 169)
/opt/graphite/webapp/graphite/local_settings.py:334: UserWarning: SECRET_KEY is set to an unsafe default. This should be set in local_settings.py for better security
[2019-02-07 16:33:33 +0000] [167] [ERROR] Exception in worker process
Traceback (most recent call last):
  File "/usr/lib/python2.7/site-packages/gunicorn/arbiter.py", line 583, in spawn_worker
    worker.init_process()
  File "/usr/lib/python2.7/site-packages/gunicorn/workers/base.py", line 129, in init_process
    self.load_wsgi()
  File "/usr/lib/python2.7/site-packages/gunicorn/workers/base.py", line 138, in load_wsgi
    self.wsgi = self.app.wsgi()
  File "/usr/lib/python2.7/site-packages/gunicorn/app/base.py", line 67, in wsgi
    self.callable = self.load()
  File "/usr/lib/python2.7/site-packages/gunicorn/app/wsgiapp.py", line 52, in load
    return self.load_wsgiapp()
  File "/usr/lib/python2.7/site-packages/gunicorn/app/wsgiapp.py", line 41, in load_wsgiapp
    return util.import_app(self.app_uri)
  File "/usr/lib/python2.7/site-packages/gunicorn/util.py", line 350, in import_app
    __import__(module)
  File "/opt/graphite/webapp/graphite/wsgi.py", line 15, in <module>
    application = get_wsgi_application()
  File "/usr/lib/python2.7/site-packages/django/core/wsgi.py", line 13, in get_wsgi_application
    django.setup(set_prefix=False)
  File "/usr/lib/python2.7/site-packages/django/__init__.py", line 27, in setup
    apps.populate(settings.INSTALLED_APPS)
  File "/usr/lib/python2.7/site-packages/django/apps/registry.py", line 85, in populate
    app_config = AppConfig.create(entry)
  File "/usr/lib/python2.7/site-packages/django/apps/config.py", line 94, in create
    module = import_module(entry)
  File "/usr/lib/python2.7/importlib/__init__.py", line 37, in import_module
    __import__(name)
  File "/opt/graphite/webapp/graphite/functions/__init__.py", line 10, in <module>
    from graphite.logger import log
  File "/opt/graphite/webapp/graphite/logger.py", line 106, in <module>
    log = GraphiteLogger() # import-shared logger instance
  File "/opt/graphite/webapp/graphite/logger.py", line 39, in __init__
    level = logging.DEBUG if settings.DEBUG else logging.INFO,
  File "/opt/graphite/webapp/graphite/logger.py", line 78, in _config_logger
    handler = Rotater(log_file, when=when, backupCount=backupCount)
  File "/usr/lib/python2.7/logging/handlers.py", line 171, in __init__
    BaseRotatingHandler.__init__(self, filename, 'a', encoding, delay)
  File "/usr/lib/python2.7/logging/handlers.py", line 64, in __init__
    logging.FileHandler.__init__(self, filename, mode, encoding, delay)
  File "/usr/lib/python2.7/logging/__init__.py", line 920, in __init__
    StreamHandler.__init__(self, self._open())
  File "/usr/lib/python2.7/logging/__init__.py", line 950, in _open
    stream = open(self.baseFilename, self.mode)
IOError: [Errno 2] No such file or directory: '/opt/graphite/storage/log/webapp/info.log'
[2019-02-07 16:33:33 +0000] [167] [INFO] Worker exiting (pid: 167)
Traceback (most recent call last):
  File "/usr/bin/gunicorn", line 11, in <module>
    sys.exit(run())
  File "/usr/lib/python2.7/site-packages/gunicorn/app/wsgiapp.py", line 61, in run
    WSGIApplication("%(prog)s [OPTIONS] [APP_MODULE]").run()
  File "/usr/lib/python2.7/site-packages/gunicorn/app/base.py", line 223, in run
    super(Application, self).run()
  File "/usr/lib/python2.7/site-packages/gunicorn/app/base.py", line 72, in run
    Arbiter(self).run()
  File "/usr/lib/python2.7/site-packages/gunicorn/arbiter.py", line 232, in run
    self.halt(reason=inst.reason, exit_status=inst.exit_status)
  File "/usr/lib/python2.7/site-packages/gunicorn/arbiter.py", line 345, in halt
    self.stop()
  File "/usr/lib/python2.7/site-packages/gunicorn/arbiter.py", line 393, in stop
    time.sleep(0.1)
  File "/usr/lib/python2.7/site-packages/gunicorn/arbiter.py", line 245, in handle_chld
    self.reap_workers()
  File "/usr/lib/python2.7/site-packages/gunicorn/arbiter.py", line 525, in reap_workers
    raise HaltServer(reason, self.WORKER_BOOT_ERROR)
gunicorn.errors.HaltServer: <HaltServer 'Worker failed to boot.' 3>
/opt/graphite/webapp/graphite/local_settings.py:334: UserWarning: SECRET_KEY is set to an unsafe default. This should be set in local_settings.py for better security
[2019-02-07 16:33:34 +0000] [170] [INFO] Starting gunicorn 19.9.0
[2019-02-07 16:33:34 +0000] [170] [INFO] Listening at: http://127.0.0.1:8000 (170)
[2019-02-07 16:33:34 +0000] [170] [INFO] Using worker: sync
[2019-02-07 16:33:34 +0000] [176] [INFO] Booting worker with pid: 176
[2019-02-07 16:33:34 +0000] [177] [INFO] Booting worker with pid: 177
[2019-02-07 16:33:34 +0000] [178] [INFO] Booting worker with pid: 178
[2019-02-07 16:33:34 +0000] [179] [INFO] Booting worker with pid: 179
/opt/graphite/webapp/graphite/local_settings.py:334: UserWarning: SECRET_KEY is set to an unsafe default. This should be set in local_settings.py for better security
[2019-02-07 16:33:34 +0000] [179] [ERROR] Exception in worker process
Traceback (most recent call last):
  File "/usr/lib/python2.7/site-packages/gunicorn/arbiter.py", line 583, in spawn_worker
    worker.init_process()
  File "/usr/lib/python2.7/site-packages/gunicorn/workers/base.py", line 129, in init_process
    self.load_wsgi()
  File "/usr/lib/python2.7/site-packages/gunicorn/workers/base.py", line 138, in load_wsgi
    self.wsgi = self.app.wsgi()
  File "/usr/lib/python2.7/site-packages/gunicorn/app/base.py", line 67, in wsgi
    self.callable = self.load()
  File "/usr/lib/python2.7/site-packages/gunicorn/app/wsgiapp.py", line 52, in load
    return self.load_wsgiapp()
  File "/usr/lib/python2.7/site-packages/gunicorn/app/wsgiapp.py", line 41, in load_wsgiapp
    return util.import_app(self.app_uri)
  File "/usr/lib/python2.7/site-packages/gunicorn/util.py", line 350, in import_app
    __import__(module)
  File "/opt/graphite/webapp/graphite/wsgi.py", line 15, in <module>
    application = get_wsgi_application()
  File "/usr/lib/python2.7/site-packages/django/core/wsgi.py", line 13, in get_wsgi_application
    django.setup(set_prefix=False)
  File "/usr/lib/python2.7/site-packages/django/__init__.py", line 27, in setup
    apps.populate(settings.INSTALLED_APPS)
  File "/usr/lib/python2.7/site-packages/django/apps/registry.py", line 85, in populate
    app_config = AppConfig.create(entry)
  File "/usr/lib/python2.7/site-packages/django/apps/config.py", line 94, in create
    module = import_module(entry)
  File "/usr/lib/python2.7/importlib/__init__.py", line 37, in import_module
    __import__(name)
  File "/opt/graphite/webapp/graphite/functions/__init__.py", line 10, in <module>
    from graphite.logger import log
  File "/opt/graphite/webapp/graphite/logger.py", line 106, in <module>
    log = GraphiteLogger() # import-shared logger instance
  File "/opt/graphite/webapp/graphite/logger.py", line 39, in __init__
    level = logging.DEBUG if settings.DEBUG else logging.INFO,
  File "/opt/graphite/webapp/graphite/logger.py", line 78, in _config_logger
    handler = Rotater(log_file, when=when, backupCount=backupCount)
  File "/usr/lib/python2.7/logging/handlers.py", line 171, in __init__
    BaseRotatingHandler.__init__(self, filename, 'a', encoding, delay)
  File "/usr/lib/python2.7/logging/handlers.py", line 64, in __init__
    logging.FileHandler.__init__(self, filename, mode, encoding, delay)
  File "/usr/lib/python2.7/logging/__init__.py", line 920, in __init__
    StreamHandler.__init__(self, self._open())
  File "/usr/lib/python2.7/logging/__init__.py", line 950, in _open
    stream = open(self.baseFilename, self.mode)
IOError: [Errno 2] No such file or directory: '/opt/graphite/storage/log/webapp/info.log'
[2019-02-07 16:33:34 +0000] [179] [INFO] Worker exiting (pid: 179)
/opt/graphite/webapp/graphite/local_settings.py:334: UserWarning: SECRET_KEY is set to an unsafe default. This should be set in local_settings.py for better security
/opt/graphite/webapp/graphite/local_settings.py:334: UserWarning: SECRET_KEY is set to an unsafe default. This should be set in local_settings.py for better security
/opt/graphite/webapp/graphite/local_settings.py:334: UserWarning: SECRET_KEY is set to an unsafe default. This should be set in local_settings.py for better security
[2019-02-07 16:33:34 +0000] [176] [ERROR] Exception in worker process
Traceback (most recent call last):
  File "/usr/lib/python2.7/site-packages/gunicorn/arbiter.py", line 583, in spawn_worker
    worker.init_process()
  File "/usr/lib/python2.7/site-packages/gunicorn/workers/base.py", line 129, in init_process
    self.load_wsgi()
  File "/usr/lib/python2.7/site-packages/gunicorn/workers/base.py", line 138, in load_wsgi
    self.wsgi = self.app.wsgi()
  File "/usr/lib/python2.7/site-packages/gunicorn/app/base.py", line 67, in wsgi
    self.callable = self.load()
  File "/usr/lib/python2.7/site-packages/gunicorn/app/wsgiapp.py", line 52, in load
    return self.load_wsgiapp()
  File "/usr/lib/python2.7/site-packages/gunicorn/app/wsgiapp.py", line 41, in load_wsgiapp
    return util.import_app(self.app_uri)
  File "/usr/lib/python2.7/site-packages/gunicorn/util.py", line 350, in import_app
    __import__(module)
  File "/opt/graphite/webapp/graphite/wsgi.py", line 15, in <module>
    application = get_wsgi_application()
  File "/usr/lib/python2.7/site-packages/django/core/wsgi.py", line 13, in get_wsgi_application
    django.setup(set_prefix=False)
  File "/usr/lib/python2.7/site-packages/django/__init__.py", line 27, in setup
    apps.populate(settings.INSTALLED_APPS)
  File "/usr/lib/python2.7/site-packages/django/apps/registry.py", line 85, in populate
    app_config = AppConfig.create(entry)
  File "/usr/lib/python2.7/site-packages/django/apps/config.py", line 94, in create
    module = import_module(entry)
  File "/usr/lib/python2.7/importlib/__init__.py", line 37, in import_module
    __import__(name)
  File "/opt/graphite/webapp/graphite/functions/__init__.py", line 10, in <module>
    from graphite.logger import log
  File "/opt/graphite/webapp/graphite/logger.py", line 106, in <module>
    log = GraphiteLogger() # import-shared logger instance
  File "/opt/graphite/webapp/graphite/logger.py", line 39, in __init__
    level = logging.DEBUG if settings.DEBUG else logging.INFO,
  File "/opt/graphite/webapp/graphite/logger.py", line 78, in _config_logger
    handler = Rotater(log_file, when=when, backupCount=backupCount)
  File "/usr/lib/python2.7/logging/handlers.py", line 171, in __init__
    BaseRotatingHandler.__init__(self, filename, 'a', encoding, delay)
  File "/usr/lib/python2.7/logging/handlers.py", line 64, in __init__
    logging.FileHandler.__init__(self, filename, mode, encoding, delay)
  File "/usr/lib/python2.7/logging/__init__.py", line 920, in __init__
    StreamHandler.__init__(self, self._open())
  File "/usr/lib/python2.7/logging/__init__.py", line 950, in _open
    stream = open(self.baseFilename, self.mode)
IOError: [Errno 2] No such file or directory: '/opt/graphite/storage/log/webapp/info.log'
[2019-02-07 16:33:34 +0000] [176] [INFO] Worker exiting (pid: 176)
[2019-02-07 16:33:34 +0000] [177] [ERROR] Exception in worker process
Traceback (most recent call last):
  File "/usr/lib/python2.7/site-packages/gunicorn/arbiter.py", line 583, in spawn_worker
    worker.init_process()
  File "/usr/lib/python2.7/site-packages/gunicorn/workers/base.py", line 129, in init_process
    self.load_wsgi()
  File "/usr/lib/python2.7/site-packages/gunicorn/workers/base.py", line 138, in load_wsgi
    self.wsgi = self.app.wsgi()
  File "/usr/lib/python2.7/site-packages/gunicorn/app/base.py", line 67, in wsgi
    self.callable = self.load()
  File "/usr/lib/python2.7/site-packages/gunicorn/app/wsgiapp.py", line 52, in load
    return self.load_wsgiapp()
  File "/usr/lib/python2.7/site-packages/gunicorn/app/wsgiapp.py", line 41, in load_wsgiapp
    return util.import_app(self.app_uri)
  File "/usr/lib/python2.7/site-packages/gunicorn/util.py", line 350, in import_app
    __import__(module)
  File "/opt/graphite/webapp/graphite/wsgi.py", line 15, in <module>
    application = get_wsgi_application()
  File "/usr/lib/python2.7/site-packages/django/core/wsgi.py", line 13, in get_wsgi_application
    django.setup(set_prefix=False)
  File "/usr/lib/python2.7/site-packages/django/__init__.py", line 27, in setup
    apps.populate(settings.INSTALLED_APPS)
  File "/usr/lib/python2.7/site-packages/django/apps/registry.py", line 85, in populate
    app_config = AppConfig.create(entry)
  File "/usr/lib/python2.7/site-packages/django/apps/config.py", line 94, in create
    module = import_module(entry)
  File "/usr/lib/python2.7/importlib/__init__.py", line 37, in import_module
    __import__(name)
  File "/opt/graphite/webapp/graphite/functions/__init__.py", line 10, in <module>
    from graphite.logger import log
  File "/opt/graphite/webapp/graphite/logger.py", line 106, in <module>
    log = GraphiteLogger() # import-shared logger instance
  File "/opt/graphite/webapp/graphite/logger.py", line 39, in __init__
    level = logging.DEBUG if settings.DEBUG else logging.INFO,
  File "/opt/graphite/webapp/graphite/logger.py", line 78, in _config_logger
    handler = Rotater(log_file, when=when, backupCount=backupCount)
  File "/usr/lib/python2.7/logging/handlers.py", line 171, in __init__
    BaseRotatingHandler.__init__(self, filename, 'a', encoding, delay)
  File "/usr/lib/python2.7/logging/handlers.py", line 64, in __init__
    logging.FileHandler.__init__(self, filename, mode, encoding, delay)
  File "/usr/lib/python2.7/logging/__init__.py", line 920, in __init__
    StreamHandler.__init__(self, self._open())
  File "/usr/lib/python2.7/logging/__init__.py", line 950, in _open
    stream = open(self.baseFilename, self.mode)
IOError: [Errno 2] No such file or directory: '/opt/graphite/storage/log/webapp/info.log'
[2019-02-07 16:33:34 +0000] [177] [INFO] Worker exiting (pid: 177)
[2019-02-07 16:33:34 +0000] [178] [ERROR] Exception in worker process
Traceback (most recent call last):
  File "/usr/lib/python2.7/site-packages/gunicorn/arbiter.py", line 583, in spawn_worker
    worker.init_process()
  File "/usr/lib/python2.7/site-packages/gunicorn/workers/base.py", line 129, in init_process
    self.load_wsgi()
  File "/usr/lib/python2.7/site-packages/gunicorn/workers/base.py", line 138, in load_wsgi
    self.wsgi = self.app.wsgi()
  File "/usr/lib/python2.7/site-packages/gunicorn/app/base.py", line 67, in wsgi
    self.callable = self.load()
  File "/usr/lib/python2.7/site-packages/gunicorn/app/wsgiapp.py", line 52, in load
    return self.load_wsgiapp()
  File "/usr/lib/python2.7/site-packages/gunicorn/app/wsgiapp.py", line 41, in load_wsgiapp
    return util.import_app(self.app_uri)
  File "/usr/lib/python2.7/site-packages/gunicorn/util.py", line 350, in import_app
    __import__(module)
  File "/opt/graphite/webapp/graphite/wsgi.py", line 15, in <module>
    application = get_wsgi_application()
  File "/usr/lib/python2.7/site-packages/django/core/wsgi.py", line 13, in get_wsgi_application
    django.setup(set_prefix=False)
  File "/usr/lib/python2.7/site-packages/django/__init__.py", line 27, in setup
    apps.populate(settings.INSTALLED_APPS)
  File "/usr/lib/python2.7/site-packages/django/apps/registry.py", line 85, in populate
    app_config = AppConfig.create(entry)
  File "/usr/lib/python2.7/site-packages/django/apps/config.py", line 94, in create
    module = import_module(entry)
  File "/usr/lib/python2.7/importlib/__init__.py", line 37, in import_module
    __import__(name)
  File "/opt/graphite/webapp/graphite/functions/__init__.py", line 10, in <module>
    from graphite.logger import log
  File "/opt/graphite/webapp/graphite/logger.py", line 106, in <module>
    log = GraphiteLogger() # import-shared logger instance
  File "/opt/graphite/webapp/graphite/logger.py", line 39, in __init__
    level = logging.DEBUG if settings.DEBUG else logging.INFO,
  File "/opt/graphite/webapp/graphite/logger.py", line 78, in _config_logger
    handler = Rotater(log_file, when=when, backupCount=backupCount)
  File "/usr/lib/python2.7/logging/handlers.py", line 171, in __init__
    BaseRotatingHandler.__init__(self, filename, 'a', encoding, delay)
  File "/usr/lib/python2.7/logging/handlers.py", line 64, in __init__
    logging.FileHandler.__init__(self, filename, mode, encoding, delay)
  File "/usr/lib/python2.7/logging/__init__.py", line 920, in __init__
    StreamHandler.__init__(self, self._open())
  File "/usr/lib/python2.7/logging/__init__.py", line 950, in _open
    stream = open(self.baseFilename, self.mode)
IOError: [Errno 2] No such file or directory: '/opt/graphite/storage/log/webapp/info.log'
[2019-02-07 16:33:34 +0000] [178] [INFO] Worker exiting (pid: 178)
[2019-02-07 16:33:35 +0000] [170] [INFO] Shutting down: Master
[2019-02-07 16:33:35 +0000] [170] [INFO] Reason: Worker failed to boot.
[2019-02-07 16:33:36 +0000] [242] [INFO] Starting gunicorn 19.9.0
[2019-02-07 16:33:36 +0000] [242] [INFO] Listening at: http://127.0.0.1:8000 (242)
[2019-02-07 16:33:36 +0000] [242] [INFO] Using worker: sync
[2019-02-07 16:33:36 +0000] [245] [INFO] Booting worker with pid: 245
[2019-02-07 16:33:36 +0000] [246] [INFO] Booting worker with pid: 246
[2019-02-07 16:33:36 +0000] [247] [INFO] Booting worker with pid: 247
[2019-02-07 16:33:36 +0000] [248] [INFO] Booting worker with pid: 248
/opt/graphite/webapp/graphite/local_settings.py:334: UserWarning: SECRET_KEY is set to an unsafe default. This should be set in local_settings.py for better security
[2019-02-07 16:33:36 +0000] [245] [ERROR] Exception in worker process
Traceback (most recent call last):
  File "/usr/lib/python2.7/site-packages/gunicorn/arbiter.py", line 583, in spawn_worker
    worker.init_process()
  File "/usr/lib/python2.7/site-packages/gunicorn/workers/base.py", line 129, in init_process
    self.load_wsgi()
  File "/usr/lib/python2.7/site-packages/gunicorn/workers/base.py", line 138, in load_wsgi
    self.wsgi = self.app.wsgi()
  File "/usr/lib/python2.7/site-packages/gunicorn/app/base.py", line 67, in wsgi
    self.callable = self.load()
  File "/usr/lib/python2.7/site-packages/gunicorn/app/wsgiapp.py", line 52, in load
    return self.load_wsgiapp()
  File "/usr/lib/python2.7/site-packages/gunicorn/app/wsgiapp.py", line 41, in load_wsgiapp
    return util.import_app(self.app_uri)
  File "/usr/lib/python2.7/site-packages/gunicorn/util.py", line 350, in import_app
    __import__(module)
  File "/opt/graphite/webapp/graphite/wsgi.py", line 15, in <module>
    application = get_wsgi_application()
  File "/usr/lib/python2.7/site-packages/django/core/wsgi.py", line 13, in get_wsgi_application
    django.setup(set_prefix=False)
  File "/usr/lib/python2.7/site-packages/django/__init__.py", line 27, in setup
    apps.populate(settings.INSTALLED_APPS)
  File "/usr/lib/python2.7/site-packages/django/apps/registry.py", line 85, in populate
    app_config = AppConfig.create(entry)
  File "/usr/lib/python2.7/site-packages/django/apps/config.py", line 94, in create
    module = import_module(entry)
  File "/usr/lib/python2.7/importlib/__init__.py", line 37, in import_module
    __import__(name)
  File "/opt/graphite/webapp/graphite/functions/__init__.py", line 10, in <module>
    from graphite.logger import log
  File "/opt/graphite/webapp/graphite/logger.py", line 106, in <module>
    log = GraphiteLogger() # import-shared logger instance
  File "/opt/graphite/webapp/graphite/logger.py", line 39, in __init__
    level = logging.DEBUG if settings.DEBUG else logging.INFO,
  File "/opt/graphite/webapp/graphite/logger.py", line 78, in _config_logger
    handler = Rotater(log_file, when=when, backupCount=backupCount)
  File "/usr/lib/python2.7/logging/handlers.py", line 171, in __init__
    BaseRotatingHandler.__init__(self, filename, 'a', encoding, delay)
  File "/usr/lib/python2.7/logging/handlers.py", line 64, in __init__
    logging.FileHandler.__init__(self, filename, mode, encoding, delay)
  File "/usr/lib/python2.7/logging/__init__.py", line 920, in __init__
    StreamHandler.__init__(self, self._open())
  File "/usr/lib/python2.7/logging/__init__.py", line 950, in _open
    stream = open(self.baseFilename, self.mode)
IOError: [Errno 2] No such file or directory: '/opt/graphite/storage/log/webapp/info.log'
[2019-02-07 16:33:36 +0000] [245] [INFO] Worker exiting (pid: 245)
/opt/graphite/webapp/graphite/local_settings.py:334: UserWarning: SECRET_KEY is set to an unsafe default. This should be set in local_settings.py for better security
[2019-02-07 16:33:36 +0000] [246] [ERROR] Exception in worker process
Traceback (most recent call last):
  File "/usr/lib/python2.7/site-packages/gunicorn/arbiter.py", line 583, in spawn_worker
    worker.init_process()
  File "/usr/lib/python2.7/site-packages/gunicorn/workers/base.py", line 129, in init_process
    self.load_wsgi()
  File "/usr/lib/python2.7/site-packages/gunicorn/workers/base.py", line 138, in load_wsgi
    self.wsgi = self.app.wsgi()
  File "/usr/lib/python2.7/site-packages/gunicorn/app/base.py", line 67, in wsgi
    self.callable = self.load()
  File "/usr/lib/python2.7/site-packages/gunicorn/app/wsgiapp.py", line 52, in load
    return self.load_wsgiapp()
  File "/usr/lib/python2.7/site-packages/gunicorn/app/wsgiapp.py", line 41, in load_wsgiapp
    return util.import_app(self.app_uri)
  File "/usr/lib/python2.7/site-packages/gunicorn/util.py", line 350, in import_app
    __import__(module)
  File "/opt/graphite/webapp/graphite/wsgi.py", line 15, in <module>
    application = get_wsgi_application()
  File "/usr/lib/python2.7/site-packages/django/core/wsgi.py", line 13, in get_wsgi_application
    django.setup(set_prefix=False)
  File "/usr/lib/python2.7/site-packages/django/__init__.py", line 27, in setup
    apps.populate(settings.INSTALLED_APPS)
  File "/usr/lib/python2.7/site-packages/django/apps/registry.py", line 85, in populate
    app_config = AppConfig.create(entry)
  File "/usr/lib/python2.7/site-packages/django/apps/config.py", line 94, in create
    module = import_module(entry)
  File "/usr/lib/python2.7/importlib/__init__.py", line 37, in import_module
    __import__(name)
  File "/opt/graphite/webapp/graphite/functions/__init__.py", line 10, in <module>
    from graphite.logger import log
  File "/opt/graphite/webapp/graphite/logger.py", line 106, in <module>
    log = GraphiteLogger() # import-shared logger instance
  File "/opt/graphite/webapp/graphite/logger.py", line 39, in __init__
    level = logging.DEBUG if settings.DEBUG else logging.INFO,
  File "/opt/graphite/webapp/graphite/logger.py", line 78, in _config_logger
    handler = Rotater(log_file, when=when, backupCount=backupCount)
  File "/usr/lib/python2.7/logging/handlers.py", line 171, in __init__
    BaseRotatingHandler.__init__(self, filename, 'a', encoding, delay)
  File "/usr/lib/python2.7/logging/handlers.py", line 64, in __init__
    logging.FileHandler.__init__(self, filename, mode, encoding, delay)
  File "/usr/lib/python2.7/logging/__init__.py", line 920, in __init__
    StreamHandler.__init__(self, self._open())
  File "/usr/lib/python2.7/logging/__init__.py", line 950, in _open
    stream = open(self.baseFilename, self.mode)
IOError: [Errno 2] No such file or directory: '/opt/graphite/storage/log/webapp/info.log'
[2019-02-07 16:33:36 +0000] [246] [INFO] Worker exiting (pid: 246)
/opt/graphite/webapp/graphite/local_settings.py:334: UserWarning: SECRET_KEY is set to an unsafe default. This should be set in local_settings.py for better security
[2019-02-07 16:33:37 +0000] [247] [ERROR] Exception in worker process
Traceback (most recent call last):
  File "/usr/lib/python2.7/site-packages/gunicorn/arbiter.py", line 583, in spawn_worker
    worker.init_process()
  File "/usr/lib/python2.7/site-packages/gunicorn/workers/base.py", line 129, in init_process
    self.load_wsgi()
  File "/usr/lib/python2.7/site-packages/gunicorn/workers/base.py", line 138, in load_wsgi
    self.wsgi = self.app.wsgi()
  File "/usr/lib/python2.7/site-packages/gunicorn/app/base.py", line 67, in wsgi
    self.callable = self.load()
  File "/usr/lib/python2.7/site-packages/gunicorn/app/wsgiapp.py", line 52, in load
    return self.load_wsgiapp()
  File "/usr/lib/python2.7/site-packages/gunicorn/app/wsgiapp.py", line 41, in load_wsgiapp
    return util.import_app(self.app_uri)
  File "/usr/lib/python2.7/site-packages/gunicorn/util.py", line 350, in import_app
    __import__(module)
  File "/opt/graphite/webapp/graphite/wsgi.py", line 15, in <module>
    application = get_wsgi_application()
  File "/usr/lib/python2.7/site-packages/django/core/wsgi.py", line 13, in get_wsgi_application
    django.setup(set_prefix=False)
  File "/usr/lib/python2.7/site-packages/django/__init__.py", line 27, in setup
    apps.populate(settings.INSTALLED_APPS)
  File "/usr/lib/python2.7/site-packages/django/apps/registry.py", line 85, in populate
    app_config = AppConfig.create(entry)
  File "/usr/lib/python2.7/site-packages/django/apps/config.py", line 94, in create
    module = import_module(entry)
  File "/usr/lib/python2.7/importlib/__init__.py", line 37, in import_module
    __import__(name)
  File "/opt/graphite/webapp/graphite/functions/__init__.py", line 10, in <module>
    from graphite.logger import log
  File "/opt/graphite/webapp/graphite/logger.py", line 106, in <module>
    log = GraphiteLogger() # import-shared logger instance
  File "/opt/graphite/webapp/graphite/logger.py", line 39, in __init__
    level = logging.DEBUG if settings.DEBUG else logging.INFO,
  File "/opt/graphite/webapp/graphite/logger.py", line 78, in _config_logger
    handler = Rotater(log_file, when=when, backupCount=backupCount)
  File "/usr/lib/python2.7/logging/handlers.py", line 171, in __init__
    BaseRotatingHandler.__init__(self, filename, 'a', encoding, delay)
  File "/usr/lib/python2.7/logging/handlers.py", line 64, in __init__
    logging.FileHandler.__init__(self, filename, mode, encoding, delay)
  File "/usr/lib/python2.7/logging/__init__.py", line 920, in __init__
    StreamHandler.__init__(self, self._open())
  File "/usr/lib/python2.7/logging/__init__.py", line 950, in _open
    stream = open(self.baseFilename, self.mode)
IOError: [Errno 2] No such file or directory: '/opt/graphite/storage/log/webapp/info.log'
[2019-02-07 16:33:37 +0000] [247] [INFO] Worker exiting (pid: 247)
/opt/graphite/webapp/graphite/local_settings.py:334: UserWarning: SECRET_KEY is set to an unsafe default. This should be set in local_settings.py for better security
[2019-02-07 16:33:37 +0000] [248] [ERROR] Exception in worker process
Traceback (most recent call last):
  File "/usr/lib/python2.7/site-packages/gunicorn/arbiter.py", line 583, in spawn_worker
    worker.init_process()
  File "/usr/lib/python2.7/site-packages/gunicorn/workers/base.py", line 129, in init_process
    self.load_wsgi()
  File "/usr/lib/python2.7/site-packages/gunicorn/workers/base.py", line 138, in load_wsgi
    self.wsgi = self.app.wsgi()
  File "/usr/lib/python2.7/site-packages/gunicorn/app/base.py", line 67, in wsgi
    self.callable = self.load()
  File "/usr/lib/python2.7/site-packages/gunicorn/app/wsgiapp.py", line 52, in load
    return self.load_wsgiapp()
  File "/usr/lib/python2.7/site-packages/gunicorn/app/wsgiapp.py", line 41, in load_wsgiapp
    return util.import_app(self.app_uri)
  File "/usr/lib/python2.7/site-packages/gunicorn/util.py", line 350, in import_app
    __import__(module)
  File "/opt/graphite/webapp/graphite/wsgi.py", line 15, in <module>
    application = get_wsgi_application()
  File "/usr/lib/python2.7/site-packages/django/core/wsgi.py", line 13, in get_wsgi_application
    django.setup(set_prefix=False)
  File "/usr/lib/python2.7/site-packages/django/__init__.py", line 27, in setup
    apps.populate(settings.INSTALLED_APPS)
  File "/usr/lib/python2.7/site-packages/django/apps/registry.py", line 85, in populate
    app_config = AppConfig.create(entry)
  File "/usr/lib/python2.7/site-packages/django/apps/config.py", line 94, in create
    module = import_module(entry)
  File "/usr/lib/python2.7/importlib/__init__.py", line 37, in import_module
    __import__(name)
  File "/opt/graphite/webapp/graphite/functions/__init__.py", line 10, in <module>
    from graphite.logger import log
  File "/opt/graphite/webapp/graphite/logger.py", line 106, in <module>
    log = GraphiteLogger() # import-shared logger instance
  File "/opt/graphite/webapp/graphite/logger.py", line 39, in __init__
    level = logging.DEBUG if settings.DEBUG else logging.INFO,
  File "/opt/graphite/webapp/graphite/logger.py", line 78, in _config_logger
    handler = Rotater(log_file, when=when, backupCount=backupCount)
  File "/usr/lib/python2.7/logging/handlers.py", line 171, in __init__
    BaseRotatingHandler.__init__(self, filename, 'a', encoding, delay)
  File "/usr/lib/python2.7/logging/handlers.py", line 64, in __init__
    logging.FileHandler.__init__(self, filename, mode, encoding, delay)
  File "/usr/lib/python2.7/logging/__init__.py", line 920, in __init__
    StreamHandler.__init__(self, self._open())
  File "/usr/lib/python2.7/logging/__init__.py", line 950, in _open
    stream = open(self.baseFilename, self.mode)
IOError: [Errno 2] No such file or directory: '/opt/graphite/storage/log/webapp/info.log'
[2019-02-07 16:33:37 +0000] [248] [INFO] Worker exiting (pid: 248)
Traceback (most recent call last):
  File "/usr/bin/gunicorn", line 11, in <module>
    sys.exit(run())
  File "/usr/lib/python2.7/site-packages/gunicorn/app/wsgiapp.py", line 61, in run
    WSGIApplication("%(prog)s [OPTIONS] [APP_MODULE]").run()
  File "/usr/lib/python2.7/site-packages/gunicorn/app/base.py", line 223, in run
    super(Application, self).run()
  File "/usr/lib/python2.7/site-packages/gunicorn/app/base.py", line 72, in run
    Arbiter(self).run()
  File "/usr/lib/python2.7/site-packages/gunicorn/arbiter.py", line 232, in run
    self.halt(reason=inst.reason, exit_status=inst.exit_status)
  File "/usr/lib/python2.7/site-packages/gunicorn/arbiter.py", line 345, in halt
    self.stop()
  File "/usr/lib/python2.7/site-packages/gunicorn/arbiter.py", line 393, in stop
    time.sleep(0.1)
  File "/usr/lib/python2.7/site-packages/gunicorn/arbiter.py", line 245, in handle_chld
    self.reap_workers()
  File "/usr/lib/python2.7/site-packages/gunicorn/arbiter.py", line 525, in reap_workers
    raise HaltServer(reason, self.WORKER_BOOT_ERROR)
gunicorn.errors.HaltServer: <HaltServer 'Worker failed to boot.' 3>
[2019-02-07 16:33:38 +0000] [249] [INFO] Starting gunicorn 19.9.0
[2019-02-07 16:33:38 +0000] [249] [INFO] Listening at: http://127.0.0.1:8000 (249)
[2019-02-07 16:33:38 +0000] [249] [INFO] Using worker: sync
[2019-02-07 16:33:38 +0000] [251] [INFO] Booting worker with pid: 251
[2019-02-07 16:33:38 +0000] [252] [INFO] Booting worker with pid: 252
[2019-02-07 16:33:38 +0000] [253] [INFO] Booting worker with pid: 253
/opt/graphite/webapp/graphite/local_settings.py:334: UserWarning: SECRET_KEY is set to an unsafe default. This should be set in local_settings.py for better security
[2019-02-07 16:33:38 +0000] [251] [ERROR] Exception in worker process
Traceback (most recent call last):
  File "/usr/lib/python2.7/site-packages/gunicorn/arbiter.py", line 583, in spawn_worker
    worker.init_process()
  File "/usr/lib/python2.7/site-packages/gunicorn/workers/base.py", line 129, in init_process
    self.load_wsgi()
  File "/usr/lib/python2.7/site-packages/gunicorn/workers/base.py", line 138, in load_wsgi
    self.wsgi = self.app.wsgi()
  File "/usr/lib/python2.7/site-packages/gunicorn/app/base.py", line 67, in wsgi
    self.callable = self.load()
  File "/usr/lib/python2.7/site-packages/gunicorn/app/wsgiapp.py", line 52, in load
    return self.load_wsgiapp()
  File "/usr/lib/python2.7/site-packages/gunicorn/app/wsgiapp.py", line 41, in load_wsgiapp
    return util.import_app(self.app_uri)
  File "/usr/lib/python2.7/site-packages/gunicorn/util.py", line 350, in import_app
    __import__(module)
  File "/opt/graphite/webapp/graphite/wsgi.py", line 15, in <module>
    application = get_wsgi_application()
  File "/usr/lib/python2.7/site-packages/django/core/wsgi.py", line 13, in get_wsgi_application
    django.setup(set_prefix=False)
  File "/usr/lib/python2.7/site-packages/django/__init__.py", line 27, in setup
    apps.populate(settings.INSTALLED_APPS)
  File "/usr/lib/python2.7/site-packages/django/apps/registry.py", line 85, in populate
    app_config = AppConfig.create(entry)
  File "/usr/lib/python2.7/site-packages/django/apps/config.py", line 94, in create
    module = import_module(entry)
  File "/usr/lib/python2.7/importlib/__init__.py", line 37, in import_module
    __import__(name)
  File "/opt/graphite/webapp/graphite/functions/__init__.py", line 10, in <module>
    from graphite.logger import log
  File "/opt/graphite/webapp/graphite/logger.py", line 106, in <module>
    log = GraphiteLogger() # import-shared logger instance
  File "/opt/graphite/webapp/graphite/logger.py", line 39, in __init__
    level = logging.DEBUG if settings.DEBUG else logging.INFO,
  File "/opt/graphite/webapp/graphite/logger.py", line 78, in _config_logger
    handler = Rotater(log_file, when=when, backupCount=backupCount)
  File "/usr/lib/python2.7/logging/handlers.py", line 171, in __init__
    BaseRotatingHandler.__init__(self, filename, 'a', encoding, delay)
  File "/usr/lib/python2.7/logging/handlers.py", line 64, in __init__
    logging.FileHandler.__init__(self, filename, mode, encoding, delay)
  File "/usr/lib/python2.7/logging/__init__.py", line 920, in __init__
    StreamHandler.__init__(self, self._open())
  File "/usr/lib/python2.7/logging/__init__.py", line 950, in _open
    stream = open(self.baseFilename, self.mode)
IOError: [Errno 2] No such file or directory: '/opt/graphite/storage/log/webapp/info.log'
[2019-02-07 16:33:38 +0000] [251] [INFO] Worker exiting (pid: 251)
[2019-02-07 16:33:38 +0000] [254] [INFO] Booting worker with pid: 254
/opt/graphite/webapp/graphite/local_settings.py:334: UserWarning: SECRET_KEY is set to an unsafe default. This should be set in local_settings.py for better security
[2019-02-07 16:33:38 +0000] [252] [ERROR] Exception in worker process
Traceback (most recent call last):
  File "/usr/lib/python2.7/site-packages/gunicorn/arbiter.py", line 583, in spawn_worker
    worker.init_process()
  File "/usr/lib/python2.7/site-packages/gunicorn/workers/base.py", line 129, in init_process
    self.load_wsgi()
  File "/usr/lib/python2.7/site-packages/gunicorn/workers/base.py", line 138, in load_wsgi
    self.wsgi = self.app.wsgi()
  File "/usr/lib/python2.7/site-packages/gunicorn/app/base.py", line 67, in wsgi
    self.callable = self.load()
  File "/usr/lib/python2.7/site-packages/gunicorn/app/wsgiapp.py", line 52, in load
    return self.load_wsgiapp()
  File "/usr/lib/python2.7/site-packages/gunicorn/app/wsgiapp.py", line 41, in load_wsgiapp
    return util.import_app(self.app_uri)
  File "/usr/lib/python2.7/site-packages/gunicorn/util.py", line 350, in import_app
    __import__(module)
  File "/opt/graphite/webapp/graphite/wsgi.py", line 15, in <module>
    application = get_wsgi_application()
  File "/usr/lib/python2.7/site-packages/django/core/wsgi.py", line 13, in get_wsgi_application
    django.setup(set_prefix=False)
  File "/usr/lib/python2.7/site-packages/django/__init__.py", line 27, in setup
    apps.populate(settings.INSTALLED_APPS)
  File "/usr/lib/python2.7/site-packages/django/apps/registry.py", line 85, in populate
    app_config = AppConfig.create(entry)
  File "/usr/lib/python2.7/site-packages/django/apps/config.py", line 94, in create
    module = import_module(entry)
  File "/usr/lib/python2.7/importlib/__init__.py", line 37, in import_module
    __import__(name)
  File "/opt/graphite/webapp/graphite/functions/__init__.py", line 10, in <module>
    from graphite.logger import log
  File "/opt/graphite/webapp/graphite/logger.py", line 106, in <module>
    log = GraphiteLogger() # import-shared logger instance
  File "/opt/graphite/webapp/graphite/logger.py", line 39, in __init__
    level = logging.DEBUG if settings.DEBUG else logging.INFO,
  File "/opt/graphite/webapp/graphite/logger.py", line 78, in _config_logger
    handler = Rotater(log_file, when=when, backupCount=backupCount)
  File "/usr/lib/python2.7/logging/handlers.py", line 171, in __init__
    BaseRotatingHandler.__init__(self, filename, 'a', encoding, delay)
  File "/usr/lib/python2.7/logging/handlers.py", line 64, in __init__
    logging.FileHandler.__init__(self, filename, mode, encoding, delay)
  File "/usr/lib/python2.7/logging/__init__.py", line 920, in __init__
    StreamHandler.__init__(self, self._open())
  File "/usr/lib/python2.7/logging/__init__.py", line 950, in _open
    stream = open(self.baseFilename, self.mode)
IOError: [Errno 2] No such file or directory: '/opt/graphite/storage/log/webapp/info.log'
[2019-02-07 16:33:38 +0000] [252] [INFO] Worker exiting (pid: 252)
/opt/graphite/webapp/graphite/local_settings.py:334: UserWarning: SECRET_KEY is set to an unsafe default. This should be set in local_settings.py for better security
[2019-02-07 16:33:38 +0000] [253] [ERROR] Exception in worker process
Traceback (most recent call last):
  File "/usr/lib/python2.7/site-packages/gunicorn/arbiter.py", line 583, in spawn_worker
    worker.init_process()
  File "/usr/lib/python2.7/site-packages/gunicorn/workers/base.py", line 129, in init_process
    self.load_wsgi()
  File "/usr/lib/python2.7/site-packages/gunicorn/workers/base.py", line 138, in load_wsgi
    self.wsgi = self.app.wsgi()
  File "/usr/lib/python2.7/site-packages/gunicorn/app/base.py", line 67, in wsgi
    self.callable = self.load()
  File "/usr/lib/python2.7/site-packages/gunicorn/app/wsgiapp.py", line 52, in load
    return self.load_wsgiapp()
  File "/usr/lib/python2.7/site-packages/gunicorn/app/wsgiapp.py", line 41, in load_wsgiapp
    return util.import_app(self.app_uri)
  File "/usr/lib/python2.7/site-packages/gunicorn/util.py", line 350, in import_app
    __import__(module)
  File "/opt/graphite/webapp/graphite/wsgi.py", line 15, in <module>
    application = get_wsgi_application()
  File "/usr/lib/python2.7/site-packages/django/core/wsgi.py", line 13, in get_wsgi_application
    django.setup(set_prefix=False)
  File "/usr/lib/python2.7/site-packages/django/__init__.py", line 27, in setup
    apps.populate(settings.INSTALLED_APPS)
  File "/usr/lib/python2.7/site-packages/django/apps/registry.py", line 85, in populate
    app_config = AppConfig.create(entry)
  File "/usr/lib/python2.7/site-packages/django/apps/config.py", line 94, in create
    module = import_module(entry)
  File "/usr/lib/python2.7/importlib/__init__.py", line 37, in import_module
    __import__(name)
  File "/opt/graphite/webapp/graphite/functions/__init__.py", line 10, in <module>
    from graphite.logger import log
  File "/opt/graphite/webapp/graphite/logger.py", line 106, in <module>
    log = GraphiteLogger() # import-shared logger instance
  File "/opt/graphite/webapp/graphite/logger.py", line 39, in __init__
    level = logging.DEBUG if settings.DEBUG else logging.INFO,
  File "/opt/graphite/webapp/graphite/logger.py", line 78, in _config_logger
    handler = Rotater(log_file, when=when, backupCount=backupCount)
  File "/usr/lib/python2.7/logging/handlers.py", line 171, in __init__
    BaseRotatingHandler.__init__(self, filename, 'a', encoding, delay)
  File "/usr/lib/python2.7/logging/handlers.py", line 64, in __init__
    logging.FileHandler.__init__(self, filename, mode, encoding, delay)
  File "/usr/lib/python2.7/logging/__init__.py", line 920, in __init__
    StreamHandler.__init__(self, self._open())
  File "/usr/lib/python2.7/logging/__init__.py", line 950, in _open
    stream = open(self.baseFilename, self.mode)
IOError: [Errno 2] No such file or directory: '/opt/graphite/storage/log/webapp/info.log'
[2019-02-07 16:33:38 +0000] [253] [INFO] Worker exiting (pid: 253)
Traceback (most recent call last):
  File "/usr/bin/gunicorn", line 11, in <module>
    sys.exit(run())
  File "/usr/lib/python2.7/site-packages/gunicorn/app/wsgiapp.py", line 61, in run
    WSGIApplication("%(prog)s [OPTIONS] [APP_MODULE]").run()
  File "/usr/lib/python2.7/site-packages/gunicorn/app/base.py", line 223, in run
    super(Application, self).run()
  File "/usr/lib/python2.7/site-packages/gunicorn/app/base.py", line 72, in run
    Arbiter(self).run()
  File "/usr/lib/python2.7/site-packages/gunicorn/arbiter.py", line 232, in run
    self.halt(reason=inst.reason, exit_status=inst.exit_status)
  File "/usr/lib/python2.7/site-packages/gunicorn/arbiter.py", line 345, in halt
    self.stop()
  File "/usr/lib/python2.7/site-packages/gunicorn/arbiter.py", line 393, in stop
    time.sleep(0.1)
  File "/usr/lib/python2.7/site-packages/gunicorn/arbiter.py", line 245, in handle_chld
    self.reap_workers()
  File "/usr/lib/python2.7/site-packages/gunicorn/arbiter.py", line 525, in reap_workers
    raise HaltServer(reason, self.WORKER_BOOT_ERROR)
gunicorn.errors.HaltServer: <HaltServer 'Worker failed to boot.' 3>
[2019-02-07 16:33:41 +0000] [255] [INFO] Starting gunicorn 19.9.0
[2019-02-07 16:33:41 +0000] [255] [INFO] Listening at: http://127.0.0.1:8000 (255)
[2019-02-07 16:33:41 +0000] [255] [INFO] Using worker: sync
[2019-02-07 16:33:41 +0000] [257] [INFO] Booting worker with pid: 257
[2019-02-07 16:33:41 +0000] [258] [INFO] Booting worker with pid: 258
[2019-02-07 16:33:41 +0000] [259] [INFO] Booting worker with pid: 259
[2019-02-07 16:33:41 +0000] [260] [INFO] Booting worker with pid: 260
/opt/graphite/webapp/graphite/local_settings.py:334: UserWarning: SECRET_KEY is set to an unsafe default. This should be set in local_settings.py for better security
[2019-02-07 16:33:41 +0000] [257] [ERROR] Exception in worker process
Traceback (most recent call last):
  File "/usr/lib/python2.7/site-packages/gunicorn/arbiter.py", line 583, in spawn_worker
    worker.init_process()
  File "/usr/lib/python2.7/site-packages/gunicorn/workers/base.py", line 129, in init_process
    self.load_wsgi()
  File "/usr/lib/python2.7/site-packages/gunicorn/workers/base.py", line 138, in load_wsgi
    self.wsgi = self.app.wsgi()
  File "/usr/lib/python2.7/site-packages/gunicorn/app/base.py", line 67, in wsgi
    self.callable = self.load()
  File "/usr/lib/python2.7/site-packages/gunicorn/app/wsgiapp.py", line 52, in load
    return self.load_wsgiapp()
  File "/usr/lib/python2.7/site-packages/gunicorn/app/wsgiapp.py", line 41, in load_wsgiapp
    return util.import_app(self.app_uri)
  File "/usr/lib/python2.7/site-packages/gunicorn/util.py", line 350, in import_app
    __import__(module)
  File "/opt/graphite/webapp/graphite/wsgi.py", line 15, in <module>
    application = get_wsgi_application()
  File "/usr/lib/python2.7/site-packages/django/core/wsgi.py", line 13, in get_wsgi_application
    django.setup(set_prefix=False)
  File "/usr/lib/python2.7/site-packages/django/__init__.py", line 27, in setup
    apps.populate(settings.INSTALLED_APPS)
  File "/usr/lib/python2.7/site-packages/django/apps/registry.py", line 85, in populate
    app_config = AppConfig.create(entry)
  File "/usr/lib/python2.7/site-packages/django/apps/config.py", line 94, in create
    module = import_module(entry)
  File "/usr/lib/python2.7/importlib/__init__.py", line 37, in import_module
    __import__(name)
  File "/opt/graphite/webapp/graphite/functions/__init__.py", line 10, in <module>
    from graphite.logger import log
  File "/opt/graphite/webapp/graphite/logger.py", line 106, in <module>
    log = GraphiteLogger() # import-shared logger instance
  File "/opt/graphite/webapp/graphite/logger.py", line 39, in __init__
    level = logging.DEBUG if settings.DEBUG else logging.INFO,
  File "/opt/graphite/webapp/graphite/logger.py", line 78, in _config_logger
    handler = Rotater(log_file, when=when, backupCount=backupCount)
  File "/usr/lib/python2.7/logging/handlers.py", line 171, in __init__
    BaseRotatingHandler.__init__(self, filename, 'a', encoding, delay)
  File "/usr/lib/python2.7/logging/handlers.py", line 64, in __init__
    logging.FileHandler.__init__(self, filename, mode, encoding, delay)
  File "/usr/lib/python2.7/logging/__init__.py", line 920, in __init__
    StreamHandler.__init__(self, self._open())
  File "/usr/lib/python2.7/logging/__init__.py", line 950, in _open
    stream = open(self.baseFilename, self.mode)
IOError: [Errno 2] No such file or directory: '/opt/graphite/storage/log/webapp/info.log'
[2019-02-07 16:33:41 +0000] [257] [INFO] Worker exiting (pid: 257)
/opt/graphite/webapp/graphite/local_settings.py:334: UserWarning: SECRET_KEY is set to an unsafe default. This should be set in local_settings.py for better security
/opt/graphite/webapp/graphite/local_settings.py:334: UserWarning: SECRET_KEY is set to an unsafe default. This should be set in local_settings.py for better security
[2019-02-07 16:33:41 +0000] [258] [ERROR] Exception in worker process
Traceback (most recent call last):
  File "/usr/lib/python2.7/site-packages/gunicorn/arbiter.py", line 583, in spawn_worker
    worker.init_process()
  File "/usr/lib/python2.7/site-packages/gunicorn/workers/base.py", line 129, in init_process
    self.load_wsgi()
  File "/usr/lib/python2.7/site-packages/gunicorn/workers/base.py", line 138, in load_wsgi
    self.wsgi = self.app.wsgi()
  File "/usr/lib/python2.7/site-packages/gunicorn/app/base.py", line 67, in wsgi
    self.callable = self.load()
  File "/usr/lib/python2.7/site-packages/gunicorn/app/wsgiapp.py", line 52, in load
    return self.load_wsgiapp()
  File "/usr/lib/python2.7/site-packages/gunicorn/app/wsgiapp.py", line 41, in load_wsgiapp
    return util.import_app(self.app_uri)
  File "/usr/lib/python2.7/site-packages/gunicorn/util.py", line 350, in import_app
    __import__(module)
  File "/opt/graphite/webapp/graphite/wsgi.py", line 15, in <module>
    application = get_wsgi_application()
  File "/usr/lib/python2.7/site-packages/django/core/wsgi.py", line 13, in get_wsgi_application
    django.setup(set_prefix=False)
  File "/usr/lib/python2.7/site-packages/django/__init__.py", line 27, in setup
    apps.populate(settings.INSTALLED_APPS)
  File "/usr/lib/python2.7/site-packages/django/apps/registry.py", line 85, in populate
    app_config = AppConfig.create(entry)
  File "/usr/lib/python2.7/site-packages/django/apps/config.py", line 94, in create
    module = import_module(entry)
  File "/usr/lib/python2.7/importlib/__init__.py", line 37, in import_module
    __import__(name)
  File "/opt/graphite/webapp/graphite/functions/__init__.py", line 10, in <module>
    from graphite.logger import log
  File "/opt/graphite/webapp/graphite/logger.py", line 106, in <module>
    log = GraphiteLogger() # import-shared logger instance
  File "/opt/graphite/webapp/graphite/logger.py", line 39, in __init__
    level = logging.DEBUG if settings.DEBUG else logging.INFO,
  File "/opt/graphite/webapp/graphite/logger.py", line 78, in _config_logger
    handler = Rotater(log_file, when=when, backupCount=backupCount)
  File "/usr/lib/python2.7/logging/handlers.py", line 171, in __init__
    BaseRotatingHandler.__init__(self, filename, 'a', encoding, delay)
  File "/usr/lib/python2.7/logging/handlers.py", line 64, in __init__
    logging.FileHandler.__init__(self, filename, mode, encoding, delay)
  File "/usr/lib/python2.7/logging/__init__.py", line 920, in __init__
    StreamHandler.__init__(self, self._open())
  File "/usr/lib/python2.7/logging/__init__.py", line 950, in _open
    stream = open(self.baseFilename, self.mode)
IOError: [Errno 2] No such file or directory: '/opt/graphite/storage/log/webapp/info.log'
[2019-02-07 16:33:41 +0000] [258] [INFO] Worker exiting (pid: 258)
[2019-02-07 16:33:41 +0000] [259] [ERROR] Exception in worker process
Traceback (most recent call last):
  File "/usr/lib/python2.7/site-packages/gunicorn/arbiter.py", line 583, in spawn_worker
    worker.init_process()
  File "/usr/lib/python2.7/site-packages/gunicorn/workers/base.py", line 129, in init_process
    self.load_wsgi()
  File "/usr/lib/python2.7/site-packages/gunicorn/workers/base.py", line 138, in load_wsgi
    self.wsgi = self.app.wsgi()
  File "/usr/lib/python2.7/site-packages/gunicorn/app/base.py", line 67, in wsgi
    self.callable = self.load()
  File "/usr/lib/python2.7/site-packages/gunicorn/app/wsgiapp.py", line 52, in load
    return self.load_wsgiapp()
  File "/usr/lib/python2.7/site-packages/gunicorn/app/wsgiapp.py", line 41, in load_wsgiapp
    return util.import_app(self.app_uri)
  File "/usr/lib/python2.7/site-packages/gunicorn/util.py", line 350, in import_app
    __import__(module)
  File "/opt/graphite/webapp/graphite/wsgi.py", line 15, in <module>
    application = get_wsgi_application()
  File "/usr/lib/python2.7/site-packages/django/core/wsgi.py", line 13, in get_wsgi_application
    django.setup(set_prefix=False)
  File "/usr/lib/python2.7/site-packages/django/__init__.py", line 27, in setup
    apps.populate(settings.INSTALLED_APPS)
  File "/usr/lib/python2.7/site-packages/django/apps/registry.py", line 85, in populate
    app_config = AppConfig.create(entry)
  File "/usr/lib/python2.7/site-packages/django/apps/config.py", line 94, in create
    module = import_module(entry)
  File "/usr/lib/python2.7/importlib/__init__.py", line 37, in import_module
    __import__(name)
  File "/opt/graphite/webapp/graphite/functions/__init__.py", line 10, in <module>
    from graphite.logger import log
  File "/opt/graphite/webapp/graphite/logger.py", line 106, in <module>
    log = GraphiteLogger() # import-shared logger instance
  File "/opt/graphite/webapp/graphite/logger.py", line 39, in __init__
    level = logging.DEBUG if settings.DEBUG else logging.INFO,
  File "/opt/graphite/webapp/graphite/logger.py", line 78, in _config_logger
    handler = Rotater(log_file, when=when, backupCount=backupCount)
  File "/usr/lib/python2.7/logging/handlers.py", line 171, in __init__
    BaseRotatingHandler.__init__(self, filename, 'a', encoding, delay)
  File "/usr/lib/python2.7/logging/handlers.py", line 64, in __init__
    logging.FileHandler.__init__(self, filename, mode, encoding, delay)
  File "/usr/lib/python2.7/logging/__init__.py", line 920, in __init__
    StreamHandler.__init__(self, self._open())
  File "/usr/lib/python2.7/logging/__init__.py", line 950, in _open
    stream = open(self.baseFilename, self.mode)
IOError: [Errno 2] No such file or directory: '/opt/graphite/storage/log/webapp/info.log'
[2019-02-07 16:33:41 +0000] [259] [INFO] Worker exiting (pid: 259)
Traceback (most recent call last):
  File "/usr/bin/gunicorn", line 11, in <module>
    sys.exit(run())
  File "/usr/lib/python2.7/site-packages/gunicorn/app/wsgiapp.py", line 61, in run
    WSGIApplication("%(prog)s [OPTIONS] [APP_MODULE]").run()
  File "/usr/lib/python2.7/site-packages/gunicorn/app/base.py", line 223, in run
    super(Application, self).run()
  File "/usr/lib/python2.7/site-packages/gunicorn/app/base.py", line 72, in run
    Arbiter(self).run()
  File "/usr/lib/python2.7/site-packages/gunicorn/arbiter.py", line 232, in run
    self.halt(reason=inst.reason, exit_status=inst.exit_status)
  File "/usr/lib/python2.7/site-packages/gunicorn/arbiter.py", line 345, in halt
    self.stop()
  File "/usr/lib/python2.7/site-packages/gunicorn/arbiter.py", line 393, in stop
    time.sleep(0.1)
  File "/usr/lib/python2.7/site-packages/gunicorn/arbiter.py", line 245, in handle_chld
    self.reap_workers()
  File "/usr/lib/python2.7/site-packages/gunicorn/arbiter.py", line 525, in reap_workers
    raise HaltServer(reason, self.WORKER_BOOT_ERROR)
gunicorn.errors.HaltServer: <HaltServer 'Worker failed to boot.' 3>
[2019-02-07 16:33:44 +0000] [261] [INFO] Starting gunicorn 19.9.0
[2019-02-07 16:33:44 +0000] [261] [INFO] Listening at: http://127.0.0.1:8000 (261)
[2019-02-07 16:33:44 +0000] [261] [INFO] Using worker: sync
[2019-02-07 16:33:44 +0000] [263] [INFO] Booting worker with pid: 263
[2019-02-07 16:33:44 +0000] [264] [INFO] Booting worker with pid: 264
[2019-02-07 16:33:45 +0000] [265] [INFO] Booting worker with pid: 265
[2019-02-07 16:33:45 +0000] [266] [INFO] Booting worker with pid: 266
/opt/graphite/webapp/graphite/local_settings.py:334: UserWarning: SECRET_KEY is set to an unsafe default. This should be set in local_settings.py for better security
[2019-02-07 16:33:45 +0000] [263] [ERROR] Exception in worker process
Traceback (most recent call last):
  File "/usr/lib/python2.7/site-packages/gunicorn/arbiter.py", line 583, in spawn_worker
    worker.init_process()
  File "/usr/lib/python2.7/site-packages/gunicorn/workers/base.py", line 129, in init_process
    self.load_wsgi()
  File "/usr/lib/python2.7/site-packages/gunicorn/workers/base.py", line 138, in load_wsgi
    self.wsgi = self.app.wsgi()
  File "/usr/lib/python2.7/site-packages/gunicorn/app/base.py", line 67, in wsgi
    self.callable = self.load()
  File "/usr/lib/python2.7/site-packages/gunicorn/app/wsgiapp.py", line 52, in load
    return self.load_wsgiapp()
  File "/usr/lib/python2.7/site-packages/gunicorn/app/wsgiapp.py", line 41, in load_wsgiapp
    return util.import_app(self.app_uri)
  File "/usr/lib/python2.7/site-packages/gunicorn/util.py", line 350, in import_app
    __import__(module)
  File "/opt/graphite/webapp/graphite/wsgi.py", line 15, in <module>
    application = get_wsgi_application()
  File "/usr/lib/python2.7/site-packages/django/core/wsgi.py", line 13, in get_wsgi_application
    django.setup(set_prefix=False)
  File "/usr/lib/python2.7/site-packages/django/__init__.py", line 27, in setup
    apps.populate(settings.INSTALLED_APPS)
  File "/usr/lib/python2.7/site-packages/django/apps/registry.py", line 85, in populate
    app_config = AppConfig.create(entry)
  File "/usr/lib/python2.7/site-packages/django/apps/config.py", line 94, in create
    module = import_module(entry)
  File "/usr/lib/python2.7/importlib/__init__.py", line 37, in import_module
    __import__(name)
  File "/opt/graphite/webapp/graphite/functions/__init__.py", line 10, in <module>
    from graphite.logger import log
  File "/opt/graphite/webapp/graphite/logger.py", line 106, in <module>
    log = GraphiteLogger() # import-shared logger instance
  File "/opt/graphite/webapp/graphite/logger.py", line 39, in __init__
    level = logging.DEBUG if settings.DEBUG else logging.INFO,
  File "/opt/graphite/webapp/graphite/logger.py", line 78, in _config_logger
    handler = Rotater(log_file, when=when, backupCount=backupCount)
  File "/usr/lib/python2.7/logging/handlers.py", line 171, in __init__
    BaseRotatingHandler.__init__(self, filename, 'a', encoding, delay)
  File "/usr/lib/python2.7/logging/handlers.py", line 64, in __init__
    logging.FileHandler.__init__(self, filename, mode, encoding, delay)
  File "/usr/lib/python2.7/logging/__init__.py", line 920, in __init__
    StreamHandler.__init__(self, self._open())
  File "/usr/lib/python2.7/logging/__init__.py", line 950, in _open
    stream = open(self.baseFilename, self.mode)
IOError: [Errno 2] No such file or directory: '/opt/graphite/storage/log/webapp/info.log'
[2019-02-07 16:33:45 +0000] [263] [INFO] Worker exiting (pid: 263)
/opt/graphite/webapp/graphite/local_settings.py:334: UserWarning: SECRET_KEY is set to an unsafe default. This should be set in local_settings.py for better security
[2019-02-07 16:33:45 +0000] [264] [ERROR] Exception in worker process
Traceback (most recent call last):
  File "/usr/lib/python2.7/site-packages/gunicorn/arbiter.py", line 583, in spawn_worker
    worker.init_process()
  File "/usr/lib/python2.7/site-packages/gunicorn/workers/base.py", line 129, in init_process
    self.load_wsgi()
  File "/usr/lib/python2.7/site-packages/gunicorn/workers/base.py", line 138, in load_wsgi
    self.wsgi = self.app.wsgi()
  File "/usr/lib/python2.7/site-packages/gunicorn/app/base.py", line 67, in wsgi
    self.callable = self.load()
  File "/usr/lib/python2.7/site-packages/gunicorn/app/wsgiapp.py", line 52, in load
    return self.load_wsgiapp()
  File "/usr/lib/python2.7/site-packages/gunicorn/app/wsgiapp.py", line 41, in load_wsgiapp
    return util.import_app(self.app_uri)
  File "/usr/lib/python2.7/site-packages/gunicorn/util.py", line 350, in import_app
    __import__(module)
  File "/opt/graphite/webapp/graphite/wsgi.py", line 15, in <module>
    application = get_wsgi_application()
  File "/usr/lib/python2.7/site-packages/django/core/wsgi.py", line 13, in get_wsgi_application
    django.setup(set_prefix=False)
  File "/usr/lib/python2.7/site-packages/django/__init__.py", line 27, in setup
    apps.populate(settings.INSTALLED_APPS)
  File "/usr/lib/python2.7/site-packages/django/apps/registry.py", line 85, in populate
    app_config = AppConfig.create(entry)
  File "/usr/lib/python2.7/site-packages/django/apps/config.py", line 94, in create
    module = import_module(entry)
  File "/usr/lib/python2.7/importlib/__init__.py", line 37, in import_module
    __import__(name)
  File "/opt/graphite/webapp/graphite/functions/__init__.py", line 10, in <module>
    from graphite.logger import log
  File "/opt/graphite/webapp/graphite/logger.py", line 106, in <module>
    log = GraphiteLogger() # import-shared logger instance
  File "/opt/graphite/webapp/graphite/logger.py", line 39, in __init__
    level = logging.DEBUG if settings.DEBUG else logging.INFO,
  File "/opt/graphite/webapp/graphite/logger.py", line 78, in _config_logger
    handler = Rotater(log_file, when=when, backupCount=backupCount)
  File "/usr/lib/python2.7/logging/handlers.py", line 171, in __init__
    BaseRotatingHandler.__init__(self, filename, 'a', encoding, delay)
  File "/usr/lib/python2.7/logging/handlers.py", line 64, in __init__
    logging.FileHandler.__init__(self, filename, mode, encoding, delay)
  File "/usr/lib/python2.7/logging/__init__.py", line 920, in __init__
    StreamHandler.__init__(self, self._open())
  File "/usr/lib/python2.7/logging/__init__.py", line 950, in _open
    stream = open(self.baseFilename, self.mode)
IOError: [Errno 2] No such file or directory: '/opt/graphite/storage/log/webapp/info.log'
[2019-02-07 16:33:45 +0000] [264] [INFO] Worker exiting (pid: 264)
/opt/graphite/webapp/graphite/local_settings.py:334: UserWarning: SECRET_KEY is set to an unsafe default. This should be set in local_settings.py for better security
[2019-02-07 16:33:45 +0000] [266] [ERROR] Exception in worker process
Traceback (most recent call last):
  File "/usr/lib/python2.7/site-packages/gunicorn/arbiter.py", line 583, in spawn_worker
    worker.init_process()
  File "/usr/lib/python2.7/site-packages/gunicorn/workers/base.py", line 129, in init_process
    self.load_wsgi()
  File "/usr/lib/python2.7/site-packages/gunicorn/workers/base.py", line 138, in load_wsgi
    self.wsgi = self.app.wsgi()
  File "/usr/lib/python2.7/site-packages/gunicorn/app/base.py", line 67, in wsgi
    self.callable = self.load()
  File "/usr/lib/python2.7/site-packages/gunicorn/app/wsgiapp.py", line 52, in load
    return self.load_wsgiapp()
  File "/usr/lib/python2.7/site-packages/gunicorn/app/wsgiapp.py", line 41, in load_wsgiapp
    return util.import_app(self.app_uri)
  File "/usr/lib/python2.7/site-packages/gunicorn/util.py", line 350, in import_app
    __import__(module)
  File "/opt/graphite/webapp/graphite/wsgi.py", line 15, in <module>
    application = get_wsgi_application()
  File "/usr/lib/python2.7/site-packages/django/core/wsgi.py", line 13, in get_wsgi_application
    django.setup(set_prefix=False)
  File "/usr/lib/python2.7/site-packages/django/__init__.py", line 27, in setup
    apps.populate(settings.INSTALLED_APPS)
  File "/usr/lib/python2.7/site-packages/django/apps/registry.py", line 85, in populate
    app_config = AppConfig.create(entry)
  File "/usr/lib/python2.7/site-packages/django/apps/config.py", line 94, in create
    module = import_module(entry)
  File "/usr/lib/python2.7/importlib/__init__.py", line 37, in import_module
    __import__(name)
  File "/opt/graphite/webapp/graphite/functions/__init__.py", line 10, in <module>
    from graphite.logger import log
  File "/opt/graphite/webapp/graphite/logger.py", line 106, in <module>
    log = GraphiteLogger() # import-shared logger instance
  File "/opt/graphite/webapp/graphite/logger.py", line 39, in __init__
    level = logging.DEBUG if settings.DEBUG else logging.INFO,
  File "/opt/graphite/webapp/graphite/logger.py", line 78, in _config_logger
    handler = Rotater(log_file, when=when, backupCount=backupCount)
  File "/usr/lib/python2.7/logging/handlers.py", line 171, in __init__
    BaseRotatingHandler.__init__(self, filename, 'a', encoding, delay)
  File "/usr/lib/python2.7/logging/handlers.py", line 64, in __init__
    logging.FileHandler.__init__(self, filename, mode, encoding, delay)
  File "/usr/lib/python2.7/logging/__init__.py", line 920, in __init__
    StreamHandler.__init__(self, self._open())
  File "/usr/lib/python2.7/logging/__init__.py", line 950, in _open
    stream = open(self.baseFilename, self.mode)
IOError: [Errno 2] No such file or directory: '/opt/graphite/storage/log/webapp/info.log'
[2019-02-07 16:33:45 +0000] [266] [INFO] Worker exiting (pid: 266)
Traceback (most recent call last):
  File "/usr/bin/gunicorn", line 11, in <module>
    sys.exit(run())
  File "/usr/lib/python2.7/site-packages/gunicorn/app/wsgiapp.py", line 61, in run
    WSGIApplication("%(prog)s [OPTIONS] [APP_MODULE]").run()
  File "/usr/lib/python2.7/site-packages/gunicorn/app/base.py", line 223, in run
    super(Application, self).run()
  File "/usr/lib/python2.7/site-packages/gunicorn/app/base.py", line 72, in run
    Arbiter(self).run()
  File "/usr/lib/python2.7/site-packages/gunicorn/arbiter.py", line 232, in run
    self.halt(reason=inst.reason, exit_status=inst.exit_status)
  File "/usr/lib/python2.7/site-packages/gunicorn/arbiter.py", line 345, in halt
    self.stop()
  File "/usr/lib/python2.7/site-packages/gunicorn/arbiter.py", line 393, in stop
    time.sleep(0.1)
  File "/usr/lib/python2.7/site-packages/gunicorn/arbiter.py", line 245, in handle_chld
    self.reap_workers()
  File "/usr/lib/python2.7/site-packages/gunicorn/arbiter.py", line 525, in reap_workers
    raise HaltServer(reason, self.WORKER_BOOT_ERROR)
gunicorn.errors.HaltServer: <HaltServer 'Worker failed to boot.' 3>
/opt/graphite/webapp/graphite/local_settings.py:334: UserWarning: SECRET_KEY is set to an unsafe default. This should be set in local_settings.py for better security
[2019-02-07 16:33:45 +0000] [265] [ERROR] Exception in worker process
Traceback (most recent call last):
  File "/usr/lib/python2.7/site-packages/gunicorn/arbiter.py", line 583, in spawn_worker
    worker.init_process()
  File "/usr/lib/python2.7/site-packages/gunicorn/workers/base.py", line 129, in init_process
    self.load_wsgi()
  File "/usr/lib/python2.7/site-packages/gunicorn/workers/base.py", line 138, in load_wsgi
    self.wsgi = self.app.wsgi()
  File "/usr/lib/python2.7/site-packages/gunicorn/app/base.py", line 67, in wsgi
    self.callable = self.load()
  File "/usr/lib/python2.7/site-packages/gunicorn/app/wsgiapp.py", line 52, in load
    return self.load_wsgiapp()
  File "/usr/lib/python2.7/site-packages/gunicorn/app/wsgiapp.py", line 41, in load_wsgiapp
    return util.import_app(self.app_uri)
  File "/usr/lib/python2.7/site-packages/gunicorn/util.py", line 350, in import_app
    __import__(module)
  File "/opt/graphite/webapp/graphite/wsgi.py", line 15, in <module>
    application = get_wsgi_application()
  File "/usr/lib/python2.7/site-packages/django/core/wsgi.py", line 13, in get_wsgi_application
    django.setup(set_prefix=False)
  File "/usr/lib/python2.7/site-packages/django/__init__.py", line 27, in setup
    apps.populate(settings.INSTALLED_APPS)
  File "/usr/lib/python2.7/site-packages/django/apps/registry.py", line 85, in populate
    app_config = AppConfig.create(entry)
  File "/usr/lib/python2.7/site-packages/django/apps/config.py", line 94, in create
    module = import_module(entry)
  File "/usr/lib/python2.7/importlib/__init__.py", line 37, in import_module
    __import__(name)
  File "/opt/graphite/webapp/graphite/functions/__init__.py", line 10, in <module>
    from graphite.logger import log
  File "/opt/graphite/webapp/graphite/logger.py", line 106, in <module>
    log = GraphiteLogger() # import-shared logger instance
  File "/opt/graphite/webapp/graphite/logger.py", line 39, in __init__
    level = logging.DEBUG if settings.DEBUG else logging.INFO,
  File "/opt/graphite/webapp/graphite/logger.py", line 78, in _config_logger
    handler = Rotater(log_file, when=when, backupCount=backupCount)
  File "/usr/lib/python2.7/logging/handlers.py", line 171, in __init__
    BaseRotatingHandler.__init__(self, filename, 'a', encoding, delay)
  File "/usr/lib/python2.7/logging/handlers.py", line 64, in __init__
    logging.FileHandler.__init__(self, filename, mode, encoding, delay)
  File "/usr/lib/python2.7/logging/__init__.py", line 920, in __init__
    StreamHandler.__init__(self, self._open())
  File "/usr/lib/python2.7/logging/__init__.py", line 950, in _open
    stream = open(self.baseFilename, self.mode)
IOError: [Errno 2] No such file or directory: '/opt/graphite/storage/log/webapp/info.log'
[2019-02-07 16:33:45 +0000] [265] [INFO] Worker exiting (pid: 265)
